2017-11-01 19:17:55,150 INFO org.apache.hadoop.yarn.server.resourcemanager.ResourceManager: STARTUP_MSG: 
/************************************************************
STARTUP_MSG: Starting ResourceManager
STARTUP_MSG:   host = c220g1-031117.wisc.cloudlab.us/128.104.222.27
STARTUP_MSG:   args = []
STARTUP_MSG:   version = 3.0.0-beta1
STARTUP_MSG:   build = https://github.com/wentingt/hadoop-3.0.0-beta1-src.git -r 656db6e8eb0989655a7f1f1e0886b4e12efaacc2; compiled by 'wentingt' on 2017-11-02T00:56Z
STARTUP_MSG:   java = 1.8.0_131
************************************************************/
2017-11-01 19:17:55,164 INFO org.apache.hadoop.yarn.server.resourcemanager.ResourceManager: registered UNIX signal handlers for [TERM, HUP, INT]
2017-11-01 19:17:55,365 INFO org.apache.hadoop.conf.Configuration: found resource core-site.xml at file:/users/wentingt/hadoop-3.0.0-beta1-src/hadoop-dist/target/hadoop-3.0.0-beta1/etc/hadoop/core-site.xml
2017-11-01 19:17:55,396 WARN org.apache.hadoop.util.NativeCodeLoader: Unable to load native-hadoop library for your platform... using builtin-java classes where applicable
2017-11-01 19:17:55,420 INFO org.apache.hadoop.security.Groups: clearing userToGroupsMap cache
2017-11-01 19:17:55,466 INFO org.apache.hadoop.conf.Configuration: found resource yarn-site.xml at file:/users/wentingt/hadoop-3.0.0-beta1-src/hadoop-dist/target/hadoop-3.0.0-beta1/etc/hadoop/yarn-site.xml
2017-11-01 19:17:55,572 INFO org.apache.hadoop.yarn.event.AsyncDispatcher: Registering class org.apache.hadoop.yarn.server.resourcemanager.RMFatalEventType for class org.apache.hadoop.yarn.server.resourcemanager.ResourceManager$RMFatalEventDispatcher
2017-11-01 19:17:55,744 INFO org.apache.hadoop.yarn.server.resourcemanager.security.NMTokenSecretManagerInRM: NMTokenKeyRollingInterval: 86400000ms and NMTokenKeyActivationDelay: 900000ms
2017-11-01 19:17:55,750 INFO org.apache.hadoop.yarn.server.resourcemanager.security.RMContainerTokenSecretManager: ContainerTokenKeyRollingInterval: 86400000ms and ContainerTokenKeyActivationDelay: 900000ms
2017-11-01 19:17:55,762 INFO org.apache.hadoop.yarn.server.resourcemanager.security.AMRMTokenSecretManager: AMRMTokenKeyRollingInterval: 86400000ms and AMRMTokenKeyActivationDelay: 900000 ms
2017-11-01 19:17:55,805 INFO org.apache.hadoop.yarn.event.AsyncDispatcher: Registering class org.apache.hadoop.yarn.server.resourcemanager.recovery.RMStateStoreEventType for class org.apache.hadoop.yarn.server.resourcemanager.recovery.RMStateStore$ForwardingEventHandler
2017-11-01 19:17:55,809 INFO org.apache.hadoop.yarn.event.AsyncDispatcher: Registering class org.apache.hadoop.yarn.server.resourcemanager.NodesListManagerEventType for class org.apache.hadoop.yarn.server.resourcemanager.NodesListManager
2017-11-01 19:17:55,810 INFO org.apache.hadoop.yarn.server.resourcemanager.ResourceManager: Using Scheduler: org.apache.hadoop.yarn.server.resourcemanager.scheduler.capacity.CapacityScheduler
2017-11-01 19:17:55,838 INFO org.apache.hadoop.yarn.event.AsyncDispatcher: Registering class org.apache.hadoop.yarn.server.resourcemanager.scheduler.event.SchedulerEventType for class org.apache.hadoop.yarn.event.EventDispatcher
2017-11-01 19:17:55,839 INFO org.apache.hadoop.yarn.event.AsyncDispatcher: Registering class org.apache.hadoop.yarn.server.resourcemanager.rmapp.RMAppEventType for class org.apache.hadoop.yarn.server.resourcemanager.ResourceManager$ApplicationEventDispatcher
2017-11-01 19:17:55,840 INFO org.apache.hadoop.yarn.event.AsyncDispatcher: Registering class org.apache.hadoop.yarn.server.resourcemanager.rmapp.attempt.RMAppAttemptEventType for class org.apache.hadoop.yarn.server.resourcemanager.ResourceManager$ApplicationAttemptEventDispatcher
2017-11-01 19:17:55,841 INFO org.apache.hadoop.yarn.event.AsyncDispatcher: Registering class org.apache.hadoop.yarn.server.resourcemanager.rmnode.RMNodeEventType for class org.apache.hadoop.yarn.server.resourcemanager.ResourceManager$NodeEventDispatcher
2017-11-01 19:17:55,976 INFO org.apache.commons.beanutils.FluentPropertyBeanIntrospector: Error when creating PropertyDescriptor for public final void org.apache.commons.configuration2.AbstractConfiguration.setProperty(java.lang.String,java.lang.Object)! Ignoring this property.
2017-11-01 19:17:56,010 INFO org.apache.hadoop.metrics2.impl.MetricsConfig: loaded properties from hadoop-metrics2.properties
2017-11-01 19:17:56,066 INFO org.apache.hadoop.metrics2.impl.MetricsSystemImpl: Scheduled Metric snapshot period at 10 second(s).
2017-11-01 19:17:56,066 INFO org.apache.hadoop.metrics2.impl.MetricsSystemImpl: ResourceManager metrics system started
2017-11-01 19:17:56,090 INFO org.apache.hadoop.yarn.security.YarnAuthorizationProvider: org.apache.hadoop.yarn.security.ConfiguredYarnAuthorizer is instantiated.
2017-11-01 19:17:56,095 INFO org.apache.hadoop.yarn.event.AsyncDispatcher: Registering class org.apache.hadoop.yarn.server.resourcemanager.RMAppManagerEventType for class org.apache.hadoop.yarn.server.resourcemanager.RMAppManager
2017-11-01 19:17:56,108 INFO org.apache.hadoop.yarn.event.AsyncDispatcher: Registering class org.apache.hadoop.yarn.server.resourcemanager.amlauncher.AMLauncherEventType for class org.apache.hadoop.yarn.server.resourcemanager.amlauncher.ApplicationMasterLauncher
2017-11-01 19:17:56,111 INFO org.apache.hadoop.yarn.server.resourcemanager.RMNMInfo: Registered RMNMInfo MBean
2017-11-01 19:17:56,111 INFO org.apache.hadoop.yarn.server.resourcemanager.rmapp.monitor.RMAppLifetimeMonitor: Application lifelime monitor interval set to 3000 ms.
2017-11-01 19:17:56,122 INFO org.apache.hadoop.util.HostsFileReader: Refreshing hosts (include/exclude) list
2017-11-01 19:17:56,130 INFO org.apache.hadoop.conf.Configuration: found resource capacity-scheduler.xml at file:/users/wentingt/hadoop-3.0.0-beta1-src/hadoop-dist/target/hadoop-3.0.0-beta1/etc/hadoop/capacity-scheduler.xml
2017-11-01 19:17:56,201 INFO org.apache.hadoop.yarn.server.resourcemanager.scheduler.capacity.CapacitySchedulerConfiguration: max alloc mb per queue for root is undefined
2017-11-01 19:17:56,201 INFO org.apache.hadoop.yarn.server.resourcemanager.scheduler.capacity.CapacitySchedulerConfiguration: max alloc vcore per queue for root is undefined
2017-11-01 19:17:56,221 INFO org.apache.hadoop.yarn.server.resourcemanager.scheduler.capacity.ParentQueue: root, capacity=1.0, absoluteCapacity=1.0, maxCapacity=1.0, absoluteMaxCapacity=1.0, state=RUNNING, acls=ADMINISTER_QUEUE:*SUBMIT_APP:*, labels=*,
, reservationsContinueLooking=true, orderingPolicy=utilization, priority=0
2017-11-01 19:17:56,221 INFO org.apache.hadoop.yarn.server.resourcemanager.scheduler.capacity.ParentQueue: Initialized parent-queue root name=root, fullname=root
2017-11-01 19:17:56,240 INFO org.apache.hadoop.yarn.server.resourcemanager.scheduler.capacity.CapacitySchedulerConfiguration: max alloc mb per queue for root.default is undefined
2017-11-01 19:17:56,240 INFO org.apache.hadoop.yarn.server.resourcemanager.scheduler.capacity.CapacitySchedulerConfiguration: max alloc vcore per queue for root.default is undefined
2017-11-01 19:17:56,243 INFO org.apache.hadoop.yarn.server.resourcemanager.scheduler.capacity.LeafQueue: Initializing default
capacity = 1.0 [= (float) configuredCapacity / 100 ]
absoluteCapacity = 1.0 [= parentAbsoluteCapacity * capacity ]
maxCapacity = 1.0 [= configuredMaxCapacity ]
absoluteMaxCapacity = 1.0 [= 1.0 maximumCapacity undefined, (parentAbsoluteMaxCapacity * maximumCapacity) / 100 otherwise ]
userLimit = 100 [= configuredUserLimit ]
userLimitFactor = 1.0 [= configuredUserLimitFactor ]
maxApplications = 10000 [= configuredMaximumSystemApplicationsPerQueue or (int)(configuredMaximumSystemApplications * absoluteCapacity)]
maxApplicationsPerUser = 10000 [= (int)(maxApplications * (userLimit / 100.0f) * userLimitFactor) ]
usedCapacity = 0.0 [= usedResourcesMemory / (clusterResourceMemory * absoluteCapacity)]
absoluteUsedCapacity = 0.0 [= usedResourcesMemory / clusterResourceMemory]
maxAMResourcePerQueuePercent = 0.1 [= configuredMaximumAMResourcePercent ]
minimumAllocationFactor = 0.875 [= (float)(maximumAllocationMemory - minimumAllocationMemory) / maximumAllocationMemory ]
maximumAllocation = <memory:8192, vCores:4> [= configuredMaxAllocation ]
numContainers = 0 [= currentNumContainers ]
state = RUNNING [= configuredState ]
acls = ADMINISTER_QUEUE:*SUBMIT_APP:* [= configuredAcls ]
nodeLocalityDelay = 40
rackLocalityAdditionalDelay = -1
labels=*,
reservationsContinueLooking = true
preemptionDisabled = true
defaultAppPriorityPerQueue = 0
priority = 0
maxLifetime = -1 seconds
defaultLifetime = -1 seconds
2017-11-01 19:17:56,243 INFO org.apache.hadoop.yarn.server.resourcemanager.scheduler.capacity.CapacitySchedulerQueueManager: Initialized queue: default: capacity=1.0, absoluteCapacity=1.0, usedResources=<memory:0, vCores:0>, usedCapacity=0.0, absoluteUsedCapacity=0.0, numApps=0, numContainers=0
2017-11-01 19:17:56,243 INFO org.apache.hadoop.yarn.server.resourcemanager.scheduler.capacity.CapacitySchedulerQueueManager: Initialized queue: root: numChildQueue= 1, capacity=1.0, absoluteCapacity=1.0, usedResources=<memory:0, vCores:0>usedCapacity=0.0, numApps=0, numContainers=0
2017-11-01 19:17:56,245 INFO org.apache.hadoop.yarn.server.resourcemanager.scheduler.capacity.CapacitySchedulerQueueManager: Initialized root queue root: numChildQueue= 1, capacity=1.0, absoluteCapacity=1.0, usedResources=<memory:0, vCores:0>usedCapacity=0.0, numApps=0, numContainers=0
2017-11-01 19:17:56,245 INFO org.apache.hadoop.yarn.server.resourcemanager.scheduler.capacity.CapacityScheduler: Initialized queue mappings, override: false
2017-11-01 19:17:56,246 INFO org.apache.hadoop.yarn.server.resourcemanager.scheduler.capacity.CapacityScheduler: Initialized CapacityScheduler with calculator=class org.apache.hadoop.yarn.util.resource.DefaultResourceCalculator, minimumAllocation=<<memory:1024, vCores:1>>, maximumAllocation=<<memory:8192, vCores:4>>, asynchronousScheduling=false, asyncScheduleInterval=5ms
2017-11-01 19:17:56,250 INFO org.apache.hadoop.conf.Configuration: dynamic-resources.xml not found
2017-11-01 19:17:56,252 INFO org.apache.hadoop.yarn.server.resourcemanager.AMSProcessingChain: Initializing AMS Processing chain. Root Processor=[org.apache.hadoop.yarn.server.resourcemanager.DefaultAMSProcessor].
2017-11-01 19:17:56,259 INFO org.apache.hadoop.yarn.server.resourcemanager.ResourceManager: TimelineServicePublisher is not configured
2017-11-01 19:17:56,260 INFO org.apache.hadoop.yarn.server.resourcemanager.ResourceManager: Transitioning to active state
2017-11-01 19:17:56,289 INFO org.apache.hadoop.yarn.server.resourcemanager.recovery.RMStateStore: Updating AMRMToken
2017-11-01 19:17:56,289 INFO org.apache.hadoop.yarn.server.resourcemanager.security.RMContainerTokenSecretManager: Rolling master-key for container-tokens
2017-11-01 19:17:56,289 INFO org.apache.hadoop.yarn.server.resourcemanager.security.NMTokenSecretManagerInRM: Rolling master-key for nm-tokens
2017-11-01 19:17:56,289 INFO org.apache.hadoop.security.token.delegation.AbstractDelegationTokenSecretManager: Updating the current master key for generating delegation tokens
2017-11-01 19:17:56,290 INFO org.apache.hadoop.yarn.server.resourcemanager.security.RMDelegationTokenSecretManager: storing master key with keyID 1
2017-11-01 19:17:56,290 INFO org.apache.hadoop.yarn.server.resourcemanager.recovery.RMStateStore: Storing RMDTMasterKey.
2017-11-01 19:17:56,293 INFO org.apache.hadoop.security.token.delegation.AbstractDelegationTokenSecretManager: Starting expired delegation token remover thread, tokenRemoverScanInterval=60 min(s)
2017-11-01 19:17:56,293 INFO org.apache.hadoop.security.token.delegation.AbstractDelegationTokenSecretManager: Updating the current master key for generating delegation tokens
2017-11-01 19:17:56,293 INFO org.apache.hadoop.yarn.server.resourcemanager.security.RMDelegationTokenSecretManager: storing master key with keyID 2
2017-11-01 19:17:56,293 INFO org.apache.hadoop.yarn.server.resourcemanager.recovery.RMStateStore: Storing RMDTMasterKey.
2017-11-01 19:17:56,297 INFO org.apache.hadoop.yarn.event.AsyncDispatcher: Registering class org.apache.hadoop.yarn.nodelabels.event.NodeLabelsStoreEventType for class org.apache.hadoop.yarn.nodelabels.CommonNodeLabelsManager$ForwardingEventHandler
2017-11-01 19:17:56,347 INFO org.apache.hadoop.ipc.CallQueueManager: Using callQueue: class java.util.concurrent.LinkedBlockingQueue queueCapacity: 5000 scheduler: class org.apache.hadoop.ipc.DefaultRpcScheduler
2017-11-01 19:17:56,364 INFO org.apache.hadoop.ipc.Server: Starting Socket Reader #1 for port 8031
2017-11-01 19:17:56,536 INFO org.apache.hadoop.yarn.factories.impl.pb.RpcServerFactoryPBImpl: Adding protocol org.apache.hadoop.yarn.server.api.ResourceTrackerPB to the server
2017-11-01 19:17:56,537 INFO org.apache.hadoop.ipc.Server: IPC Server Responder: starting
2017-11-01 19:17:56,538 INFO org.apache.hadoop.ipc.Server: IPC Server listener on 8031: starting
2017-11-01 19:17:56,649 INFO org.apache.hadoop.util.JvmPauseMonitor: Starting JVM pause monitor
2017-11-01 19:17:56,663 INFO org.apache.hadoop.ipc.CallQueueManager: Using callQueue: class java.util.concurrent.LinkedBlockingQueue queueCapacity: 5000 scheduler: class org.apache.hadoop.ipc.DefaultRpcScheduler
2017-11-01 19:17:56,672 INFO org.apache.hadoop.ipc.Server: Starting Socket Reader #1 for port 8030
2017-11-01 19:17:56,683 INFO org.apache.hadoop.yarn.factories.impl.pb.RpcServerFactoryPBImpl: Adding protocol org.apache.hadoop.yarn.api.ApplicationMasterProtocolPB to the server
2017-11-01 19:17:56,683 INFO org.apache.hadoop.ipc.Server: IPC Server Responder: starting
2017-11-01 19:17:56,683 INFO org.apache.hadoop.ipc.Server: IPC Server listener on 8030: starting
2017-11-01 19:17:56,781 INFO org.apache.hadoop.ipc.CallQueueManager: Using callQueue: class java.util.concurrent.LinkedBlockingQueue queueCapacity: 5000 scheduler: class org.apache.hadoop.ipc.DefaultRpcScheduler
2017-11-01 19:17:56,781 INFO org.apache.hadoop.ipc.Server: Starting Socket Reader #1 for port 8032
2017-11-01 19:17:56,785 INFO org.apache.hadoop.yarn.factories.impl.pb.RpcServerFactoryPBImpl: Adding protocol org.apache.hadoop.yarn.api.ApplicationClientProtocolPB to the server
2017-11-01 19:17:56,785 INFO org.apache.hadoop.ipc.Server: IPC Server Responder: starting
2017-11-01 19:17:56,786 INFO org.apache.hadoop.ipc.Server: IPC Server listener on 8032: starting
2017-11-01 19:17:56,796 INFO org.apache.hadoop.yarn.server.resourcemanager.ResourceManager: Transitioned to active state
2017-11-01 19:17:56,849 INFO org.eclipse.jetty.util.log: Logging initialized @2282ms
2017-11-01 19:17:56,930 INFO org.apache.hadoop.security.authentication.server.AuthenticationFilter: Unable to initialize FileSignerSecretProvider, falling back to use random secrets.
2017-11-01 19:17:56,935 INFO org.apache.hadoop.http.HttpRequestLog: Http request log for http.requests.resourcemanager is not defined
2017-11-01 19:17:56,946 INFO org.apache.hadoop.http.HttpServer2: Added global filter 'safety' (class=org.apache.hadoop.http.HttpServer2$QuotingInputFilter)
2017-11-01 19:17:56,952 INFO org.apache.hadoop.http.HttpServer2: Added filter RMAuthenticationFilter (class=org.apache.hadoop.yarn.server.security.http.RMAuthenticationFilter) to context cluster
2017-11-01 19:17:56,952 INFO org.apache.hadoop.http.HttpServer2: Added filter RMAuthenticationFilter (class=org.apache.hadoop.yarn.server.security.http.RMAuthenticationFilter) to context static
2017-11-01 19:17:56,952 INFO org.apache.hadoop.http.HttpServer2: Added filter RMAuthenticationFilter (class=org.apache.hadoop.yarn.server.security.http.RMAuthenticationFilter) to context logs
2017-11-01 19:17:56,953 INFO org.apache.hadoop.http.HttpServer2: Added filter static_user_filter (class=org.apache.hadoop.http.lib.StaticUserWebFilter$StaticUserFilter) to context cluster
2017-11-01 19:17:56,953 INFO org.apache.hadoop.http.HttpServer2: Added filter static_user_filter (class=org.apache.hadoop.http.lib.StaticUserWebFilter$StaticUserFilter) to context static
2017-11-01 19:17:56,953 INFO org.apache.hadoop.http.HttpServer2: Added filter static_user_filter (class=org.apache.hadoop.http.lib.StaticUserWebFilter$StaticUserFilter) to context logs
2017-11-01 19:17:56,955 INFO org.apache.hadoop.http.HttpServer2: adding path spec: /cluster/*
2017-11-01 19:17:56,955 INFO org.apache.hadoop.http.HttpServer2: adding path spec: /ws/*
2017-11-01 19:17:57,313 INFO org.apache.hadoop.yarn.webapp.WebApps: Registered webapp guice modules
2017-11-01 19:17:57,314 INFO org.apache.hadoop.http.HttpServer2: Jetty bound to port 8088
2017-11-01 19:17:57,315 INFO org.eclipse.jetty.server.Server: jetty-9.3.19.v20170502
2017-11-01 19:17:57,361 INFO org.apache.hadoop.security.authentication.server.AuthenticationFilter: Unable to initialize FileSignerSecretProvider, falling back to use random secrets.
2017-11-01 19:17:57,374 INFO org.apache.hadoop.security.token.delegation.AbstractDelegationTokenSecretManager: Updating the current master key for generating delegation tokens
2017-11-01 19:17:57,374 INFO org.apache.hadoop.security.token.delegation.AbstractDelegationTokenSecretManager: Starting expired delegation token remover thread, tokenRemoverScanInterval=60 min(s)
2017-11-01 19:17:57,374 INFO org.apache.hadoop.security.token.delegation.AbstractDelegationTokenSecretManager: Updating the current master key for generating delegation tokens
2017-11-01 19:17:57,377 INFO org.eclipse.jetty.server.handler.ContextHandler: Started o.e.j.s.ServletContextHandler@4ba534b0{/logs,file:///users/wentingt/hadoop-3.0.0-beta1-src/hadoop-dist/target/hadoop-3.0.0-beta1/logs/,AVAILABLE}
2017-11-01 19:17:57,377 INFO org.eclipse.jetty.server.handler.ContextHandler: Started o.e.j.s.ServletContextHandler@4e517165{/static,jar:file:/users/wentingt/hadoop-3.0.0-beta1-src/hadoop-dist/target/hadoop-3.0.0-beta1/share/hadoop/yarn/hadoop-yarn-common-3.0.0-beta1.jar!/webapps/static,AVAILABLE}
2017-11-01 19:17:58,391 INFO org.eclipse.jetty.server.handler.ContextHandler: Started o.e.j.w.WebAppContext@77774571{/,file:///tmp/jetty-0.0.0.0-8088-cluster-_-any-7781280960730832774.dir/webapp/,AVAILABLE}{/cluster}
2017-11-01 19:17:58,395 INFO org.eclipse.jetty.server.AbstractConnector: Started ServerConnector@3bbf841e{HTTP/1.1,[http/1.1]}{0.0.0.0:8088}
2017-11-01 19:17:58,396 INFO org.eclipse.jetty.server.Server: Started @3830ms
2017-11-01 19:17:58,396 INFO org.apache.hadoop.yarn.webapp.WebApps: Web app cluster started at 8088
2017-11-01 19:17:58,442 INFO org.apache.hadoop.ipc.CallQueueManager: Using callQueue: class java.util.concurrent.LinkedBlockingQueue queueCapacity: 100 scheduler: class org.apache.hadoop.ipc.DefaultRpcScheduler
2017-11-01 19:17:58,444 INFO org.apache.hadoop.ipc.Server: Starting Socket Reader #1 for port 8033
2017-11-01 19:17:58,446 INFO org.apache.hadoop.yarn.factories.impl.pb.RpcServerFactoryPBImpl: Adding protocol org.apache.hadoop.yarn.server.api.ResourceManagerAdministrationProtocolPB to the server
2017-11-01 19:17:58,448 INFO org.apache.hadoop.ipc.Server: IPC Server Responder: starting
2017-11-01 19:17:58,448 INFO org.apache.hadoop.ipc.Server: IPC Server listener on 8033: starting
2017-11-01 19:18:01,263 INFO org.apache.hadoop.yarn.server.resourcemanager.ResourceTrackerService: NodeManager from node c220g1-031112.wisc.cloudlab.us(cmPort: 46102 httpPort: 8042) registered with capability: <memory:8192, vCores:8>, assigned nodeId c220g1-031112.wisc.cloudlab.us:46102
2017-11-01 19:18:01,263 INFO org.apache.hadoop.yarn.server.resourcemanager.ResourceTrackerService: NodeManager from node c220g1-031119.wisc.cloudlab.us(cmPort: 38777 httpPort: 8042) registered with capability: <memory:8192, vCores:8>, assigned nodeId c220g1-031119.wisc.cloudlab.us:38777
2017-11-01 19:18:01,263 INFO org.apache.hadoop.yarn.server.resourcemanager.ResourceTrackerService: NodeManager from node c220g1-031118.wisc.cloudlab.us(cmPort: 33290 httpPort: 8042) registered with capability: <memory:8192, vCores:8>, assigned nodeId c220g1-031118.wisc.cloudlab.us:33290
2017-11-01 19:18:01,275 INFO org.apache.hadoop.yarn.server.resourcemanager.rmnode.RMNodeImpl: c220g1-031118.wisc.cloudlab.us:33290 Node Transitioned from NEW to RUNNING
2017-11-01 19:18:01,275 INFO org.apache.hadoop.yarn.server.resourcemanager.rmnode.RMNodeImpl: c220g1-031112.wisc.cloudlab.us:46102 Node Transitioned from NEW to RUNNING
2017-11-01 19:18:01,275 INFO org.apache.hadoop.yarn.server.resourcemanager.rmnode.RMNodeImpl: c220g1-031119.wisc.cloudlab.us:38777 Node Transitioned from NEW to RUNNING
2017-11-01 19:18:01,289 INFO org.apache.hadoop.yarn.server.resourcemanager.scheduler.capacity.CapacityScheduler: Added node c220g1-031118.wisc.cloudlab.us:33290 clusterResource: <memory:8192, vCores:8>
2017-11-01 19:18:01,289 INFO org.apache.hadoop.yarn.server.resourcemanager.scheduler.capacity.CapacityScheduler: Added node c220g1-031112.wisc.cloudlab.us:46102 clusterResource: <memory:16384, vCores:16>
2017-11-01 19:18:01,290 INFO org.apache.hadoop.yarn.server.resourcemanager.scheduler.capacity.CapacityScheduler: Added node c220g1-031119.wisc.cloudlab.us:38777 clusterResource: <memory:24576, vCores:24>
2017-11-01 19:19:06,274 INFO org.apache.hadoop.yarn.server.resourcemanager.ClientRMService: Allocated new applicationId: 1
2017-11-01 19:19:07,348 INFO org.apache.hadoop.yarn.server.resourcemanager.scheduler.capacity.CapacityScheduler: Application 'application_1509585476261_0001' is submitted without priority hence considering default queue/cluster priority: 0
2017-11-01 19:19:07,348 INFO org.apache.hadoop.yarn.server.resourcemanager.scheduler.capacity.CapacityScheduler: Priority '0' is acceptable in queue : default for application: application_1509585476261_0001
2017-11-01 19:19:07,379 INFO org.apache.hadoop.yarn.server.resourcemanager.ClientRMService: Application with id 1 submitted by user wentingt
2017-11-01 19:19:07,379 INFO org.apache.hadoop.yarn.server.resourcemanager.rmapp.RMAppImpl: Storing application with id application_1509585476261_0001
2017-11-01 19:19:07,382 INFO org.apache.hadoop.yarn.server.resourcemanager.RMAuditLogger: USER=wentingt	IP=10.0.0.1	OPERATION=Submit Application Request	TARGET=ClientRMService	RESULT=SUCCESS	APPID=application_1509585476261_0001	CALLERCONTEXT=CLI
2017-11-01 19:19:07,396 INFO org.apache.hadoop.yarn.server.resourcemanager.recovery.RMStateStore: Storing info for app: application_1509585476261_0001
2017-11-01 19:19:07,396 INFO org.apache.hadoop.yarn.server.resourcemanager.rmapp.RMAppImpl: application_1509585476261_0001 State change from NEW to NEW_SAVING on event = START
2017-11-01 19:19:07,397 INFO org.apache.hadoop.yarn.server.resourcemanager.rmapp.RMAppImpl: application_1509585476261_0001 State change from NEW_SAVING to SUBMITTED on event = APP_NEW_SAVED
2017-11-01 19:19:07,400 INFO org.apache.hadoop.yarn.server.resourcemanager.scheduler.capacity.ParentQueue: Application added - appId: application_1509585476261_0001 user: wentingt leaf-queue of parent: root #applications: 1
2017-11-01 19:19:07,402 INFO org.apache.hadoop.yarn.server.resourcemanager.scheduler.capacity.CapacityScheduler: Accepted application application_1509585476261_0001 from user: wentingt, in queue: default
2017-11-01 19:19:07,454 INFO org.apache.hadoop.yarn.server.resourcemanager.rmapp.RMAppImpl: application_1509585476261_0001 State change from SUBMITTED to ACCEPTED on event = APP_ACCEPTED
2017-11-01 19:19:07,485 INFO org.apache.hadoop.yarn.server.resourcemanager.ApplicationMasterService: Registering app attempt : appattempt_1509585476261_0001_000001
2017-11-01 19:19:07,487 INFO org.apache.hadoop.yarn.server.resourcemanager.rmapp.attempt.RMAppAttemptImpl: appattempt_1509585476261_0001_000001 State change from NEW to SUBMITTED on event = START
2017-11-01 19:19:07,523 INFO org.apache.hadoop.yarn.server.resourcemanager.scheduler.capacity.LeafQueue: Application application_1509585476261_0001 from user: wentingt activated in queue: default
2017-11-01 19:19:07,523 INFO org.apache.hadoop.yarn.server.resourcemanager.scheduler.capacity.LeafQueue: Application added - appId: application_1509585476261_0001 user: wentingt, leaf-queue: default #user-pending-applications: 0 #user-active-applications: 1 #queue-pending-applications: 0 #queue-active-applications: 1
2017-11-01 19:19:07,523 INFO org.apache.hadoop.yarn.server.resourcemanager.scheduler.capacity.CapacityScheduler: Added Application Attempt appattempt_1509585476261_0001_000001 to scheduler from user wentingt in queue default
2017-11-01 19:19:07,531 INFO org.apache.hadoop.yarn.server.resourcemanager.rmapp.attempt.RMAppAttemptImpl: appattempt_1509585476261_0001_000001 State change from SUBMITTED to SCHEDULED on event = ATTEMPT_ADDED
2017-11-01 19:19:07,591 INFO org.apache.hadoop.yarn.server.resourcemanager.scheduler.capacity.allocator.AbstractContainerAllocator: assignedContainer application attempt=appattempt_1509585476261_0001_000001 container=null queue=org.apache.hadoop.yarn.server.resourcemanager.scheduler.capacity.allocator.RegularContainerAllocator@50ee77d8 clusterResource=<memory:24576, vCores:24> type=OFF_SWITCH requestedPartition=
2017-11-01 19:19:07,593 INFO org.apache.hadoop.yarn.server.resourcemanager.scheduler.capacity.ParentQueue: assignedContainer queue=root usedCapacity=0.0 absoluteUsedCapacity=0.0 used=<memory:0, vCores:0> cluster=<memory:24576, vCores:24>
2017-11-01 19:19:07,597 INFO org.apache.hadoop.yarn.server.resourcemanager.rmcontainer.RMContainerImpl: container_1509585476261_0001_01_000001 Container Transitioned from NEW to ALLOCATED
2017-11-01 19:19:07,598 INFO org.apache.hadoop.yarn.server.resourcemanager.scheduler.common.fica.FiCaSchedulerNode: Assigned container container_1509585476261_0001_01_000001 of capacity <memory:2048, vCores:1> on host c220g1-031119.wisc.cloudlab.us:38777, which has 1 containers, <memory:2048, vCores:1> used and <memory:6144, vCores:7> available after allocation
2017-11-01 19:19:07,598 INFO org.apache.hadoop.yarn.server.resourcemanager.RMAuditLogger: USER=wentingt	OPERATION=AM Allocated Container	TARGET=SchedulerApp	RESULT=SUCCESS	APPID=application_1509585476261_0001	CONTAINERID=container_1509585476261_0001_01_000001	RESOURCE=<memory:2048, vCores:1>
2017-11-01 19:19:07,629 INFO org.apache.hadoop.yarn.server.resourcemanager.security.NMTokenSecretManagerInRM: Sending NMToken for nodeId : c220g1-031119.wisc.cloudlab.us:38777 for container : container_1509585476261_0001_01_000001
2017-11-01 19:19:07,642 INFO org.apache.hadoop.yarn.server.resourcemanager.rmcontainer.RMContainerImpl: container_1509585476261_0001_01_000001 Container Transitioned from ALLOCATED to ACQUIRED
2017-11-01 19:19:07,643 INFO org.apache.hadoop.yarn.server.resourcemanager.security.NMTokenSecretManagerInRM: Clear node set for appattempt_1509585476261_0001_000001
2017-11-01 19:19:07,644 INFO org.apache.hadoop.yarn.server.resourcemanager.scheduler.capacity.ParentQueue: assignedContainer queue=root usedCapacity=0.083333336 absoluteUsedCapacity=0.083333336 used=<memory:2048, vCores:1> cluster=<memory:24576, vCores:24>
2017-11-01 19:19:07,644 INFO org.apache.hadoop.yarn.server.resourcemanager.rmapp.attempt.RMAppAttemptImpl: Storing attempt: AppId: application_1509585476261_0001 AttemptId: appattempt_1509585476261_0001_000001 MasterContainer: Container: [ContainerId: container_1509585476261_0001_01_000001, AllocationRequestId: 0, Version: 0, NodeId: c220g1-031119.wisc.cloudlab.us:38777, NodeHttpAddress: c220g1-031119.wisc.cloudlab.us:8042, Resource: <memory:2048, vCores:1>, Priority: 0, Token: Token { kind: ContainerToken, service: 128.104.222.29:38777 }, ExecutionType: GUARANTEED, ]
2017-11-01 19:19:07,644 INFO org.apache.hadoop.yarn.server.resourcemanager.scheduler.capacity.CapacityScheduler: Allocation proposal accepted
2017-11-01 19:19:07,667 INFO org.apache.hadoop.yarn.server.resourcemanager.rmapp.attempt.RMAppAttemptImpl: appattempt_1509585476261_0001_000001 State change from SCHEDULED to ALLOCATED_SAVING on event = CONTAINER_ALLOCATED
2017-11-01 19:19:07,674 INFO org.apache.hadoop.yarn.server.resourcemanager.rmapp.attempt.RMAppAttemptImpl: appattempt_1509585476261_0001_000001 State change from ALLOCATED_SAVING to ALLOCATED on event = ATTEMPT_NEW_SAVED
2017-11-01 19:19:07,677 INFO org.apache.hadoop.yarn.server.resourcemanager.amlauncher.AMLauncher: Launching masterappattempt_1509585476261_0001_000001
2017-11-01 19:19:07,749 INFO org.apache.hadoop.yarn.server.resourcemanager.amlauncher.AMLauncher: Setting up container Container: [ContainerId: container_1509585476261_0001_01_000001, AllocationRequestId: 0, Version: 0, NodeId: c220g1-031119.wisc.cloudlab.us:38777, NodeHttpAddress: c220g1-031119.wisc.cloudlab.us:8042, Resource: <memory:2048, vCores:1>, Priority: 0, Token: Token { kind: ContainerToken, service: 128.104.222.29:38777 }, ExecutionType: GUARANTEED, ] for AM appattempt_1509585476261_0001_000001
2017-11-01 19:19:07,751 INFO org.apache.hadoop.yarn.server.resourcemanager.security.AMRMTokenSecretManager: Create AMRMToken for ApplicationAttempt: appattempt_1509585476261_0001_000001
2017-11-01 19:19:07,755 INFO org.apache.hadoop.yarn.server.resourcemanager.security.AMRMTokenSecretManager: Creating password for appattempt_1509585476261_0001_000001
2017-11-01 19:19:08,292 INFO org.apache.hadoop.yarn.server.resourcemanager.amlauncher.AMLauncher: Done launching container Container: [ContainerId: container_1509585476261_0001_01_000001, AllocationRequestId: 0, Version: 0, NodeId: c220g1-031119.wisc.cloudlab.us:38777, NodeHttpAddress: c220g1-031119.wisc.cloudlab.us:8042, Resource: <memory:2048, vCores:1>, Priority: 0, Token: Token { kind: ContainerToken, service: 128.104.222.29:38777 }, ExecutionType: GUARANTEED, ] for AM appattempt_1509585476261_0001_000001
2017-11-01 19:19:08,292 INFO org.apache.hadoop.yarn.server.resourcemanager.rmapp.attempt.RMAppAttemptImpl: appattempt_1509585476261_0001_000001 State change from ALLOCATED to LAUNCHED on event = LAUNCHED
2017-11-01 19:19:08,583 INFO org.apache.hadoop.yarn.server.resourcemanager.rmcontainer.RMContainerImpl: container_1509585476261_0001_01_000001 Container Transitioned from ACQUIRED to RUNNING
2017-11-01 19:19:14,700 INFO SecurityLogger.org.apache.hadoop.ipc.Server: Auth successful for appattempt_1509585476261_0001_000001 (auth:SIMPLE)
2017-11-01 19:19:14,726 INFO org.apache.hadoop.yarn.server.resourcemanager.DefaultAMSProcessor: AM registration appattempt_1509585476261_0001_000001
2017-11-01 19:19:14,727 INFO org.apache.hadoop.yarn.server.resourcemanager.RMAuditLogger: USER=wentingt	IP=10.0.0.4	OPERATION=Register App Master	TARGET=ApplicationMasterService	RESULT=SUCCESS	APPID=application_1509585476261_0001	APPATTEMPTID=appattempt_1509585476261_0001_000001
2017-11-01 19:19:14,727 INFO org.apache.hadoop.yarn.server.resourcemanager.rmapp.attempt.RMAppAttemptImpl: appattempt_1509585476261_0001_000001 State change from LAUNCHED to RUNNING on event = REGISTERED
2017-11-01 19:19:14,727 INFO org.apache.hadoop.yarn.server.resourcemanager.rmapp.RMAppImpl: application_1509585476261_0001 State change from ACCEPTED to RUNNING on event = ATTEMPT_REGISTERED
2017-11-01 19:19:16,572 INFO org.apache.hadoop.yarn.server.resourcemanager.scheduler.capacity.allocator.AbstractContainerAllocator: assignedContainer application attempt=appattempt_1509585476261_0001_000001 container=null queue=org.apache.hadoop.yarn.server.resourcemanager.scheduler.capacity.allocator.RegularContainerAllocator@50ee77d8 clusterResource=<memory:24576, vCores:24> type=NODE_LOCAL requestedPartition=
2017-11-01 19:19:16,573 INFO org.apache.hadoop.yarn.server.resourcemanager.scheduler.capacity.ParentQueue: assignedContainer queue=root usedCapacity=0.083333336 absoluteUsedCapacity=0.083333336 used=<memory:2048, vCores:1> cluster=<memory:24576, vCores:24>
2017-11-01 19:19:16,574 INFO org.apache.hadoop.yarn.server.resourcemanager.rmcontainer.RMContainerImpl: container_1509585476261_0001_01_000002 Container Transitioned from NEW to ALLOCATED
2017-11-01 19:19:16,574 INFO org.apache.hadoop.yarn.server.resourcemanager.scheduler.common.fica.FiCaSchedulerNode: Assigned container container_1509585476261_0001_01_000002 of capacity <memory:1024, vCores:1> on host c220g1-031112.wisc.cloudlab.us:46102, which has 1 containers, <memory:1024, vCores:1> used and <memory:7168, vCores:7> available after allocation
2017-11-01 19:19:16,574 INFO org.apache.hadoop.yarn.server.resourcemanager.RMAuditLogger: USER=wentingt	OPERATION=AM Allocated Container	TARGET=SchedulerApp	RESULT=SUCCESS	APPID=application_1509585476261_0001	CONTAINERID=container_1509585476261_0001_01_000002	RESOURCE=<memory:1024, vCores:1>
2017-11-01 19:19:16,574 INFO org.apache.hadoop.yarn.server.resourcemanager.scheduler.capacity.ParentQueue: assignedContainer queue=root usedCapacity=0.125 absoluteUsedCapacity=0.125 used=<memory:3072, vCores:2> cluster=<memory:24576, vCores:24>
2017-11-01 19:19:16,575 INFO org.apache.hadoop.yarn.server.resourcemanager.scheduler.capacity.CapacityScheduler: Allocation proposal accepted
2017-11-01 19:19:16,575 INFO org.apache.hadoop.yarn.server.resourcemanager.scheduler.capacity.allocator.AbstractContainerAllocator: assignedContainer application attempt=appattempt_1509585476261_0001_000001 container=null queue=org.apache.hadoop.yarn.server.resourcemanager.scheduler.capacity.allocator.RegularContainerAllocator@50ee77d8 clusterResource=<memory:24576, vCores:24> type=NODE_LOCAL requestedPartition=
2017-11-01 19:19:16,575 INFO org.apache.hadoop.yarn.server.resourcemanager.scheduler.capacity.ParentQueue: assignedContainer queue=root usedCapacity=0.125 absoluteUsedCapacity=0.125 used=<memory:3072, vCores:2> cluster=<memory:24576, vCores:24>
2017-11-01 19:19:16,575 INFO org.apache.hadoop.yarn.server.resourcemanager.rmcontainer.RMContainerImpl: container_1509585476261_0001_01_000003 Container Transitioned from NEW to ALLOCATED
2017-11-01 19:19:16,576 INFO org.apache.hadoop.yarn.server.resourcemanager.scheduler.common.fica.FiCaSchedulerNode: Assigned container container_1509585476261_0001_01_000003 of capacity <memory:1024, vCores:1> on host c220g1-031112.wisc.cloudlab.us:46102, which has 2 containers, <memory:2048, vCores:2> used and <memory:6144, vCores:6> available after allocation
2017-11-01 19:19:16,576 INFO org.apache.hadoop.yarn.server.resourcemanager.RMAuditLogger: USER=wentingt	OPERATION=AM Allocated Container	TARGET=SchedulerApp	RESULT=SUCCESS	APPID=application_1509585476261_0001	CONTAINERID=container_1509585476261_0001_01_000003	RESOURCE=<memory:1024, vCores:1>
2017-11-01 19:19:16,576 INFO org.apache.hadoop.yarn.server.resourcemanager.scheduler.capacity.ParentQueue: assignedContainer queue=root usedCapacity=0.16666667 absoluteUsedCapacity=0.16666667 used=<memory:4096, vCores:3> cluster=<memory:24576, vCores:24>
2017-11-01 19:19:16,576 INFO org.apache.hadoop.yarn.server.resourcemanager.scheduler.capacity.CapacityScheduler: Allocation proposal accepted
2017-11-01 19:19:16,577 INFO org.apache.hadoop.yarn.server.resourcemanager.scheduler.capacity.allocator.AbstractContainerAllocator: assignedContainer application attempt=appattempt_1509585476261_0001_000001 container=null queue=org.apache.hadoop.yarn.server.resourcemanager.scheduler.capacity.allocator.RegularContainerAllocator@50ee77d8 clusterResource=<memory:24576, vCores:24> type=NODE_LOCAL requestedPartition=
2017-11-01 19:19:16,577 INFO org.apache.hadoop.yarn.server.resourcemanager.scheduler.capacity.ParentQueue: assignedContainer queue=root usedCapacity=0.16666667 absoluteUsedCapacity=0.16666667 used=<memory:4096, vCores:3> cluster=<memory:24576, vCores:24>
2017-11-01 19:19:16,578 INFO org.apache.hadoop.yarn.server.resourcemanager.rmcontainer.RMContainerImpl: container_1509585476261_0001_01_000004 Container Transitioned from NEW to ALLOCATED
2017-11-01 19:19:16,578 INFO org.apache.hadoop.yarn.server.resourcemanager.scheduler.common.fica.FiCaSchedulerNode: Assigned container container_1509585476261_0001_01_000004 of capacity <memory:1024, vCores:1> on host c220g1-031112.wisc.cloudlab.us:46102, which has 3 containers, <memory:3072, vCores:3> used and <memory:5120, vCores:5> available after allocation
2017-11-01 19:19:16,578 INFO org.apache.hadoop.yarn.server.resourcemanager.RMAuditLogger: USER=wentingt	OPERATION=AM Allocated Container	TARGET=SchedulerApp	RESULT=SUCCESS	APPID=application_1509585476261_0001	CONTAINERID=container_1509585476261_0001_01_000004	RESOURCE=<memory:1024, vCores:1>
2017-11-01 19:19:16,578 INFO org.apache.hadoop.yarn.server.resourcemanager.scheduler.capacity.ParentQueue: assignedContainer queue=root usedCapacity=0.20833333 absoluteUsedCapacity=0.20833333 used=<memory:5120, vCores:4> cluster=<memory:24576, vCores:24>
2017-11-01 19:19:16,578 INFO org.apache.hadoop.yarn.server.resourcemanager.scheduler.capacity.CapacityScheduler: Allocation proposal accepted
2017-11-01 19:19:16,833 INFO org.apache.hadoop.yarn.server.resourcemanager.security.NMTokenSecretManagerInRM: Sending NMToken for nodeId : c220g1-031112.wisc.cloudlab.us:46102 for container : container_1509585476261_0001_01_000002
2017-11-01 19:19:16,835 INFO org.apache.hadoop.yarn.server.resourcemanager.rmcontainer.RMContainerImpl: container_1509585476261_0001_01_000002 Container Transitioned from ALLOCATED to ACQUIRED
2017-11-01 19:19:16,837 INFO org.apache.hadoop.yarn.server.resourcemanager.rmcontainer.RMContainerImpl: container_1509585476261_0001_01_000003 Container Transitioned from ALLOCATED to ACQUIRED
2017-11-01 19:19:16,840 INFO org.apache.hadoop.yarn.server.resourcemanager.rmcontainer.RMContainerImpl: container_1509585476261_0001_01_000004 Container Transitioned from ALLOCATED to ACQUIRED
2017-11-01 19:19:17,866 INFO org.apache.hadoop.yarn.server.resourcemanager.scheduler.AppSchedulingInfo: checking for deactivate of application :application_1509585476261_0001
2017-11-01 19:19:18,601 INFO org.apache.hadoop.yarn.server.resourcemanager.rmcontainer.RMContainerImpl: container_1509585476261_0001_01_000002 Container Transitioned from ACQUIRED to RUNNING
2017-11-01 19:19:18,602 INFO org.apache.hadoop.yarn.server.resourcemanager.rmcontainer.RMContainerImpl: container_1509585476261_0001_01_000003 Container Transitioned from ACQUIRED to RUNNING
2017-11-01 19:19:18,602 INFO org.apache.hadoop.yarn.server.resourcemanager.rmcontainer.RMContainerImpl: container_1509585476261_0001_01_000004 Container Transitioned from ACQUIRED to RUNNING
2017-11-01 19:19:22,048 INFO org.apache.hadoop.yarn.server.resourcemanager.rmcontainer.RMContainerImpl: container_1509585476261_0001_01_000003 Container Transitioned from RUNNING to COMPLETED
2017-11-01 19:19:22,048 INFO org.apache.hadoop.yarn.server.resourcemanager.RMAuditLogger: USER=wentingt	OPERATION=AM Released Container	TARGET=SchedulerApp	RESULT=SUCCESS	APPID=application_1509585476261_0001	CONTAINERID=container_1509585476261_0001_01_000003	RESOURCE=<memory:1024, vCores:1>
2017-11-01 19:19:22,078 INFO org.apache.hadoop.yarn.server.resourcemanager.rmcontainer.RMContainerImpl: container_1509585476261_0001_01_000004 Container Transitioned from RUNNING to COMPLETED
2017-11-01 19:19:22,078 INFO org.apache.hadoop.yarn.server.resourcemanager.RMAuditLogger: USER=wentingt	OPERATION=AM Released Container	TARGET=SchedulerApp	RESULT=SUCCESS	APPID=application_1509585476261_0001	CONTAINERID=container_1509585476261_0001_01_000004	RESOURCE=<memory:1024, vCores:1>
2017-11-01 19:19:22,097 INFO org.apache.hadoop.yarn.server.resourcemanager.rmcontainer.RMContainerImpl: container_1509585476261_0001_01_000002 Container Transitioned from RUNNING to COMPLETED
2017-11-01 19:19:22,097 INFO org.apache.hadoop.yarn.server.resourcemanager.RMAuditLogger: USER=wentingt	OPERATION=AM Released Container	TARGET=SchedulerApp	RESULT=SUCCESS	APPID=application_1509585476261_0001	CONTAINERID=container_1509585476261_0001_01_000002	RESOURCE=<memory:1024, vCores:1>
2017-11-01 19:19:23,101 INFO org.apache.hadoop.yarn.server.resourcemanager.scheduler.capacity.allocator.AbstractContainerAllocator: assignedContainer application attempt=appattempt_1509585476261_0001_000001 container=null queue=org.apache.hadoop.yarn.server.resourcemanager.scheduler.capacity.allocator.RegularContainerAllocator@50ee77d8 clusterResource=<memory:24576, vCores:24> type=OFF_SWITCH requestedPartition=
2017-11-01 19:19:23,101 INFO org.apache.hadoop.yarn.server.resourcemanager.scheduler.capacity.ParentQueue: assignedContainer queue=root usedCapacity=0.083333336 absoluteUsedCapacity=0.083333336 used=<memory:2048, vCores:1> cluster=<memory:24576, vCores:24>
2017-11-01 19:19:23,102 INFO org.apache.hadoop.yarn.server.resourcemanager.rmcontainer.RMContainerImpl: container_1509585476261_0001_01_000005 Container Transitioned from NEW to ALLOCATED
2017-11-01 19:19:23,102 INFO org.apache.hadoop.yarn.server.resourcemanager.scheduler.common.fica.FiCaSchedulerNode: Assigned container container_1509585476261_0001_01_000005 of capacity <memory:1024, vCores:1> on host c220g1-031112.wisc.cloudlab.us:46102, which has 1 containers, <memory:1024, vCores:1> used and <memory:7168, vCores:7> available after allocation
2017-11-01 19:19:23,102 INFO org.apache.hadoop.yarn.server.resourcemanager.RMAuditLogger: USER=wentingt	OPERATION=AM Allocated Container	TARGET=SchedulerApp	RESULT=SUCCESS	APPID=application_1509585476261_0001	CONTAINERID=container_1509585476261_0001_01_000005	RESOURCE=<memory:1024, vCores:1>
2017-11-01 19:19:23,103 INFO org.apache.hadoop.yarn.server.resourcemanager.scheduler.capacity.ParentQueue: assignedContainer queue=root usedCapacity=0.125 absoluteUsedCapacity=0.125 used=<memory:3072, vCores:2> cluster=<memory:24576, vCores:24>
2017-11-01 19:19:23,103 INFO org.apache.hadoop.yarn.server.resourcemanager.scheduler.capacity.CapacityScheduler: Allocation proposal accepted
2017-11-01 19:19:23,919 INFO org.apache.hadoop.yarn.server.resourcemanager.rmcontainer.RMContainerImpl: container_1509585476261_0001_01_000005 Container Transitioned from ALLOCATED to ACQUIRED
2017-11-01 19:19:24,102 INFO org.apache.hadoop.yarn.server.resourcemanager.rmcontainer.RMContainerImpl: container_1509585476261_0001_01_000005 Container Transitioned from ACQUIRED to RUNNING
2017-11-01 19:19:24,925 INFO org.apache.hadoop.yarn.server.resourcemanager.scheduler.AppSchedulingInfo: checking for deactivate of application :application_1509585476261_0001
2017-11-01 19:19:28,107 INFO org.apache.hadoop.yarn.server.resourcemanager.rmcontainer.RMContainerImpl: container_1509585476261_0001_01_000005 Container Transitioned from RUNNING to COMPLETED
2017-11-01 19:19:28,107 INFO org.apache.hadoop.yarn.server.resourcemanager.RMAuditLogger: USER=wentingt	OPERATION=AM Released Container	TARGET=SchedulerApp	RESULT=SUCCESS	APPID=application_1509585476261_0001	CONTAINERID=container_1509585476261_0001_01_000005	RESOURCE=<memory:1024, vCores:1>
2017-11-01 19:19:28,121 INFO org.apache.hadoop.yarn.server.resourcemanager.rmapp.attempt.RMAppAttemptImpl: Updating application attempt appattempt_1509585476261_0001_000001 with final state: FINISHING, and exit status: -1000
2017-11-01 19:19:28,122 INFO org.apache.hadoop.yarn.server.resourcemanager.rmapp.attempt.RMAppAttemptImpl: appattempt_1509585476261_0001_000001 State change from RUNNING to FINAL_SAVING on event = UNREGISTERED
2017-11-01 19:19:28,122 INFO org.apache.hadoop.yarn.server.resourcemanager.rmapp.RMAppImpl: Updating application application_1509585476261_0001 with final state: FINISHING
2017-11-01 19:19:28,122 INFO org.apache.hadoop.yarn.server.resourcemanager.rmapp.RMAppImpl: application_1509585476261_0001 State change from RUNNING to FINAL_SAVING on event = ATTEMPT_UNREGISTERED
2017-11-01 19:19:28,123 INFO org.apache.hadoop.yarn.server.resourcemanager.recovery.RMStateStore: Updating info for app: application_1509585476261_0001
2017-11-01 19:19:28,123 INFO org.apache.hadoop.yarn.server.resourcemanager.rmapp.attempt.RMAppAttemptImpl: appattempt_1509585476261_0001_000001 State change from FINAL_SAVING to FINISHING on event = ATTEMPT_UPDATE_SAVED
2017-11-01 19:19:28,123 INFO org.apache.hadoop.yarn.server.resourcemanager.rmapp.RMAppImpl: application_1509585476261_0001 State change from FINAL_SAVING to FINISHING on event = APP_UPDATE_SAVED
2017-11-01 19:19:29,120 INFO org.apache.hadoop.yarn.server.resourcemanager.ApplicationMasterService: application_1509585476261_0001 unregistered successfully. 
2017-11-01 19:19:34,545 INFO org.apache.hadoop.yarn.server.resourcemanager.rmcontainer.RMContainerImpl: container_1509585476261_0001_01_000001 Container Transitioned from RUNNING to COMPLETED
2017-11-01 19:19:34,546 INFO org.apache.hadoop.yarn.server.resourcemanager.RMAuditLogger: USER=wentingt	OPERATION=AM Released Container	TARGET=SchedulerApp	RESULT=SUCCESS	APPID=application_1509585476261_0001	CONTAINERID=container_1509585476261_0001_01_000001	RESOURCE=<memory:2048, vCores:1>
2017-11-01 19:19:34,546 INFO org.apache.hadoop.yarn.server.resourcemanager.ApplicationMasterService: Unregistering app attempt : appattempt_1509585476261_0001_000001
2017-11-01 19:19:34,547 INFO org.apache.hadoop.yarn.server.resourcemanager.security.AMRMTokenSecretManager: Application finished, removing password for appattempt_1509585476261_0001_000001
2017-11-01 19:19:34,548 INFO org.apache.hadoop.yarn.server.resourcemanager.rmapp.attempt.RMAppAttemptImpl: appattempt_1509585476261_0001_000001 State change from FINISHING to FINISHED on event = CONTAINER_FINISHED
2017-11-01 19:19:34,552 INFO org.apache.hadoop.yarn.server.resourcemanager.rmapp.RMAppImpl: application_1509585476261_0001 State change from FINISHING to FINISHED on event = ATTEMPT_FINISHED
2017-11-01 19:19:34,552 INFO org.apache.hadoop.yarn.server.resourcemanager.scheduler.capacity.CapacityScheduler: Application Attempt appattempt_1509585476261_0001_000001 is done. finalState=FINISHED
2017-11-01 19:19:34,552 INFO org.apache.hadoop.yarn.server.resourcemanager.scheduler.AppSchedulingInfo: Application application_1509585476261_0001 requests cleared
2017-11-01 19:19:34,553 INFO org.apache.hadoop.yarn.server.resourcemanager.amlauncher.AMLauncher: Cleaning master appattempt_1509585476261_0001_000001
2017-11-01 19:19:34,553 INFO org.apache.hadoop.yarn.server.resourcemanager.scheduler.capacity.LeafQueue: Application removed - appId: application_1509585476261_0001 user: wentingt queue: default #user-pending-applications: 0 #user-active-applications: 0 #queue-pending-applications: 0 #queue-active-applications: 0
2017-11-01 19:19:34,554 INFO org.apache.hadoop.yarn.server.resourcemanager.RMAuditLogger: USER=wentingt	OPERATION=Application Finished - Succeeded	TARGET=RMAppManager	RESULT=SUCCESS	APPID=application_1509585476261_0001
2017-11-01 19:19:34,554 INFO org.apache.hadoop.yarn.server.resourcemanager.scheduler.capacity.ParentQueue: Application removed - appId: application_1509585476261_0001 user: wentingt leaf-queue of parent: root #applications: 0
2017-11-01 19:19:34,557 INFO org.apache.hadoop.yarn.server.resourcemanager.RMAppManager$ApplicationSummary: appId=application_1509585476261_0001,name=QuasiMonteCarlo,user=wentingt,queue=default,state=FINISHED,trackingUrl=http://c220g1-031117.wisc.cloudlab.us:8088/proxy/application_1509585476261_0001/,appMasterHost=c220g1-031119.wisc.cloudlab.us,submitTime=1509585547294,startTime=1509585547378,finishTime=1509585568122,finalStatus=SUCCEEDED,memorySeconds=77222,vcoreSeconds=46,preemptedMemorySeconds=0,preemptedVcoreSeconds=0,preemptedAMContainers=0,preemptedNonAMContainers=0,preemptedResources=<memory:0\, vCores:0>,applicationType=MAPREDUCE
2017-11-01 19:22:14,995 INFO org.apache.hadoop.yarn.server.resourcemanager.ClientRMService: Allocated new applicationId: 2
2017-11-01 19:22:15,859 INFO org.apache.hadoop.yarn.server.resourcemanager.scheduler.capacity.CapacityScheduler: Application 'application_1509585476261_0002' is submitted without priority hence considering default queue/cluster priority: 0
2017-11-01 19:22:15,859 INFO org.apache.hadoop.yarn.server.resourcemanager.scheduler.capacity.CapacityScheduler: Priority '0' is acceptable in queue : default for application: application_1509585476261_0002
2017-11-01 19:22:15,860 INFO org.apache.hadoop.yarn.server.resourcemanager.ClientRMService: Application with id 2 submitted by user wentingt
2017-11-01 19:22:15,860 INFO org.apache.hadoop.yarn.server.resourcemanager.RMAuditLogger: USER=wentingt	IP=10.0.0.1	OPERATION=Submit Application Request	TARGET=ClientRMService	RESULT=SUCCESS	APPID=application_1509585476261_0002	CALLERCONTEXT=CLI
2017-11-01 19:22:15,860 INFO org.apache.hadoop.yarn.server.resourcemanager.rmapp.RMAppImpl: Storing application with id application_1509585476261_0002
2017-11-01 19:22:15,861 INFO org.apache.hadoop.yarn.server.resourcemanager.recovery.RMStateStore: Storing info for app: application_1509585476261_0002
2017-11-01 19:22:15,861 INFO org.apache.hadoop.yarn.server.resourcemanager.rmapp.RMAppImpl: application_1509585476261_0002 State change from NEW to NEW_SAVING on event = START
2017-11-01 19:22:15,861 INFO org.apache.hadoop.yarn.server.resourcemanager.rmapp.RMAppImpl: application_1509585476261_0002 State change from NEW_SAVING to SUBMITTED on event = APP_NEW_SAVED
2017-11-01 19:22:15,861 INFO org.apache.hadoop.yarn.server.resourcemanager.scheduler.capacity.ParentQueue: Application added - appId: application_1509585476261_0002 user: wentingt leaf-queue of parent: root #applications: 1
2017-11-01 19:22:15,861 INFO org.apache.hadoop.yarn.server.resourcemanager.scheduler.capacity.CapacityScheduler: Accepted application application_1509585476261_0002 from user: wentingt, in queue: default
2017-11-01 19:22:15,864 INFO org.apache.hadoop.yarn.server.resourcemanager.rmapp.RMAppImpl: application_1509585476261_0002 State change from SUBMITTED to ACCEPTED on event = APP_ACCEPTED
2017-11-01 19:22:15,864 INFO org.apache.hadoop.yarn.server.resourcemanager.ApplicationMasterService: Registering app attempt : appattempt_1509585476261_0002_000001
2017-11-01 19:22:15,864 INFO org.apache.hadoop.yarn.server.resourcemanager.rmapp.attempt.RMAppAttemptImpl: appattempt_1509585476261_0002_000001 State change from NEW to SUBMITTED on event = START
2017-11-01 19:22:15,865 INFO org.apache.hadoop.yarn.server.resourcemanager.scheduler.capacity.LeafQueue: Application application_1509585476261_0002 from user: wentingt activated in queue: default
2017-11-01 19:22:15,865 INFO org.apache.hadoop.yarn.server.resourcemanager.scheduler.capacity.LeafQueue: Application added - appId: application_1509585476261_0002 user: wentingt, leaf-queue: default #user-pending-applications: 0 #user-active-applications: 1 #queue-pending-applications: 0 #queue-active-applications: 1
2017-11-01 19:22:15,865 INFO org.apache.hadoop.yarn.server.resourcemanager.scheduler.capacity.CapacityScheduler: Added Application Attempt appattempt_1509585476261_0002_000001 to scheduler from user wentingt in queue default
2017-11-01 19:22:15,866 INFO org.apache.hadoop.yarn.server.resourcemanager.rmapp.attempt.RMAppAttemptImpl: appattempt_1509585476261_0002_000001 State change from SUBMITTED to SCHEDULED on event = ATTEMPT_ADDED
2017-11-01 19:22:16,352 INFO org.apache.hadoop.yarn.server.resourcemanager.scheduler.capacity.allocator.AbstractContainerAllocator: assignedContainer application attempt=appattempt_1509585476261_0002_000001 container=null queue=org.apache.hadoop.yarn.server.resourcemanager.scheduler.capacity.allocator.RegularContainerAllocator@7b52fe4 clusterResource=<memory:24576, vCores:24> type=OFF_SWITCH requestedPartition=
2017-11-01 19:22:16,353 INFO org.apache.hadoop.yarn.server.resourcemanager.scheduler.capacity.ParentQueue: assignedContainer queue=root usedCapacity=0.0 absoluteUsedCapacity=0.0 used=<memory:0, vCores:0> cluster=<memory:24576, vCores:24>
2017-11-01 19:22:16,354 INFO org.apache.hadoop.yarn.server.resourcemanager.rmcontainer.RMContainerImpl: container_1509585476261_0002_01_000001 Container Transitioned from NEW to ALLOCATED
2017-11-01 19:22:16,354 INFO org.apache.hadoop.yarn.server.resourcemanager.scheduler.common.fica.FiCaSchedulerNode: Assigned container container_1509585476261_0002_01_000001 of capacity <memory:2048, vCores:1> on host c220g1-031112.wisc.cloudlab.us:46102, which has 1 containers, <memory:2048, vCores:1> used and <memory:6144, vCores:7> available after allocation
2017-11-01 19:22:16,354 INFO org.apache.hadoop.yarn.server.resourcemanager.RMAuditLogger: USER=wentingt	OPERATION=AM Allocated Container	TARGET=SchedulerApp	RESULT=SUCCESS	APPID=application_1509585476261_0002	CONTAINERID=container_1509585476261_0002_01_000001	RESOURCE=<memory:2048, vCores:1>
2017-11-01 19:22:16,355 INFO org.apache.hadoop.yarn.server.resourcemanager.security.NMTokenSecretManagerInRM: Sending NMToken for nodeId : c220g1-031112.wisc.cloudlab.us:46102 for container : container_1509585476261_0002_01_000001
2017-11-01 19:22:16,356 INFO org.apache.hadoop.yarn.server.resourcemanager.rmcontainer.RMContainerImpl: container_1509585476261_0002_01_000001 Container Transitioned from ALLOCATED to ACQUIRED
2017-11-01 19:22:16,357 INFO org.apache.hadoop.yarn.server.resourcemanager.security.NMTokenSecretManagerInRM: Clear node set for appattempt_1509585476261_0002_000001
2017-11-01 19:22:16,357 INFO org.apache.hadoop.yarn.server.resourcemanager.rmapp.attempt.RMAppAttemptImpl: Storing attempt: AppId: application_1509585476261_0002 AttemptId: appattempt_1509585476261_0002_000001 MasterContainer: Container: [ContainerId: container_1509585476261_0002_01_000001, AllocationRequestId: 0, Version: 0, NodeId: c220g1-031112.wisc.cloudlab.us:46102, NodeHttpAddress: c220g1-031112.wisc.cloudlab.us:8042, Resource: <memory:2048, vCores:1>, Priority: 0, Token: Token { kind: ContainerToken, service: 128.104.222.22:46102 }, ExecutionType: GUARANTEED, ]
2017-11-01 19:22:16,357 INFO org.apache.hadoop.yarn.server.resourcemanager.scheduler.capacity.ParentQueue: assignedContainer queue=root usedCapacity=0.083333336 absoluteUsedCapacity=0.083333336 used=<memory:2048, vCores:1> cluster=<memory:24576, vCores:24>
2017-11-01 19:22:16,357 INFO org.apache.hadoop.yarn.server.resourcemanager.scheduler.capacity.CapacityScheduler: Allocation proposal accepted
2017-11-01 19:22:16,357 INFO org.apache.hadoop.yarn.server.resourcemanager.rmapp.attempt.RMAppAttemptImpl: appattempt_1509585476261_0002_000001 State change from SCHEDULED to ALLOCATED_SAVING on event = CONTAINER_ALLOCATED
2017-11-01 19:22:16,358 INFO org.apache.hadoop.yarn.server.resourcemanager.rmapp.attempt.RMAppAttemptImpl: appattempt_1509585476261_0002_000001 State change from ALLOCATED_SAVING to ALLOCATED on event = ATTEMPT_NEW_SAVED
2017-11-01 19:22:16,359 INFO org.apache.hadoop.yarn.server.resourcemanager.amlauncher.AMLauncher: Launching masterappattempt_1509585476261_0002_000001
2017-11-01 19:22:16,363 INFO org.apache.hadoop.yarn.server.resourcemanager.amlauncher.AMLauncher: Setting up container Container: [ContainerId: container_1509585476261_0002_01_000001, AllocationRequestId: 0, Version: 0, NodeId: c220g1-031112.wisc.cloudlab.us:46102, NodeHttpAddress: c220g1-031112.wisc.cloudlab.us:8042, Resource: <memory:2048, vCores:1>, Priority: 0, Token: Token { kind: ContainerToken, service: 128.104.222.22:46102 }, ExecutionType: GUARANTEED, ] for AM appattempt_1509585476261_0002_000001
2017-11-01 19:22:16,363 INFO org.apache.hadoop.yarn.server.resourcemanager.security.AMRMTokenSecretManager: Create AMRMToken for ApplicationAttempt: appattempt_1509585476261_0002_000001
2017-11-01 19:22:16,363 INFO org.apache.hadoop.yarn.server.resourcemanager.security.AMRMTokenSecretManager: Creating password for appattempt_1509585476261_0002_000001
2017-11-01 19:22:16,383 INFO org.apache.hadoop.yarn.server.resourcemanager.amlauncher.AMLauncher: Done launching container Container: [ContainerId: container_1509585476261_0002_01_000001, AllocationRequestId: 0, Version: 0, NodeId: c220g1-031112.wisc.cloudlab.us:46102, NodeHttpAddress: c220g1-031112.wisc.cloudlab.us:8042, Resource: <memory:2048, vCores:1>, Priority: 0, Token: Token { kind: ContainerToken, service: 128.104.222.22:46102 }, ExecutionType: GUARANTEED, ] for AM appattempt_1509585476261_0002_000001
2017-11-01 19:22:16,383 INFO org.apache.hadoop.yarn.server.resourcemanager.rmapp.attempt.RMAppAttemptImpl: appattempt_1509585476261_0002_000001 State change from ALLOCATED to LAUNCHED on event = LAUNCHED
2017-11-01 19:22:17,354 INFO org.apache.hadoop.yarn.server.resourcemanager.rmcontainer.RMContainerImpl: container_1509585476261_0002_01_000001 Container Transitioned from ACQUIRED to RUNNING
2017-11-01 19:22:21,790 INFO SecurityLogger.org.apache.hadoop.ipc.Server: Auth successful for appattempt_1509585476261_0002_000001 (auth:SIMPLE)
2017-11-01 19:22:21,796 INFO org.apache.hadoop.yarn.server.resourcemanager.DefaultAMSProcessor: AM registration appattempt_1509585476261_0002_000001
2017-11-01 19:22:21,796 INFO org.apache.hadoop.yarn.server.resourcemanager.RMAuditLogger: USER=wentingt	IP=10.0.0.2	OPERATION=Register App Master	TARGET=ApplicationMasterService	RESULT=SUCCESS	APPID=application_1509585476261_0002	APPATTEMPTID=appattempt_1509585476261_0002_000001
2017-11-01 19:22:21,796 INFO org.apache.hadoop.yarn.server.resourcemanager.rmapp.attempt.RMAppAttemptImpl: appattempt_1509585476261_0002_000001 State change from LAUNCHED to RUNNING on event = REGISTERED
2017-11-01 19:22:21,797 INFO org.apache.hadoop.yarn.server.resourcemanager.rmapp.RMAppImpl: application_1509585476261_0002 State change from ACCEPTED to RUNNING on event = ATTEMPT_REGISTERED
2017-11-01 19:22:23,365 INFO org.apache.hadoop.yarn.server.resourcemanager.scheduler.capacity.allocator.AbstractContainerAllocator: assignedContainer application attempt=appattempt_1509585476261_0002_000001 container=null queue=org.apache.hadoop.yarn.server.resourcemanager.scheduler.capacity.allocator.RegularContainerAllocator@7b52fe4 clusterResource=<memory:24576, vCores:24> type=NODE_LOCAL requestedPartition=
2017-11-01 19:22:23,365 INFO org.apache.hadoop.yarn.server.resourcemanager.scheduler.capacity.ParentQueue: assignedContainer queue=root usedCapacity=0.083333336 absoluteUsedCapacity=0.083333336 used=<memory:2048, vCores:1> cluster=<memory:24576, vCores:24>
2017-11-01 19:22:23,365 INFO org.apache.hadoop.yarn.server.resourcemanager.rmcontainer.RMContainerImpl: container_1509585476261_0002_01_000002 Container Transitioned from NEW to ALLOCATED
2017-11-01 19:22:23,365 INFO org.apache.hadoop.yarn.server.resourcemanager.scheduler.common.fica.FiCaSchedulerNode: Assigned container container_1509585476261_0002_01_000002 of capacity <memory:1024, vCores:1> on host c220g1-031112.wisc.cloudlab.us:46102, which has 2 containers, <memory:3072, vCores:2> used and <memory:5120, vCores:6> available after allocation
2017-11-01 19:22:23,365 INFO org.apache.hadoop.yarn.server.resourcemanager.RMAuditLogger: USER=wentingt	OPERATION=AM Allocated Container	TARGET=SchedulerApp	RESULT=SUCCESS	APPID=application_1509585476261_0002	CONTAINERID=container_1509585476261_0002_01_000002	RESOURCE=<memory:1024, vCores:1>
2017-11-01 19:22:23,366 INFO org.apache.hadoop.yarn.server.resourcemanager.scheduler.capacity.ParentQueue: assignedContainer queue=root usedCapacity=0.125 absoluteUsedCapacity=0.125 used=<memory:3072, vCores:2> cluster=<memory:24576, vCores:24>
2017-11-01 19:22:23,366 INFO org.apache.hadoop.yarn.server.resourcemanager.scheduler.capacity.CapacityScheduler: Allocation proposal accepted
2017-11-01 19:22:23,366 INFO org.apache.hadoop.yarn.server.resourcemanager.scheduler.capacity.allocator.AbstractContainerAllocator: assignedContainer application attempt=appattempt_1509585476261_0002_000001 container=null queue=org.apache.hadoop.yarn.server.resourcemanager.scheduler.capacity.allocator.RegularContainerAllocator@7b52fe4 clusterResource=<memory:24576, vCores:24> type=NODE_LOCAL requestedPartition=
2017-11-01 19:22:23,366 INFO org.apache.hadoop.yarn.server.resourcemanager.scheduler.capacity.ParentQueue: assignedContainer queue=root usedCapacity=0.125 absoluteUsedCapacity=0.125 used=<memory:3072, vCores:2> cluster=<memory:24576, vCores:24>
2017-11-01 19:22:23,367 INFO org.apache.hadoop.yarn.server.resourcemanager.rmcontainer.RMContainerImpl: container_1509585476261_0002_01_000003 Container Transitioned from NEW to ALLOCATED
2017-11-01 19:22:23,367 INFO org.apache.hadoop.yarn.server.resourcemanager.scheduler.common.fica.FiCaSchedulerNode: Assigned container container_1509585476261_0002_01_000003 of capacity <memory:1024, vCores:1> on host c220g1-031112.wisc.cloudlab.us:46102, which has 3 containers, <memory:4096, vCores:3> used and <memory:4096, vCores:5> available after allocation
2017-11-01 19:22:23,367 INFO org.apache.hadoop.yarn.server.resourcemanager.RMAuditLogger: USER=wentingt	OPERATION=AM Allocated Container	TARGET=SchedulerApp	RESULT=SUCCESS	APPID=application_1509585476261_0002	CONTAINERID=container_1509585476261_0002_01_000003	RESOURCE=<memory:1024, vCores:1>
2017-11-01 19:22:23,367 INFO org.apache.hadoop.yarn.server.resourcemanager.scheduler.capacity.ParentQueue: assignedContainer queue=root usedCapacity=0.16666667 absoluteUsedCapacity=0.16666667 used=<memory:4096, vCores:3> cluster=<memory:24576, vCores:24>
2017-11-01 19:22:23,367 INFO org.apache.hadoop.yarn.server.resourcemanager.scheduler.capacity.CapacityScheduler: Allocation proposal accepted
2017-11-01 19:22:23,367 INFO org.apache.hadoop.yarn.server.resourcemanager.scheduler.capacity.allocator.AbstractContainerAllocator: assignedContainer application attempt=appattempt_1509585476261_0002_000001 container=null queue=org.apache.hadoop.yarn.server.resourcemanager.scheduler.capacity.allocator.RegularContainerAllocator@7b52fe4 clusterResource=<memory:24576, vCores:24> type=NODE_LOCAL requestedPartition=
2017-11-01 19:22:23,368 INFO org.apache.hadoop.yarn.server.resourcemanager.scheduler.capacity.ParentQueue: assignedContainer queue=root usedCapacity=0.16666667 absoluteUsedCapacity=0.16666667 used=<memory:4096, vCores:3> cluster=<memory:24576, vCores:24>
2017-11-01 19:22:23,369 INFO org.apache.hadoop.yarn.server.resourcemanager.rmcontainer.RMContainerImpl: container_1509585476261_0002_01_000004 Container Transitioned from NEW to ALLOCATED
2017-11-01 19:22:23,369 INFO org.apache.hadoop.yarn.server.resourcemanager.scheduler.common.fica.FiCaSchedulerNode: Assigned container container_1509585476261_0002_01_000004 of capacity <memory:1024, vCores:1> on host c220g1-031112.wisc.cloudlab.us:46102, which has 4 containers, <memory:5120, vCores:4> used and <memory:3072, vCores:4> available after allocation
2017-11-01 19:22:23,369 INFO org.apache.hadoop.yarn.server.resourcemanager.RMAuditLogger: USER=wentingt	OPERATION=AM Allocated Container	TARGET=SchedulerApp	RESULT=SUCCESS	APPID=application_1509585476261_0002	CONTAINERID=container_1509585476261_0002_01_000004	RESOURCE=<memory:1024, vCores:1>
2017-11-01 19:22:23,370 INFO org.apache.hadoop.yarn.server.resourcemanager.scheduler.capacity.ParentQueue: assignedContainer queue=root usedCapacity=0.20833333 absoluteUsedCapacity=0.20833333 used=<memory:5120, vCores:4> cluster=<memory:24576, vCores:24>
2017-11-01 19:22:23,370 INFO org.apache.hadoop.yarn.server.resourcemanager.scheduler.capacity.CapacityScheduler: Allocation proposal accepted
2017-11-01 19:22:23,889 INFO org.apache.hadoop.yarn.server.resourcemanager.security.NMTokenSecretManagerInRM: Sending NMToken for nodeId : c220g1-031112.wisc.cloudlab.us:46102 for container : container_1509585476261_0002_01_000002
2017-11-01 19:22:23,890 INFO org.apache.hadoop.yarn.server.resourcemanager.rmcontainer.RMContainerImpl: container_1509585476261_0002_01_000002 Container Transitioned from ALLOCATED to ACQUIRED
2017-11-01 19:22:23,903 INFO org.apache.hadoop.yarn.server.resourcemanager.rmcontainer.RMContainerImpl: container_1509585476261_0002_01_000003 Container Transitioned from ALLOCATED to ACQUIRED
2017-11-01 19:22:23,905 INFO org.apache.hadoop.yarn.server.resourcemanager.rmcontainer.RMContainerImpl: container_1509585476261_0002_01_000004 Container Transitioned from ALLOCATED to ACQUIRED
2017-11-01 19:22:24,366 INFO org.apache.hadoop.yarn.server.resourcemanager.rmcontainer.RMContainerImpl: container_1509585476261_0002_01_000002 Container Transitioned from ACQUIRED to RUNNING
2017-11-01 19:22:24,366 INFO org.apache.hadoop.yarn.server.resourcemanager.rmcontainer.RMContainerImpl: container_1509585476261_0002_01_000003 Container Transitioned from ACQUIRED to RUNNING
2017-11-01 19:22:24,367 INFO org.apache.hadoop.yarn.server.resourcemanager.rmcontainer.RMContainerImpl: container_1509585476261_0002_01_000004 Container Transitioned from ACQUIRED to RUNNING
2017-11-01 19:22:24,929 INFO org.apache.hadoop.yarn.server.resourcemanager.scheduler.AppSchedulingInfo: checking for deactivate of application :application_1509585476261_0002
2017-11-01 19:22:27,306 INFO org.apache.hadoop.yarn.server.resourcemanager.rmcontainer.RMContainerImpl: container_1509585476261_0002_01_000004 Container Transitioned from RUNNING to COMPLETED
2017-11-01 19:22:27,306 INFO org.apache.hadoop.yarn.server.resourcemanager.RMAuditLogger: USER=wentingt	OPERATION=AM Released Container	TARGET=SchedulerApp	RESULT=SUCCESS	APPID=application_1509585476261_0002	CONTAINERID=container_1509585476261_0002_01_000004	RESOURCE=<memory:1024, vCores:1>
2017-11-01 19:22:27,395 INFO org.apache.hadoop.yarn.server.resourcemanager.rmcontainer.RMContainerImpl: container_1509585476261_0002_01_000002 Container Transitioned from RUNNING to COMPLETED
2017-11-01 19:22:27,395 INFO org.apache.hadoop.yarn.server.resourcemanager.RMAuditLogger: USER=wentingt	OPERATION=AM Released Container	TARGET=SchedulerApp	RESULT=SUCCESS	APPID=application_1509585476261_0002	CONTAINERID=container_1509585476261_0002_01_000002	RESOURCE=<memory:1024, vCores:1>
2017-11-01 19:22:27,417 INFO org.apache.hadoop.yarn.server.resourcemanager.rmcontainer.RMContainerImpl: container_1509585476261_0002_01_000003 Container Transitioned from RUNNING to COMPLETED
2017-11-01 19:22:27,417 INFO org.apache.hadoop.yarn.server.resourcemanager.RMAuditLogger: USER=wentingt	OPERATION=AM Released Container	TARGET=SchedulerApp	RESULT=SUCCESS	APPID=application_1509585476261_0002	CONTAINERID=container_1509585476261_0002_01_000003	RESOURCE=<memory:1024, vCores:1>
2017-11-01 19:22:29,421 INFO org.apache.hadoop.yarn.server.resourcemanager.scheduler.capacity.allocator.AbstractContainerAllocator: assignedContainer application attempt=appattempt_1509585476261_0002_000001 container=null queue=org.apache.hadoop.yarn.server.resourcemanager.scheduler.capacity.allocator.RegularContainerAllocator@7b52fe4 clusterResource=<memory:24576, vCores:24> type=OFF_SWITCH requestedPartition=
2017-11-01 19:22:29,421 INFO org.apache.hadoop.yarn.server.resourcemanager.scheduler.capacity.ParentQueue: assignedContainer queue=root usedCapacity=0.083333336 absoluteUsedCapacity=0.083333336 used=<memory:2048, vCores:1> cluster=<memory:24576, vCores:24>
2017-11-01 19:22:29,422 INFO org.apache.hadoop.yarn.server.resourcemanager.rmcontainer.RMContainerImpl: container_1509585476261_0002_01_000005 Container Transitioned from NEW to ALLOCATED
2017-11-01 19:22:29,422 INFO org.apache.hadoop.yarn.server.resourcemanager.scheduler.common.fica.FiCaSchedulerNode: Assigned container container_1509585476261_0002_01_000005 of capacity <memory:1024, vCores:1> on host c220g1-031112.wisc.cloudlab.us:46102, which has 2 containers, <memory:3072, vCores:2> used and <memory:5120, vCores:6> available after allocation
2017-11-01 19:22:29,422 INFO org.apache.hadoop.yarn.server.resourcemanager.RMAuditLogger: USER=wentingt	OPERATION=AM Allocated Container	TARGET=SchedulerApp	RESULT=SUCCESS	APPID=application_1509585476261_0002	CONTAINERID=container_1509585476261_0002_01_000005	RESOURCE=<memory:1024, vCores:1>
2017-11-01 19:22:29,422 INFO org.apache.hadoop.yarn.server.resourcemanager.scheduler.capacity.ParentQueue: assignedContainer queue=root usedCapacity=0.125 absoluteUsedCapacity=0.125 used=<memory:3072, vCores:2> cluster=<memory:24576, vCores:24>
2017-11-01 19:22:29,422 INFO org.apache.hadoop.yarn.server.resourcemanager.scheduler.capacity.CapacityScheduler: Allocation proposal accepted
2017-11-01 19:22:29,959 INFO org.apache.hadoop.yarn.server.resourcemanager.rmcontainer.RMContainerImpl: container_1509585476261_0002_01_000005 Container Transitioned from ALLOCATED to ACQUIRED
2017-11-01 19:22:30,423 INFO org.apache.hadoop.yarn.server.resourcemanager.rmcontainer.RMContainerImpl: container_1509585476261_0002_01_000005 Container Transitioned from ACQUIRED to RUNNING
2017-11-01 19:22:30,964 INFO org.apache.hadoop.yarn.server.resourcemanager.scheduler.AppSchedulingInfo: checking for deactivate of application :application_1509585476261_0002
2017-11-01 19:22:59,930 INFO org.apache.hadoop.yarn.server.resourcemanager.rmcontainer.RMContainerImpl: container_1509585476261_0002_01_000005 Container Transitioned from RUNNING to COMPLETED
2017-11-01 19:22:59,930 INFO org.apache.hadoop.yarn.server.resourcemanager.RMAuditLogger: USER=wentingt	OPERATION=AM Released Container	TARGET=SchedulerApp	RESULT=SUCCESS	APPID=application_1509585476261_0002	CONTAINERID=container_1509585476261_0002_01_000005	RESOURCE=<memory:1024, vCores:1>
2017-11-01 19:23:00,127 INFO org.apache.hadoop.yarn.server.resourcemanager.rmapp.attempt.RMAppAttemptImpl: Updating application attempt appattempt_1509585476261_0002_000001 with final state: FINISHING, and exit status: -1000
2017-11-01 19:23:00,128 INFO org.apache.hadoop.yarn.server.resourcemanager.rmapp.attempt.RMAppAttemptImpl: appattempt_1509585476261_0002_000001 State change from RUNNING to FINAL_SAVING on event = UNREGISTERED
2017-11-01 19:23:00,128 INFO org.apache.hadoop.yarn.server.resourcemanager.rmapp.RMAppImpl: Updating application application_1509585476261_0002 with final state: FINISHING
2017-11-01 19:23:00,128 INFO org.apache.hadoop.yarn.server.resourcemanager.rmapp.RMAppImpl: application_1509585476261_0002 State change from RUNNING to FINAL_SAVING on event = ATTEMPT_UNREGISTERED
2017-11-01 19:23:00,128 INFO org.apache.hadoop.yarn.server.resourcemanager.recovery.RMStateStore: Updating info for app: application_1509585476261_0002
2017-11-01 19:23:00,128 INFO org.apache.hadoop.yarn.server.resourcemanager.rmapp.attempt.RMAppAttemptImpl: appattempt_1509585476261_0002_000001 State change from FINAL_SAVING to FINISHING on event = ATTEMPT_UPDATE_SAVED
2017-11-01 19:23:00,128 INFO org.apache.hadoop.yarn.server.resourcemanager.rmapp.RMAppImpl: application_1509585476261_0002 State change from FINAL_SAVING to FINISHING on event = APP_UPDATE_SAVED
2017-11-01 19:23:01,129 INFO org.apache.hadoop.yarn.server.resourcemanager.ApplicationMasterService: application_1509585476261_0002 unregistered successfully. 
2017-11-01 19:23:06,542 INFO org.apache.hadoop.yarn.server.resourcemanager.rmcontainer.RMContainerImpl: container_1509585476261_0002_01_000001 Container Transitioned from RUNNING to COMPLETED
2017-11-01 19:23:06,542 INFO org.apache.hadoop.yarn.server.resourcemanager.ApplicationMasterService: Unregistering app attempt : appattempt_1509585476261_0002_000001
2017-11-01 19:23:06,543 INFO org.apache.hadoop.yarn.server.resourcemanager.security.AMRMTokenSecretManager: Application finished, removing password for appattempt_1509585476261_0002_000001
2017-11-01 19:23:06,543 INFO org.apache.hadoop.yarn.server.resourcemanager.RMAuditLogger: USER=wentingt	OPERATION=AM Released Container	TARGET=SchedulerApp	RESULT=SUCCESS	APPID=application_1509585476261_0002	CONTAINERID=container_1509585476261_0002_01_000001	RESOURCE=<memory:2048, vCores:1>
2017-11-01 19:23:06,543 INFO org.apache.hadoop.yarn.server.resourcemanager.rmapp.attempt.RMAppAttemptImpl: appattempt_1509585476261_0002_000001 State change from FINISHING to FINISHED on event = CONTAINER_FINISHED
2017-11-01 19:23:06,543 INFO org.apache.hadoop.yarn.server.resourcemanager.rmapp.RMAppImpl: application_1509585476261_0002 State change from FINISHING to FINISHED on event = ATTEMPT_FINISHED
2017-11-01 19:23:06,543 INFO org.apache.hadoop.yarn.server.resourcemanager.scheduler.capacity.CapacityScheduler: Application Attempt appattempt_1509585476261_0002_000001 is done. finalState=FINISHED
2017-11-01 19:23:06,543 INFO org.apache.hadoop.yarn.server.resourcemanager.RMAuditLogger: USER=wentingt	OPERATION=Application Finished - Succeeded	TARGET=RMAppManager	RESULT=SUCCESS	APPID=application_1509585476261_0002
2017-11-01 19:23:06,543 INFO org.apache.hadoop.yarn.server.resourcemanager.scheduler.AppSchedulingInfo: Application application_1509585476261_0002 requests cleared
2017-11-01 19:23:06,543 INFO org.apache.hadoop.yarn.server.resourcemanager.scheduler.capacity.LeafQueue: Application removed - appId: application_1509585476261_0002 user: wentingt queue: default #user-pending-applications: 0 #user-active-applications: 0 #queue-pending-applications: 0 #queue-active-applications: 0
2017-11-01 19:23:06,544 INFO org.apache.hadoop.yarn.server.resourcemanager.scheduler.capacity.ParentQueue: Application removed - appId: application_1509585476261_0002 user: wentingt leaf-queue of parent: root #applications: 0
2017-11-01 19:23:06,544 INFO org.apache.hadoop.yarn.server.resourcemanager.amlauncher.AMLauncher: Cleaning master appattempt_1509585476261_0002_000001
2017-11-01 19:23:06,544 INFO org.apache.hadoop.yarn.server.resourcemanager.RMAppManager$ApplicationSummary: appId=application_1509585476261_0002,name=QuasiMonteCarlo,user=wentingt,queue=default,state=FINISHED,trackingUrl=http://c220g1-031117.wisc.cloudlab.us:8088/proxy/application_1509585476261_0002/,appMasterHost=c220g1-031112.wisc.cloudlab.us,submitTime=1509585735859,startTime=1509585735860,finishTime=1509585780128,finalStatus=SUCCEEDED,memorySeconds=146338,vcoreSeconds=91,preemptedMemorySeconds=0,preemptedVcoreSeconds=0,preemptedAMContainers=0,preemptedNonAMContainers=0,preemptedResources=<memory:0\, vCores:0>,applicationType=MAPREDUCE
2017-11-01 19:27:56,130 INFO org.apache.hadoop.yarn.server.resourcemanager.scheduler.AbstractYarnScheduler: Release request cache is cleaned up
2017-11-01 19:34:15,899 INFO org.apache.hadoop.yarn.server.resourcemanager.ClientRMService: Allocated new applicationId: 3
2017-11-01 19:34:16,723 INFO org.apache.hadoop.yarn.server.resourcemanager.scheduler.capacity.CapacityScheduler: Application 'application_1509585476261_0003' is submitted without priority hence considering default queue/cluster priority: 0
2017-11-01 19:34:16,723 INFO org.apache.hadoop.yarn.server.resourcemanager.scheduler.capacity.CapacityScheduler: Priority '0' is acceptable in queue : default for application: application_1509585476261_0003
2017-11-01 19:34:16,724 INFO org.apache.hadoop.yarn.server.resourcemanager.ClientRMService: Application with id 3 submitted by user wentingt
2017-11-01 19:34:16,724 INFO org.apache.hadoop.yarn.server.resourcemanager.RMAuditLogger: USER=wentingt	IP=10.0.0.1	OPERATION=Submit Application Request	TARGET=ClientRMService	RESULT=SUCCESS	APPID=application_1509585476261_0003	CALLERCONTEXT=CLI
2017-11-01 19:34:16,724 INFO org.apache.hadoop.yarn.server.resourcemanager.rmapp.RMAppImpl: Storing application with id application_1509585476261_0003
2017-11-01 19:34:16,724 INFO org.apache.hadoop.yarn.server.resourcemanager.recovery.RMStateStore: Storing info for app: application_1509585476261_0003
2017-11-01 19:34:16,724 INFO org.apache.hadoop.yarn.server.resourcemanager.rmapp.RMAppImpl: application_1509585476261_0003 State change from NEW to NEW_SAVING on event = START
2017-11-01 19:34:16,724 INFO org.apache.hadoop.yarn.server.resourcemanager.rmapp.RMAppImpl: application_1509585476261_0003 State change from NEW_SAVING to SUBMITTED on event = APP_NEW_SAVED
2017-11-01 19:34:16,724 INFO org.apache.hadoop.yarn.server.resourcemanager.scheduler.capacity.ParentQueue: Application added - appId: application_1509585476261_0003 user: wentingt leaf-queue of parent: root #applications: 1
2017-11-01 19:34:16,724 INFO org.apache.hadoop.yarn.server.resourcemanager.scheduler.capacity.CapacityScheduler: Accepted application application_1509585476261_0003 from user: wentingt, in queue: default
2017-11-01 19:34:16,727 INFO org.apache.hadoop.yarn.server.resourcemanager.rmapp.RMAppImpl: application_1509585476261_0003 State change from SUBMITTED to ACCEPTED on event = APP_ACCEPTED
2017-11-01 19:34:16,727 INFO org.apache.hadoop.yarn.server.resourcemanager.ApplicationMasterService: Registering app attempt : appattempt_1509585476261_0003_000001
2017-11-01 19:34:16,728 INFO org.apache.hadoop.yarn.server.resourcemanager.rmapp.attempt.RMAppAttemptImpl: appattempt_1509585476261_0003_000001 State change from NEW to SUBMITTED on event = START
2017-11-01 19:34:16,728 INFO org.apache.hadoop.yarn.server.resourcemanager.scheduler.capacity.LeafQueue: Application application_1509585476261_0003 from user: wentingt activated in queue: default
2017-11-01 19:34:16,728 INFO org.apache.hadoop.yarn.server.resourcemanager.scheduler.capacity.LeafQueue: Application added - appId: application_1509585476261_0003 user: wentingt, leaf-queue: default #user-pending-applications: 0 #user-active-applications: 1 #queue-pending-applications: 0 #queue-active-applications: 1
2017-11-01 19:34:16,728 INFO org.apache.hadoop.yarn.server.resourcemanager.scheduler.capacity.CapacityScheduler: Added Application Attempt appattempt_1509585476261_0003_000001 to scheduler from user wentingt in queue default
2017-11-01 19:34:16,729 INFO org.apache.hadoop.yarn.server.resourcemanager.rmapp.attempt.RMAppAttemptImpl: appattempt_1509585476261_0003_000001 State change from SUBMITTED to SCHEDULED on event = ATTEMPT_ADDED
2017-11-01 19:34:17,233 INFO org.apache.hadoop.yarn.server.resourcemanager.scheduler.capacity.allocator.AbstractContainerAllocator: assignedContainer application attempt=appattempt_1509585476261_0003_000001 container=null queue=org.apache.hadoop.yarn.server.resourcemanager.scheduler.capacity.allocator.RegularContainerAllocator@449944c clusterResource=<memory:24576, vCores:24> type=OFF_SWITCH requestedPartition=
2017-11-01 19:34:17,233 INFO org.apache.hadoop.yarn.server.resourcemanager.scheduler.capacity.ParentQueue: assignedContainer queue=root usedCapacity=0.0 absoluteUsedCapacity=0.0 used=<memory:0, vCores:0> cluster=<memory:24576, vCores:24>
2017-11-01 19:34:17,233 INFO org.apache.hadoop.yarn.server.resourcemanager.rmcontainer.RMContainerImpl: container_1509585476261_0003_01_000001 Container Transitioned from NEW to ALLOCATED
2017-11-01 19:34:17,234 INFO org.apache.hadoop.yarn.server.resourcemanager.scheduler.common.fica.FiCaSchedulerNode: Assigned container container_1509585476261_0003_01_000001 of capacity <memory:2048, vCores:1> on host c220g1-031112.wisc.cloudlab.us:46102, which has 1 containers, <memory:2048, vCores:1> used and <memory:6144, vCores:7> available after allocation
2017-11-01 19:34:17,234 INFO org.apache.hadoop.yarn.server.resourcemanager.RMAuditLogger: USER=wentingt	OPERATION=AM Allocated Container	TARGET=SchedulerApp	RESULT=SUCCESS	APPID=application_1509585476261_0003	CONTAINERID=container_1509585476261_0003_01_000001	RESOURCE=<memory:2048, vCores:1>
2017-11-01 19:34:17,235 INFO org.apache.hadoop.yarn.server.resourcemanager.security.NMTokenSecretManagerInRM: Sending NMToken for nodeId : c220g1-031112.wisc.cloudlab.us:46102 for container : container_1509585476261_0003_01_000001
2017-11-01 19:34:17,238 INFO org.apache.hadoop.yarn.server.resourcemanager.rmcontainer.RMContainerImpl: container_1509585476261_0003_01_000001 Container Transitioned from ALLOCATED to ACQUIRED
2017-11-01 19:34:17,238 INFO org.apache.hadoop.yarn.server.resourcemanager.security.NMTokenSecretManagerInRM: Clear node set for appattempt_1509585476261_0003_000001
2017-11-01 19:34:17,238 INFO org.apache.hadoop.yarn.server.resourcemanager.scheduler.capacity.ParentQueue: assignedContainer queue=root usedCapacity=0.083333336 absoluteUsedCapacity=0.083333336 used=<memory:2048, vCores:1> cluster=<memory:24576, vCores:24>
2017-11-01 19:34:17,238 INFO org.apache.hadoop.yarn.server.resourcemanager.scheduler.capacity.CapacityScheduler: Allocation proposal accepted
2017-11-01 19:34:17,238 INFO org.apache.hadoop.yarn.server.resourcemanager.rmapp.attempt.RMAppAttemptImpl: Storing attempt: AppId: application_1509585476261_0003 AttemptId: appattempt_1509585476261_0003_000001 MasterContainer: Container: [ContainerId: container_1509585476261_0003_01_000001, AllocationRequestId: 0, Version: 0, NodeId: c220g1-031112.wisc.cloudlab.us:46102, NodeHttpAddress: c220g1-031112.wisc.cloudlab.us:8042, Resource: <memory:2048, vCores:1>, Priority: 0, Token: Token { kind: ContainerToken, service: 128.104.222.22:46102 }, ExecutionType: GUARANTEED, ]
2017-11-01 19:34:17,239 INFO org.apache.hadoop.yarn.server.resourcemanager.rmapp.attempt.RMAppAttemptImpl: appattempt_1509585476261_0003_000001 State change from SCHEDULED to ALLOCATED_SAVING on event = CONTAINER_ALLOCATED
2017-11-01 19:34:17,239 INFO org.apache.hadoop.yarn.server.resourcemanager.rmapp.attempt.RMAppAttemptImpl: appattempt_1509585476261_0003_000001 State change from ALLOCATED_SAVING to ALLOCATED on event = ATTEMPT_NEW_SAVED
2017-11-01 19:34:17,241 INFO org.apache.hadoop.yarn.server.resourcemanager.amlauncher.AMLauncher: Launching masterappattempt_1509585476261_0003_000001
2017-11-01 19:34:17,244 INFO org.apache.hadoop.yarn.server.resourcemanager.amlauncher.AMLauncher: Setting up container Container: [ContainerId: container_1509585476261_0003_01_000001, AllocationRequestId: 0, Version: 0, NodeId: c220g1-031112.wisc.cloudlab.us:46102, NodeHttpAddress: c220g1-031112.wisc.cloudlab.us:8042, Resource: <memory:2048, vCores:1>, Priority: 0, Token: Token { kind: ContainerToken, service: 128.104.222.22:46102 }, ExecutionType: GUARANTEED, ] for AM appattempt_1509585476261_0003_000001
2017-11-01 19:34:17,245 INFO org.apache.hadoop.yarn.server.resourcemanager.security.AMRMTokenSecretManager: Create AMRMToken for ApplicationAttempt: appattempt_1509585476261_0003_000001
2017-11-01 19:34:17,245 INFO org.apache.hadoop.yarn.server.resourcemanager.security.AMRMTokenSecretManager: Creating password for appattempt_1509585476261_0003_000001
2017-11-01 19:34:17,264 INFO org.apache.hadoop.yarn.server.resourcemanager.amlauncher.AMLauncher: Done launching container Container: [ContainerId: container_1509585476261_0003_01_000001, AllocationRequestId: 0, Version: 0, NodeId: c220g1-031112.wisc.cloudlab.us:46102, NodeHttpAddress: c220g1-031112.wisc.cloudlab.us:8042, Resource: <memory:2048, vCores:1>, Priority: 0, Token: Token { kind: ContainerToken, service: 128.104.222.22:46102 }, ExecutionType: GUARANTEED, ] for AM appattempt_1509585476261_0003_000001
2017-11-01 19:34:17,264 INFO org.apache.hadoop.yarn.server.resourcemanager.rmapp.attempt.RMAppAttemptImpl: appattempt_1509585476261_0003_000001 State change from ALLOCATED to LAUNCHED on event = LAUNCHED
2017-11-01 19:34:18,234 INFO org.apache.hadoop.yarn.server.resourcemanager.rmcontainer.RMContainerImpl: container_1509585476261_0003_01_000001 Container Transitioned from ACQUIRED to RUNNING
2017-11-01 19:34:22,662 INFO SecurityLogger.org.apache.hadoop.ipc.Server: Auth successful for appattempt_1509585476261_0003_000001 (auth:SIMPLE)
2017-11-01 19:34:22,667 INFO org.apache.hadoop.yarn.server.resourcemanager.DefaultAMSProcessor: AM registration appattempt_1509585476261_0003_000001
2017-11-01 19:34:22,668 INFO org.apache.hadoop.yarn.server.resourcemanager.RMAuditLogger: USER=wentingt	IP=10.0.0.2	OPERATION=Register App Master	TARGET=ApplicationMasterService	RESULT=SUCCESS	APPID=application_1509585476261_0003	APPATTEMPTID=appattempt_1509585476261_0003_000001
2017-11-01 19:34:22,668 INFO org.apache.hadoop.yarn.server.resourcemanager.rmapp.attempt.RMAppAttemptImpl: appattempt_1509585476261_0003_000001 State change from LAUNCHED to RUNNING on event = REGISTERED
2017-11-01 19:34:22,668 INFO org.apache.hadoop.yarn.server.resourcemanager.rmapp.RMAppImpl: application_1509585476261_0003 State change from ACCEPTED to RUNNING on event = ATTEMPT_REGISTERED
2017-11-01 19:34:24,243 INFO org.apache.hadoop.yarn.server.resourcemanager.scheduler.capacity.allocator.AbstractContainerAllocator: assignedContainer application attempt=appattempt_1509585476261_0003_000001 container=null queue=org.apache.hadoop.yarn.server.resourcemanager.scheduler.capacity.allocator.RegularContainerAllocator@449944c clusterResource=<memory:24576, vCores:24> type=NODE_LOCAL requestedPartition=
2017-11-01 19:34:24,243 INFO org.apache.hadoop.yarn.server.resourcemanager.scheduler.capacity.ParentQueue: assignedContainer queue=root usedCapacity=0.083333336 absoluteUsedCapacity=0.083333336 used=<memory:2048, vCores:1> cluster=<memory:24576, vCores:24>
2017-11-01 19:34:24,244 INFO org.apache.hadoop.yarn.server.resourcemanager.rmcontainer.RMContainerImpl: container_1509585476261_0003_01_000002 Container Transitioned from NEW to ALLOCATED
2017-11-01 19:34:24,244 INFO org.apache.hadoop.yarn.server.resourcemanager.scheduler.common.fica.FiCaSchedulerNode: Assigned container container_1509585476261_0003_01_000002 of capacity <memory:1024, vCores:1> on host c220g1-031112.wisc.cloudlab.us:46102, which has 2 containers, <memory:3072, vCores:2> used and <memory:5120, vCores:6> available after allocation
2017-11-01 19:34:24,244 INFO org.apache.hadoop.yarn.server.resourcemanager.RMAuditLogger: USER=wentingt	OPERATION=AM Allocated Container	TARGET=SchedulerApp	RESULT=SUCCESS	APPID=application_1509585476261_0003	CONTAINERID=container_1509585476261_0003_01_000002	RESOURCE=<memory:1024, vCores:1>
2017-11-01 19:34:24,244 INFO org.apache.hadoop.yarn.server.resourcemanager.scheduler.capacity.ParentQueue: assignedContainer queue=root usedCapacity=0.125 absoluteUsedCapacity=0.125 used=<memory:3072, vCores:2> cluster=<memory:24576, vCores:24>
2017-11-01 19:34:24,244 INFO org.apache.hadoop.yarn.server.resourcemanager.scheduler.capacity.CapacityScheduler: Allocation proposal accepted
2017-11-01 19:34:24,245 INFO org.apache.hadoop.yarn.server.resourcemanager.scheduler.capacity.allocator.AbstractContainerAllocator: assignedContainer application attempt=appattempt_1509585476261_0003_000001 container=null queue=org.apache.hadoop.yarn.server.resourcemanager.scheduler.capacity.allocator.RegularContainerAllocator@449944c clusterResource=<memory:24576, vCores:24> type=NODE_LOCAL requestedPartition=
2017-11-01 19:34:24,245 INFO org.apache.hadoop.yarn.server.resourcemanager.scheduler.capacity.ParentQueue: assignedContainer queue=root usedCapacity=0.125 absoluteUsedCapacity=0.125 used=<memory:3072, vCores:2> cluster=<memory:24576, vCores:24>
2017-11-01 19:34:24,245 INFO org.apache.hadoop.yarn.server.resourcemanager.rmcontainer.RMContainerImpl: container_1509585476261_0003_01_000003 Container Transitioned from NEW to ALLOCATED
2017-11-01 19:34:24,245 INFO org.apache.hadoop.yarn.server.resourcemanager.scheduler.common.fica.FiCaSchedulerNode: Assigned container container_1509585476261_0003_01_000003 of capacity <memory:1024, vCores:1> on host c220g1-031112.wisc.cloudlab.us:46102, which has 3 containers, <memory:4096, vCores:3> used and <memory:4096, vCores:5> available after allocation
2017-11-01 19:34:24,245 INFO org.apache.hadoop.yarn.server.resourcemanager.RMAuditLogger: USER=wentingt	OPERATION=AM Allocated Container	TARGET=SchedulerApp	RESULT=SUCCESS	APPID=application_1509585476261_0003	CONTAINERID=container_1509585476261_0003_01_000003	RESOURCE=<memory:1024, vCores:1>
2017-11-01 19:34:24,246 INFO org.apache.hadoop.yarn.server.resourcemanager.scheduler.capacity.ParentQueue: assignedContainer queue=root usedCapacity=0.16666667 absoluteUsedCapacity=0.16666667 used=<memory:4096, vCores:3> cluster=<memory:24576, vCores:24>
2017-11-01 19:34:24,246 INFO org.apache.hadoop.yarn.server.resourcemanager.scheduler.capacity.CapacityScheduler: Allocation proposal accepted
2017-11-01 19:34:24,246 INFO org.apache.hadoop.yarn.server.resourcemanager.scheduler.capacity.allocator.AbstractContainerAllocator: assignedContainer application attempt=appattempt_1509585476261_0003_000001 container=null queue=org.apache.hadoop.yarn.server.resourcemanager.scheduler.capacity.allocator.RegularContainerAllocator@449944c clusterResource=<memory:24576, vCores:24> type=NODE_LOCAL requestedPartition=
2017-11-01 19:34:24,246 INFO org.apache.hadoop.yarn.server.resourcemanager.scheduler.capacity.ParentQueue: assignedContainer queue=root usedCapacity=0.16666667 absoluteUsedCapacity=0.16666667 used=<memory:4096, vCores:3> cluster=<memory:24576, vCores:24>
2017-11-01 19:34:24,247 INFO org.apache.hadoop.yarn.server.resourcemanager.rmcontainer.RMContainerImpl: container_1509585476261_0003_01_000004 Container Transitioned from NEW to ALLOCATED
2017-11-01 19:34:24,247 INFO org.apache.hadoop.yarn.server.resourcemanager.scheduler.common.fica.FiCaSchedulerNode: Assigned container container_1509585476261_0003_01_000004 of capacity <memory:1024, vCores:1> on host c220g1-031112.wisc.cloudlab.us:46102, which has 4 containers, <memory:5120, vCores:4> used and <memory:3072, vCores:4> available after allocation
2017-11-01 19:34:24,248 INFO org.apache.hadoop.yarn.server.resourcemanager.RMAuditLogger: USER=wentingt	OPERATION=AM Allocated Container	TARGET=SchedulerApp	RESULT=SUCCESS	APPID=application_1509585476261_0003	CONTAINERID=container_1509585476261_0003_01_000004	RESOURCE=<memory:1024, vCores:1>
2017-11-01 19:34:24,248 INFO org.apache.hadoop.yarn.server.resourcemanager.scheduler.capacity.ParentQueue: assignedContainer queue=root usedCapacity=0.20833333 absoluteUsedCapacity=0.20833333 used=<memory:5120, vCores:4> cluster=<memory:24576, vCores:24>
2017-11-01 19:34:24,248 INFO org.apache.hadoop.yarn.server.resourcemanager.scheduler.capacity.CapacityScheduler: Allocation proposal accepted
2017-11-01 19:34:24,747 INFO org.apache.hadoop.yarn.server.resourcemanager.security.NMTokenSecretManagerInRM: Sending NMToken for nodeId : c220g1-031112.wisc.cloudlab.us:46102 for container : container_1509585476261_0003_01_000002
2017-11-01 19:34:24,748 INFO org.apache.hadoop.yarn.server.resourcemanager.rmcontainer.RMContainerImpl: container_1509585476261_0003_01_000002 Container Transitioned from ALLOCATED to ACQUIRED
2017-11-01 19:34:24,749 INFO org.apache.hadoop.yarn.server.resourcemanager.rmcontainer.RMContainerImpl: container_1509585476261_0003_01_000003 Container Transitioned from ALLOCATED to ACQUIRED
2017-11-01 19:34:24,751 INFO org.apache.hadoop.yarn.server.resourcemanager.rmcontainer.RMContainerImpl: container_1509585476261_0003_01_000004 Container Transitioned from ALLOCATED to ACQUIRED
2017-11-01 19:34:25,276 INFO org.apache.hadoop.yarn.server.resourcemanager.rmcontainer.RMContainerImpl: container_1509585476261_0003_01_000002 Container Transitioned from ACQUIRED to RUNNING
2017-11-01 19:34:25,277 INFO org.apache.hadoop.yarn.server.resourcemanager.rmcontainer.RMContainerImpl: container_1509585476261_0003_01_000003 Container Transitioned from ACQUIRED to RUNNING
2017-11-01 19:34:25,277 INFO org.apache.hadoop.yarn.server.resourcemanager.rmcontainer.RMContainerImpl: container_1509585476261_0003_01_000004 Container Transitioned from ACQUIRED to RUNNING
2017-11-01 19:34:25,775 INFO org.apache.hadoop.yarn.server.resourcemanager.scheduler.AppSchedulingInfo: checking for deactivate of application :application_1509585476261_0003
2017-11-01 19:34:28,250 INFO org.apache.hadoop.yarn.server.resourcemanager.rmcontainer.RMContainerImpl: container_1509585476261_0003_01_000002 Container Transitioned from RUNNING to COMPLETED
2017-11-01 19:34:28,250 INFO org.apache.hadoop.yarn.server.resourcemanager.RMAuditLogger: USER=wentingt	OPERATION=AM Released Container	TARGET=SchedulerApp	RESULT=SUCCESS	APPID=application_1509585476261_0003	CONTAINERID=container_1509585476261_0003_01_000002	RESOURCE=<memory:1024, vCores:1>
2017-11-01 19:34:28,276 INFO org.apache.hadoop.yarn.server.resourcemanager.rmcontainer.RMContainerImpl: container_1509585476261_0003_01_000004 Container Transitioned from RUNNING to COMPLETED
2017-11-01 19:34:28,276 INFO org.apache.hadoop.yarn.server.resourcemanager.RMAuditLogger: USER=wentingt	OPERATION=AM Released Container	TARGET=SchedulerApp	RESULT=SUCCESS	APPID=application_1509585476261_0003	CONTAINERID=container_1509585476261_0003_01_000004	RESOURCE=<memory:1024, vCores:1>
2017-11-01 19:34:28,301 INFO org.apache.hadoop.yarn.server.resourcemanager.rmcontainer.RMContainerImpl: container_1509585476261_0003_01_000003 Container Transitioned from RUNNING to COMPLETED
2017-11-01 19:34:28,301 INFO org.apache.hadoop.yarn.server.resourcemanager.RMAuditLogger: USER=wentingt	OPERATION=AM Released Container	TARGET=SchedulerApp	RESULT=SUCCESS	APPID=application_1509585476261_0003	CONTAINERID=container_1509585476261_0003_01_000003	RESOURCE=<memory:1024, vCores:1>
2017-11-01 19:34:30,304 INFO org.apache.hadoop.yarn.server.resourcemanager.scheduler.capacity.allocator.AbstractContainerAllocator: assignedContainer application attempt=appattempt_1509585476261_0003_000001 container=null queue=org.apache.hadoop.yarn.server.resourcemanager.scheduler.capacity.allocator.RegularContainerAllocator@449944c clusterResource=<memory:24576, vCores:24> type=OFF_SWITCH requestedPartition=
2017-11-01 19:34:30,304 INFO org.apache.hadoop.yarn.server.resourcemanager.scheduler.capacity.ParentQueue: assignedContainer queue=root usedCapacity=0.083333336 absoluteUsedCapacity=0.083333336 used=<memory:2048, vCores:1> cluster=<memory:24576, vCores:24>
2017-11-01 19:34:30,305 INFO org.apache.hadoop.yarn.server.resourcemanager.rmcontainer.RMContainerImpl: container_1509585476261_0003_01_000005 Container Transitioned from NEW to ALLOCATED
2017-11-01 19:34:30,306 INFO org.apache.hadoop.yarn.server.resourcemanager.scheduler.common.fica.FiCaSchedulerNode: Assigned container container_1509585476261_0003_01_000005 of capacity <memory:1024, vCores:1> on host c220g1-031112.wisc.cloudlab.us:46102, which has 2 containers, <memory:3072, vCores:2> used and <memory:5120, vCores:6> available after allocation
2017-11-01 19:34:30,306 INFO org.apache.hadoop.yarn.server.resourcemanager.RMAuditLogger: USER=wentingt	OPERATION=AM Allocated Container	TARGET=SchedulerApp	RESULT=SUCCESS	APPID=application_1509585476261_0003	CONTAINERID=container_1509585476261_0003_01_000005	RESOURCE=<memory:1024, vCores:1>
2017-11-01 19:34:30,306 INFO org.apache.hadoop.yarn.server.resourcemanager.scheduler.capacity.ParentQueue: assignedContainer queue=root usedCapacity=0.125 absoluteUsedCapacity=0.125 used=<memory:3072, vCores:2> cluster=<memory:24576, vCores:24>
2017-11-01 19:34:30,306 INFO org.apache.hadoop.yarn.server.resourcemanager.scheduler.capacity.CapacityScheduler: Allocation proposal accepted
2017-11-01 19:34:30,801 INFO org.apache.hadoop.yarn.server.resourcemanager.rmcontainer.RMContainerImpl: container_1509585476261_0003_01_000005 Container Transitioned from ALLOCATED to ACQUIRED
2017-11-01 19:34:31,306 INFO org.apache.hadoop.yarn.server.resourcemanager.rmcontainer.RMContainerImpl: container_1509585476261_0003_01_000005 Container Transitioned from ACQUIRED to RUNNING
2017-11-01 19:34:31,806 INFO org.apache.hadoop.yarn.server.resourcemanager.scheduler.AppSchedulingInfo: checking for deactivate of application :application_1509585476261_0003
2017-11-01 19:34:34,749 INFO org.apache.hadoop.yarn.server.resourcemanager.rmapp.attempt.RMAppAttemptImpl: Updating application attempt appattempt_1509585476261_0003_000001 with final state: FINISHING, and exit status: -1000
2017-11-01 19:34:34,749 INFO org.apache.hadoop.yarn.server.resourcemanager.rmapp.attempt.RMAppAttemptImpl: appattempt_1509585476261_0003_000001 State change from RUNNING to FINAL_SAVING on event = UNREGISTERED
2017-11-01 19:34:34,749 INFO org.apache.hadoop.yarn.server.resourcemanager.rmapp.RMAppImpl: Updating application application_1509585476261_0003 with final state: FINISHING
2017-11-01 19:34:34,750 INFO org.apache.hadoop.yarn.server.resourcemanager.recovery.RMStateStore: Updating info for app: application_1509585476261_0003
2017-11-01 19:34:34,750 INFO org.apache.hadoop.yarn.server.resourcemanager.rmapp.RMAppImpl: application_1509585476261_0003 State change from RUNNING to FINAL_SAVING on event = ATTEMPT_UNREGISTERED
2017-11-01 19:34:34,750 INFO org.apache.hadoop.yarn.server.resourcemanager.rmapp.attempt.RMAppAttemptImpl: appattempt_1509585476261_0003_000001 State change from FINAL_SAVING to FINISHING on event = ATTEMPT_UPDATE_SAVED
2017-11-01 19:34:34,750 INFO org.apache.hadoop.yarn.server.resourcemanager.rmapp.RMAppImpl: application_1509585476261_0003 State change from FINAL_SAVING to FINISHING on event = APP_UPDATE_SAVED
2017-11-01 19:34:34,762 INFO org.apache.hadoop.yarn.server.resourcemanager.rmcontainer.RMContainerImpl: container_1509585476261_0003_01_000005 Container Transitioned from RUNNING to COMPLETED
2017-11-01 19:34:34,762 INFO org.apache.hadoop.yarn.server.resourcemanager.RMAuditLogger: USER=wentingt	OPERATION=AM Released Container	TARGET=SchedulerApp	RESULT=SUCCESS	APPID=application_1509585476261_0003	CONTAINERID=container_1509585476261_0003_01_000005	RESOURCE=<memory:1024, vCores:1>
2017-11-01 19:34:35,751 INFO org.apache.hadoop.yarn.server.resourcemanager.ApplicationMasterService: application_1509585476261_0003 unregistered successfully. 
2017-11-01 19:34:41,165 INFO org.apache.hadoop.yarn.server.resourcemanager.rmcontainer.RMContainerImpl: container_1509585476261_0003_01_000001 Container Transitioned from RUNNING to COMPLETED
2017-11-01 19:34:41,165 INFO org.apache.hadoop.yarn.server.resourcemanager.ApplicationMasterService: Unregistering app attempt : appattempt_1509585476261_0003_000001
2017-11-01 19:34:41,165 INFO org.apache.hadoop.yarn.server.resourcemanager.RMAuditLogger: USER=wentingt	OPERATION=AM Released Container	TARGET=SchedulerApp	RESULT=SUCCESS	APPID=application_1509585476261_0003	CONTAINERID=container_1509585476261_0003_01_000001	RESOURCE=<memory:2048, vCores:1>
2017-11-01 19:34:41,165 INFO org.apache.hadoop.yarn.server.resourcemanager.security.AMRMTokenSecretManager: Application finished, removing password for appattempt_1509585476261_0003_000001
2017-11-01 19:34:41,165 INFO org.apache.hadoop.yarn.server.resourcemanager.rmapp.attempt.RMAppAttemptImpl: appattempt_1509585476261_0003_000001 State change from FINISHING to FINISHED on event = CONTAINER_FINISHED
2017-11-01 19:34:41,165 INFO org.apache.hadoop.yarn.server.resourcemanager.rmapp.RMAppImpl: application_1509585476261_0003 State change from FINISHING to FINISHED on event = ATTEMPT_FINISHED
2017-11-01 19:34:41,165 INFO org.apache.hadoop.yarn.server.resourcemanager.scheduler.capacity.CapacityScheduler: Application Attempt appattempt_1509585476261_0003_000001 is done. finalState=FINISHED
2017-11-01 19:34:41,166 INFO org.apache.hadoop.yarn.server.resourcemanager.RMAuditLogger: USER=wentingt	OPERATION=Application Finished - Succeeded	TARGET=RMAppManager	RESULT=SUCCESS	APPID=application_1509585476261_0003
2017-11-01 19:34:41,166 INFO org.apache.hadoop.yarn.server.resourcemanager.scheduler.AppSchedulingInfo: Application application_1509585476261_0003 requests cleared
2017-11-01 19:34:41,166 INFO org.apache.hadoop.yarn.server.resourcemanager.scheduler.capacity.LeafQueue: Application removed - appId: application_1509585476261_0003 user: wentingt queue: default #user-pending-applications: 0 #user-active-applications: 0 #queue-pending-applications: 0 #queue-active-applications: 0
2017-11-01 19:34:41,166 INFO org.apache.hadoop.yarn.server.resourcemanager.scheduler.capacity.ParentQueue: Application removed - appId: application_1509585476261_0003 user: wentingt leaf-queue of parent: root #applications: 0
2017-11-01 19:34:41,166 INFO org.apache.hadoop.yarn.server.resourcemanager.amlauncher.AMLauncher: Cleaning master appattempt_1509585476261_0003_000001
2017-11-01 19:34:41,166 INFO org.apache.hadoop.yarn.server.resourcemanager.RMAppManager$ApplicationSummary: appId=application_1509585476261_0003,name=QuasiMonteCarlo,user=wentingt,queue=default,state=FINISHED,trackingUrl=http://c220g1-031117.wisc.cloudlab.us:8088/proxy/application_1509585476261_0003/,appMasterHost=c220g1-031112.wisc.cloudlab.us,submitTime=1509586456723,startTime=1509586456723,finishTime=1509586474749,finalStatus=SUCCEEDED,memorySeconds=65960,vcoreSeconds=39,preemptedMemorySeconds=0,preemptedVcoreSeconds=0,preemptedAMContainers=0,preemptedNonAMContainers=0,preemptedResources=<memory:0\, vCores:0>,applicationType=MAPREDUCE
2017-11-01 19:42:36,074 INFO org.apache.hadoop.yarn.server.resourcemanager.ClientRMService: Allocated new applicationId: 4
2017-11-01 19:42:36,862 INFO org.apache.hadoop.yarn.server.resourcemanager.scheduler.capacity.CapacityScheduler: Application 'application_1509585476261_0004' is submitted without priority hence considering default queue/cluster priority: 0
2017-11-01 19:42:36,862 INFO org.apache.hadoop.yarn.server.resourcemanager.scheduler.capacity.CapacityScheduler: Priority '0' is acceptable in queue : default for application: application_1509585476261_0004
2017-11-01 19:42:36,863 INFO org.apache.hadoop.yarn.server.resourcemanager.ClientRMService: Application with id 4 submitted by user wentingt
2017-11-01 19:42:36,863 INFO org.apache.hadoop.yarn.server.resourcemanager.RMAuditLogger: USER=wentingt	IP=10.0.0.1	OPERATION=Submit Application Request	TARGET=ClientRMService	RESULT=SUCCESS	APPID=application_1509585476261_0004	CALLERCONTEXT=CLI
2017-11-01 19:42:36,863 INFO org.apache.hadoop.yarn.server.resourcemanager.rmapp.RMAppImpl: Storing application with id application_1509585476261_0004
2017-11-01 19:42:36,863 INFO org.apache.hadoop.yarn.server.resourcemanager.recovery.RMStateStore: Storing info for app: application_1509585476261_0004
2017-11-01 19:42:36,864 INFO org.apache.hadoop.yarn.server.resourcemanager.rmapp.RMAppImpl: application_1509585476261_0004 State change from NEW to NEW_SAVING on event = START
2017-11-01 19:42:36,864 INFO org.apache.hadoop.yarn.server.resourcemanager.rmapp.RMAppImpl: application_1509585476261_0004 State change from NEW_SAVING to SUBMITTED on event = APP_NEW_SAVED
2017-11-01 19:42:36,864 INFO org.apache.hadoop.yarn.server.resourcemanager.scheduler.capacity.ParentQueue: Application added - appId: application_1509585476261_0004 user: wentingt leaf-queue of parent: root #applications: 1
2017-11-01 19:42:36,864 INFO org.apache.hadoop.yarn.server.resourcemanager.scheduler.capacity.CapacityScheduler: Accepted application application_1509585476261_0004 from user: wentingt, in queue: default
2017-11-01 19:42:36,867 INFO org.apache.hadoop.yarn.server.resourcemanager.rmapp.RMAppImpl: application_1509585476261_0004 State change from SUBMITTED to ACCEPTED on event = APP_ACCEPTED
2017-11-01 19:42:36,867 INFO org.apache.hadoop.yarn.server.resourcemanager.ApplicationMasterService: Registering app attempt : appattempt_1509585476261_0004_000001
2017-11-01 19:42:36,867 INFO org.apache.hadoop.yarn.server.resourcemanager.rmapp.attempt.RMAppAttemptImpl: appattempt_1509585476261_0004_000001 State change from NEW to SUBMITTED on event = START
2017-11-01 19:42:36,868 INFO org.apache.hadoop.yarn.server.resourcemanager.scheduler.capacity.LeafQueue: Application application_1509585476261_0004 from user: wentingt activated in queue: default
2017-11-01 19:42:36,868 INFO org.apache.hadoop.yarn.server.resourcemanager.scheduler.capacity.LeafQueue: Application added - appId: application_1509585476261_0004 user: wentingt, leaf-queue: default #user-pending-applications: 0 #user-active-applications: 1 #queue-pending-applications: 0 #queue-active-applications: 1
2017-11-01 19:42:36,868 INFO org.apache.hadoop.yarn.server.resourcemanager.scheduler.capacity.CapacityScheduler: Added Application Attempt appattempt_1509585476261_0004_000001 to scheduler from user wentingt in queue default
2017-11-01 19:42:36,869 INFO org.apache.hadoop.yarn.server.resourcemanager.rmapp.attempt.RMAppAttemptImpl: appattempt_1509585476261_0004_000001 State change from SUBMITTED to SCHEDULED on event = ATTEMPT_ADDED
2017-11-01 19:42:37,027 INFO org.apache.hadoop.yarn.server.resourcemanager.scheduler.capacity.allocator.AbstractContainerAllocator: assignedContainer application attempt=appattempt_1509585476261_0004_000001 container=null queue=org.apache.hadoop.yarn.server.resourcemanager.scheduler.capacity.allocator.RegularContainerAllocator@5e2d7034 clusterResource=<memory:24576, vCores:24> type=OFF_SWITCH requestedPartition=
2017-11-01 19:42:37,027 INFO org.apache.hadoop.yarn.server.resourcemanager.scheduler.capacity.ParentQueue: assignedContainer queue=root usedCapacity=0.0 absoluteUsedCapacity=0.0 used=<memory:0, vCores:0> cluster=<memory:24576, vCores:24>
2017-11-01 19:42:37,028 INFO org.apache.hadoop.yarn.server.resourcemanager.rmcontainer.RMContainerImpl: container_1509585476261_0004_01_000001 Container Transitioned from NEW to ALLOCATED
2017-11-01 19:42:37,028 INFO org.apache.hadoop.yarn.server.resourcemanager.scheduler.common.fica.FiCaSchedulerNode: Assigned container container_1509585476261_0004_01_000001 of capacity <memory:2048, vCores:1> on host c220g1-031119.wisc.cloudlab.us:38777, which has 1 containers, <memory:2048, vCores:1> used and <memory:6144, vCores:7> available after allocation
2017-11-01 19:42:37,028 INFO org.apache.hadoop.yarn.server.resourcemanager.RMAuditLogger: USER=wentingt	OPERATION=AM Allocated Container	TARGET=SchedulerApp	RESULT=SUCCESS	APPID=application_1509585476261_0004	CONTAINERID=container_1509585476261_0004_01_000001	RESOURCE=<memory:2048, vCores:1>
2017-11-01 19:42:37,029 INFO org.apache.hadoop.yarn.server.resourcemanager.security.NMTokenSecretManagerInRM: Sending NMToken for nodeId : c220g1-031119.wisc.cloudlab.us:38777 for container : container_1509585476261_0004_01_000001
2017-11-01 19:42:37,031 INFO org.apache.hadoop.yarn.server.resourcemanager.rmcontainer.RMContainerImpl: container_1509585476261_0004_01_000001 Container Transitioned from ALLOCATED to ACQUIRED
2017-11-01 19:42:37,031 INFO org.apache.hadoop.yarn.server.resourcemanager.security.NMTokenSecretManagerInRM: Clear node set for appattempt_1509585476261_0004_000001
2017-11-01 19:42:37,031 INFO org.apache.hadoop.yarn.server.resourcemanager.rmapp.attempt.RMAppAttemptImpl: Storing attempt: AppId: application_1509585476261_0004 AttemptId: appattempt_1509585476261_0004_000001 MasterContainer: Container: [ContainerId: container_1509585476261_0004_01_000001, AllocationRequestId: 0, Version: 0, NodeId: c220g1-031119.wisc.cloudlab.us:38777, NodeHttpAddress: c220g1-031119.wisc.cloudlab.us:8042, Resource: <memory:2048, vCores:1>, Priority: 0, Token: Token { kind: ContainerToken, service: 128.104.222.29:38777 }, ExecutionType: GUARANTEED, ]
2017-11-01 19:42:37,031 INFO org.apache.hadoop.yarn.server.resourcemanager.scheduler.capacity.ParentQueue: assignedContainer queue=root usedCapacity=0.083333336 absoluteUsedCapacity=0.083333336 used=<memory:2048, vCores:1> cluster=<memory:24576, vCores:24>
2017-11-01 19:42:37,031 INFO org.apache.hadoop.yarn.server.resourcemanager.scheduler.capacity.CapacityScheduler: Allocation proposal accepted
2017-11-01 19:42:37,031 INFO org.apache.hadoop.yarn.server.resourcemanager.rmapp.attempt.RMAppAttemptImpl: appattempt_1509585476261_0004_000001 State change from SCHEDULED to ALLOCATED_SAVING on event = CONTAINER_ALLOCATED
2017-11-01 19:42:37,032 INFO org.apache.hadoop.yarn.server.resourcemanager.rmapp.attempt.RMAppAttemptImpl: appattempt_1509585476261_0004_000001 State change from ALLOCATED_SAVING to ALLOCATED on event = ATTEMPT_NEW_SAVED
2017-11-01 19:42:37,033 INFO org.apache.hadoop.yarn.server.resourcemanager.amlauncher.AMLauncher: Launching masterappattempt_1509585476261_0004_000001
2017-11-01 19:42:37,035 INFO org.apache.hadoop.yarn.server.resourcemanager.amlauncher.AMLauncher: Setting up container Container: [ContainerId: container_1509585476261_0004_01_000001, AllocationRequestId: 0, Version: 0, NodeId: c220g1-031119.wisc.cloudlab.us:38777, NodeHttpAddress: c220g1-031119.wisc.cloudlab.us:8042, Resource: <memory:2048, vCores:1>, Priority: 0, Token: Token { kind: ContainerToken, service: 128.104.222.29:38777 }, ExecutionType: GUARANTEED, ] for AM appattempt_1509585476261_0004_000001
2017-11-01 19:42:37,035 INFO org.apache.hadoop.yarn.server.resourcemanager.security.AMRMTokenSecretManager: Create AMRMToken for ApplicationAttempt: appattempt_1509585476261_0004_000001
2017-11-01 19:42:37,036 INFO org.apache.hadoop.yarn.server.resourcemanager.security.AMRMTokenSecretManager: Creating password for appattempt_1509585476261_0004_000001
2017-11-01 19:42:37,076 INFO org.apache.hadoop.yarn.server.resourcemanager.amlauncher.AMLauncher: Done launching container Container: [ContainerId: container_1509585476261_0004_01_000001, AllocationRequestId: 0, Version: 0, NodeId: c220g1-031119.wisc.cloudlab.us:38777, NodeHttpAddress: c220g1-031119.wisc.cloudlab.us:8042, Resource: <memory:2048, vCores:1>, Priority: 0, Token: Token { kind: ContainerToken, service: 128.104.222.29:38777 }, ExecutionType: GUARANTEED, ] for AM appattempt_1509585476261_0004_000001
2017-11-01 19:42:37,076 INFO org.apache.hadoop.yarn.server.resourcemanager.rmapp.attempt.RMAppAttemptImpl: appattempt_1509585476261_0004_000001 State change from ALLOCATED to LAUNCHED on event = LAUNCHED
2017-11-01 19:42:38,027 INFO org.apache.hadoop.yarn.server.resourcemanager.rmcontainer.RMContainerImpl: container_1509585476261_0004_01_000001 Container Transitioned from ACQUIRED to RUNNING
2017-11-01 19:42:41,996 INFO SecurityLogger.org.apache.hadoop.ipc.Server: Auth successful for appattempt_1509585476261_0004_000001 (auth:SIMPLE)
2017-11-01 19:42:42,005 INFO org.apache.hadoop.yarn.server.resourcemanager.DefaultAMSProcessor: AM registration appattempt_1509585476261_0004_000001
2017-11-01 19:42:42,005 INFO org.apache.hadoop.yarn.server.resourcemanager.RMAuditLogger: USER=wentingt	IP=10.0.0.4	OPERATION=Register App Master	TARGET=ApplicationMasterService	RESULT=SUCCESS	APPID=application_1509585476261_0004	APPATTEMPTID=appattempt_1509585476261_0004_000001
2017-11-01 19:42:42,005 INFO org.apache.hadoop.yarn.server.resourcemanager.rmapp.attempt.RMAppAttemptImpl: appattempt_1509585476261_0004_000001 State change from LAUNCHED to RUNNING on event = REGISTERED
2017-11-01 19:42:42,006 INFO org.apache.hadoop.yarn.server.resourcemanager.rmapp.RMAppImpl: application_1509585476261_0004 State change from ACCEPTED to RUNNING on event = ATTEMPT_REGISTERED
2017-11-01 19:42:43,121 INFO org.apache.hadoop.yarn.server.resourcemanager.scheduler.capacity.allocator.AbstractContainerAllocator: assignedContainer application attempt=appattempt_1509585476261_0004_000001 container=null queue=org.apache.hadoop.yarn.server.resourcemanager.scheduler.capacity.allocator.RegularContainerAllocator@5e2d7034 clusterResource=<memory:24576, vCores:24> type=NODE_LOCAL requestedPartition=
2017-11-01 19:42:43,121 INFO org.apache.hadoop.yarn.server.resourcemanager.scheduler.capacity.ParentQueue: assignedContainer queue=root usedCapacity=0.083333336 absoluteUsedCapacity=0.083333336 used=<memory:2048, vCores:1> cluster=<memory:24576, vCores:24>
2017-11-01 19:42:43,121 INFO org.apache.hadoop.yarn.server.resourcemanager.rmcontainer.RMContainerImpl: container_1509585476261_0004_01_000002 Container Transitioned from NEW to ALLOCATED
2017-11-01 19:42:43,121 INFO org.apache.hadoop.yarn.server.resourcemanager.scheduler.common.fica.FiCaSchedulerNode: Assigned container container_1509585476261_0004_01_000002 of capacity <memory:1024, vCores:1> on host c220g1-031118.wisc.cloudlab.us:33290, which has 1 containers, <memory:1024, vCores:1> used and <memory:7168, vCores:7> available after allocation
2017-11-01 19:42:43,121 INFO org.apache.hadoop.yarn.server.resourcemanager.RMAuditLogger: USER=wentingt	OPERATION=AM Allocated Container	TARGET=SchedulerApp	RESULT=SUCCESS	APPID=application_1509585476261_0004	CONTAINERID=container_1509585476261_0004_01_000002	RESOURCE=<memory:1024, vCores:1>
2017-11-01 19:42:43,122 INFO org.apache.hadoop.yarn.server.resourcemanager.scheduler.capacity.ParentQueue: assignedContainer queue=root usedCapacity=0.125 absoluteUsedCapacity=0.125 used=<memory:3072, vCores:2> cluster=<memory:24576, vCores:24>
2017-11-01 19:42:43,122 INFO org.apache.hadoop.yarn.server.resourcemanager.scheduler.capacity.CapacityScheduler: Allocation proposal accepted
2017-11-01 19:42:43,122 INFO org.apache.hadoop.yarn.server.resourcemanager.scheduler.capacity.allocator.AbstractContainerAllocator: assignedContainer application attempt=appattempt_1509585476261_0004_000001 container=null queue=org.apache.hadoop.yarn.server.resourcemanager.scheduler.capacity.allocator.RegularContainerAllocator@5e2d7034 clusterResource=<memory:24576, vCores:24> type=NODE_LOCAL requestedPartition=
2017-11-01 19:42:43,122 INFO org.apache.hadoop.yarn.server.resourcemanager.scheduler.capacity.ParentQueue: assignedContainer queue=root usedCapacity=0.125 absoluteUsedCapacity=0.125 used=<memory:3072, vCores:2> cluster=<memory:24576, vCores:24>
2017-11-01 19:42:43,122 INFO org.apache.hadoop.yarn.server.resourcemanager.rmcontainer.RMContainerImpl: container_1509585476261_0004_01_000003 Container Transitioned from NEW to ALLOCATED
2017-11-01 19:42:43,123 INFO org.apache.hadoop.yarn.server.resourcemanager.scheduler.common.fica.FiCaSchedulerNode: Assigned container container_1509585476261_0004_01_000003 of capacity <memory:1024, vCores:1> on host c220g1-031118.wisc.cloudlab.us:33290, which has 2 containers, <memory:2048, vCores:2> used and <memory:6144, vCores:6> available after allocation
2017-11-01 19:42:43,123 INFO org.apache.hadoop.yarn.server.resourcemanager.RMAuditLogger: USER=wentingt	OPERATION=AM Allocated Container	TARGET=SchedulerApp	RESULT=SUCCESS	APPID=application_1509585476261_0004	CONTAINERID=container_1509585476261_0004_01_000003	RESOURCE=<memory:1024, vCores:1>
2017-11-01 19:42:43,123 INFO org.apache.hadoop.yarn.server.resourcemanager.scheduler.capacity.ParentQueue: assignedContainer queue=root usedCapacity=0.16666667 absoluteUsedCapacity=0.16666667 used=<memory:4096, vCores:3> cluster=<memory:24576, vCores:24>
2017-11-01 19:42:43,123 INFO org.apache.hadoop.yarn.server.resourcemanager.scheduler.capacity.CapacityScheduler: Allocation proposal accepted
2017-11-01 19:42:43,123 INFO org.apache.hadoop.yarn.server.resourcemanager.scheduler.capacity.allocator.AbstractContainerAllocator: assignedContainer application attempt=appattempt_1509585476261_0004_000001 container=null queue=org.apache.hadoop.yarn.server.resourcemanager.scheduler.capacity.allocator.RegularContainerAllocator@5e2d7034 clusterResource=<memory:24576, vCores:24> type=NODE_LOCAL requestedPartition=
2017-11-01 19:42:43,123 INFO org.apache.hadoop.yarn.server.resourcemanager.scheduler.capacity.ParentQueue: assignedContainer queue=root usedCapacity=0.16666667 absoluteUsedCapacity=0.16666667 used=<memory:4096, vCores:3> cluster=<memory:24576, vCores:24>
2017-11-01 19:42:43,126 INFO org.apache.hadoop.yarn.server.resourcemanager.rmcontainer.RMContainerImpl: container_1509585476261_0004_01_000004 Container Transitioned from NEW to ALLOCATED
2017-11-01 19:42:43,126 INFO org.apache.hadoop.yarn.server.resourcemanager.scheduler.common.fica.FiCaSchedulerNode: Assigned container container_1509585476261_0004_01_000004 of capacity <memory:1024, vCores:1> on host c220g1-031118.wisc.cloudlab.us:33290, which has 3 containers, <memory:3072, vCores:3> used and <memory:5120, vCores:5> available after allocation
2017-11-01 19:42:43,126 INFO org.apache.hadoop.yarn.server.resourcemanager.RMAuditLogger: USER=wentingt	OPERATION=AM Allocated Container	TARGET=SchedulerApp	RESULT=SUCCESS	APPID=application_1509585476261_0004	CONTAINERID=container_1509585476261_0004_01_000004	RESOURCE=<memory:1024, vCores:1>
2017-11-01 19:42:43,126 INFO org.apache.hadoop.yarn.server.resourcemanager.scheduler.capacity.ParentQueue: assignedContainer queue=root usedCapacity=0.20833333 absoluteUsedCapacity=0.20833333 used=<memory:5120, vCores:4> cluster=<memory:24576, vCores:24>
2017-11-01 19:42:43,126 INFO org.apache.hadoop.yarn.server.resourcemanager.scheduler.capacity.CapacityScheduler: Allocation proposal accepted
2017-11-01 19:42:44,096 INFO org.apache.hadoop.yarn.server.resourcemanager.security.NMTokenSecretManagerInRM: Sending NMToken for nodeId : c220g1-031118.wisc.cloudlab.us:33290 for container : container_1509585476261_0004_01_000002
2017-11-01 19:42:44,097 INFO org.apache.hadoop.yarn.server.resourcemanager.rmcontainer.RMContainerImpl: container_1509585476261_0004_01_000002 Container Transitioned from ALLOCATED to ACQUIRED
2017-11-01 19:42:44,116 INFO org.apache.hadoop.yarn.server.resourcemanager.rmcontainer.RMContainerImpl: container_1509585476261_0004_01_000003 Container Transitioned from ALLOCATED to ACQUIRED
2017-11-01 19:42:44,117 INFO org.apache.hadoop.yarn.server.resourcemanager.rmcontainer.RMContainerImpl: container_1509585476261_0004_01_000004 Container Transitioned from ALLOCATED to ACQUIRED
2017-11-01 19:42:45,136 INFO org.apache.hadoop.yarn.server.resourcemanager.rmcontainer.RMContainerImpl: container_1509585476261_0004_01_000002 Container Transitioned from ACQUIRED to RUNNING
2017-11-01 19:42:45,136 INFO org.apache.hadoop.yarn.server.resourcemanager.rmcontainer.RMContainerImpl: container_1509585476261_0004_01_000003 Container Transitioned from ACQUIRED to RUNNING
2017-11-01 19:42:45,137 INFO org.apache.hadoop.yarn.server.resourcemanager.rmcontainer.RMContainerImpl: container_1509585476261_0004_01_000004 Container Transitioned from ACQUIRED to RUNNING
2017-11-01 19:42:45,143 INFO org.apache.hadoop.yarn.server.resourcemanager.scheduler.AppSchedulingInfo: checking for deactivate of application :application_1509585476261_0004
2017-11-01 19:42:49,347 INFO org.apache.hadoop.yarn.server.resourcemanager.rmcontainer.RMContainerImpl: container_1509585476261_0004_01_000004 Container Transitioned from RUNNING to COMPLETED
2017-11-01 19:42:49,366 INFO org.apache.hadoop.yarn.server.resourcemanager.RMAuditLogger: USER=wentingt	OPERATION=AM Released Container	TARGET=SchedulerApp	RESULT=SUCCESS	APPID=application_1509585476261_0004	CONTAINERID=container_1509585476261_0004_01_000004	RESOURCE=<memory:1024, vCores:1>
2017-11-01 19:42:49,375 INFO org.apache.hadoop.yarn.server.resourcemanager.rmcontainer.RMContainerImpl: container_1509585476261_0004_01_000002 Container Transitioned from RUNNING to COMPLETED
2017-11-01 19:42:49,375 INFO org.apache.hadoop.yarn.server.resourcemanager.RMAuditLogger: USER=wentingt	OPERATION=AM Released Container	TARGET=SchedulerApp	RESULT=SUCCESS	APPID=application_1509585476261_0004	CONTAINERID=container_1509585476261_0004_01_000002	RESOURCE=<memory:1024, vCores:1>
2017-11-01 19:42:49,376 INFO org.apache.hadoop.yarn.server.resourcemanager.rmcontainer.RMContainerImpl: container_1509585476261_0004_01_000003 Container Transitioned from RUNNING to COMPLETED
2017-11-01 19:42:49,376 INFO org.apache.hadoop.yarn.server.resourcemanager.RMAuditLogger: USER=wentingt	OPERATION=AM Released Container	TARGET=SchedulerApp	RESULT=SUCCESS	APPID=application_1509585476261_0004	CONTAINERID=container_1509585476261_0004_01_000003	RESOURCE=<memory:1024, vCores:1>
2017-11-01 19:42:50,377 INFO org.apache.hadoop.yarn.server.resourcemanager.scheduler.capacity.allocator.AbstractContainerAllocator: assignedContainer application attempt=appattempt_1509585476261_0004_000001 container=null queue=org.apache.hadoop.yarn.server.resourcemanager.scheduler.capacity.allocator.RegularContainerAllocator@5e2d7034 clusterResource=<memory:24576, vCores:24> type=OFF_SWITCH requestedPartition=
2017-11-01 19:42:50,377 INFO org.apache.hadoop.yarn.server.resourcemanager.scheduler.capacity.ParentQueue: assignedContainer queue=root usedCapacity=0.083333336 absoluteUsedCapacity=0.083333336 used=<memory:2048, vCores:1> cluster=<memory:24576, vCores:24>
2017-11-01 19:42:50,377 INFO org.apache.hadoop.yarn.server.resourcemanager.rmcontainer.RMContainerImpl: container_1509585476261_0004_01_000005 Container Transitioned from NEW to ALLOCATED
2017-11-01 19:42:50,377 INFO org.apache.hadoop.yarn.server.resourcemanager.scheduler.common.fica.FiCaSchedulerNode: Assigned container container_1509585476261_0004_01_000005 of capacity <memory:1024, vCores:1> on host c220g1-031118.wisc.cloudlab.us:33290, which has 1 containers, <memory:1024, vCores:1> used and <memory:7168, vCores:7> available after allocation
2017-11-01 19:42:50,377 INFO org.apache.hadoop.yarn.server.resourcemanager.RMAuditLogger: USER=wentingt	OPERATION=AM Allocated Container	TARGET=SchedulerApp	RESULT=SUCCESS	APPID=application_1509585476261_0004	CONTAINERID=container_1509585476261_0004_01_000005	RESOURCE=<memory:1024, vCores:1>
2017-11-01 19:42:50,378 INFO org.apache.hadoop.yarn.server.resourcemanager.scheduler.capacity.ParentQueue: assignedContainer queue=root usedCapacity=0.125 absoluteUsedCapacity=0.125 used=<memory:3072, vCores:2> cluster=<memory:24576, vCores:24>
2017-11-01 19:42:50,378 INFO org.apache.hadoop.yarn.server.resourcemanager.scheduler.capacity.CapacityScheduler: Allocation proposal accepted
2017-11-01 19:42:51,170 INFO org.apache.hadoop.yarn.server.resourcemanager.rmcontainer.RMContainerImpl: container_1509585476261_0004_01_000005 Container Transitioned from ALLOCATED to ACQUIRED
2017-11-01 19:42:51,378 INFO org.apache.hadoop.yarn.server.resourcemanager.rmcontainer.RMContainerImpl: container_1509585476261_0004_01_000005 Container Transitioned from ACQUIRED to RUNNING
2017-11-01 19:42:52,174 INFO org.apache.hadoop.yarn.server.resourcemanager.scheduler.AppSchedulingInfo: checking for deactivate of application :application_1509585476261_0004
2017-11-01 19:42:55,408 INFO org.apache.hadoop.yarn.server.resourcemanager.rmapp.attempt.RMAppAttemptImpl: Updating application attempt appattempt_1509585476261_0004_000001 with final state: FINISHING, and exit status: -1000
2017-11-01 19:42:55,409 INFO org.apache.hadoop.yarn.server.resourcemanager.rmapp.attempt.RMAppAttemptImpl: appattempt_1509585476261_0004_000001 State change from RUNNING to FINAL_SAVING on event = UNREGISTERED
2017-11-01 19:42:55,409 INFO org.apache.hadoop.yarn.server.resourcemanager.rmapp.RMAppImpl: Updating application application_1509585476261_0004 with final state: FINISHING
2017-11-01 19:42:55,409 INFO org.apache.hadoop.yarn.server.resourcemanager.rmapp.RMAppImpl: application_1509585476261_0004 State change from RUNNING to FINAL_SAVING on event = ATTEMPT_UNREGISTERED
2017-11-01 19:42:55,409 INFO org.apache.hadoop.yarn.server.resourcemanager.recovery.RMStateStore: Updating info for app: application_1509585476261_0004
2017-11-01 19:42:55,409 INFO org.apache.hadoop.yarn.server.resourcemanager.rmapp.attempt.RMAppAttemptImpl: appattempt_1509585476261_0004_000001 State change from FINAL_SAVING to FINISHING on event = ATTEMPT_UPDATE_SAVED
2017-11-01 19:42:55,409 INFO org.apache.hadoop.yarn.server.resourcemanager.rmapp.RMAppImpl: application_1509585476261_0004 State change from FINAL_SAVING to FINISHING on event = APP_UPDATE_SAVED
2017-11-01 19:42:55,411 INFO org.apache.hadoop.yarn.server.resourcemanager.rmcontainer.RMContainerImpl: container_1509585476261_0004_01_000005 Container Transitioned from RUNNING to COMPLETED
2017-11-01 19:42:55,411 INFO org.apache.hadoop.yarn.server.resourcemanager.RMAuditLogger: USER=wentingt	OPERATION=AM Released Container	TARGET=SchedulerApp	RESULT=SUCCESS	APPID=application_1509585476261_0004	CONTAINERID=container_1509585476261_0004_01_000005	RESOURCE=<memory:1024, vCores:1>
2017-11-01 19:42:56,409 INFO org.apache.hadoop.yarn.server.resourcemanager.ApplicationMasterService: application_1509585476261_0004 unregistered successfully. 
2017-11-01 19:43:01,821 INFO org.apache.hadoop.yarn.server.resourcemanager.rmcontainer.RMContainerImpl: container_1509585476261_0004_01_000001 Container Transitioned from RUNNING to COMPLETED
2017-11-01 19:43:01,822 INFO org.apache.hadoop.yarn.server.resourcemanager.ApplicationMasterService: Unregistering app attempt : appattempt_1509585476261_0004_000001
2017-11-01 19:43:01,822 INFO org.apache.hadoop.yarn.server.resourcemanager.RMAuditLogger: USER=wentingt	OPERATION=AM Released Container	TARGET=SchedulerApp	RESULT=SUCCESS	APPID=application_1509585476261_0004	CONTAINERID=container_1509585476261_0004_01_000001	RESOURCE=<memory:2048, vCores:1>
2017-11-01 19:43:01,822 INFO org.apache.hadoop.yarn.server.resourcemanager.security.AMRMTokenSecretManager: Application finished, removing password for appattempt_1509585476261_0004_000001
2017-11-01 19:43:01,822 INFO org.apache.hadoop.yarn.server.resourcemanager.rmapp.attempt.RMAppAttemptImpl: appattempt_1509585476261_0004_000001 State change from FINISHING to FINISHED on event = CONTAINER_FINISHED
2017-11-01 19:43:01,822 INFO org.apache.hadoop.yarn.server.resourcemanager.rmapp.RMAppImpl: application_1509585476261_0004 State change from FINISHING to FINISHED on event = ATTEMPT_FINISHED
2017-11-01 19:43:01,823 INFO org.apache.hadoop.yarn.server.resourcemanager.scheduler.capacity.CapacityScheduler: Application Attempt appattempt_1509585476261_0004_000001 is done. finalState=FINISHED
2017-11-01 19:43:01,823 INFO org.apache.hadoop.yarn.server.resourcemanager.RMAuditLogger: USER=wentingt	OPERATION=Application Finished - Succeeded	TARGET=RMAppManager	RESULT=SUCCESS	APPID=application_1509585476261_0004
2017-11-01 19:43:01,823 INFO org.apache.hadoop.yarn.server.resourcemanager.scheduler.AppSchedulingInfo: Application application_1509585476261_0004 requests cleared
2017-11-01 19:43:01,823 INFO org.apache.hadoop.yarn.server.resourcemanager.scheduler.capacity.LeafQueue: Application removed - appId: application_1509585476261_0004 user: wentingt queue: default #user-pending-applications: 0 #user-active-applications: 0 #queue-pending-applications: 0 #queue-active-applications: 0
2017-11-01 19:43:01,823 INFO org.apache.hadoop.yarn.server.resourcemanager.scheduler.capacity.ParentQueue: Application removed - appId: application_1509585476261_0004 user: wentingt leaf-queue of parent: root #applications: 0
2017-11-01 19:43:01,823 INFO org.apache.hadoop.yarn.server.resourcemanager.amlauncher.AMLauncher: Cleaning master appattempt_1509585476261_0004_000001
2017-11-01 19:43:01,823 INFO org.apache.hadoop.yarn.server.resourcemanager.RMAppManager$ApplicationSummary: appId=application_1509585476261_0004,name=QuasiMonteCarlo,user=wentingt,queue=default,state=FINISHED,trackingUrl=http://c220g1-031117.wisc.cloudlab.us:8088/proxy/application_1509585476261_0004/,appMasterHost=c220g1-031119.wisc.cloudlab.us,submitTime=1509586956861,startTime=1509586956862,finishTime=1509586975409,finalStatus=SUCCEEDED,memorySeconds=75114,vcoreSeconds=47,preemptedMemorySeconds=0,preemptedVcoreSeconds=0,preemptedAMContainers=0,preemptedNonAMContainers=0,preemptedResources=<memory:0\, vCores:0>,applicationType=MAPREDUCE
2017-11-01 19:44:20,092 INFO org.apache.hadoop.yarn.server.resourcemanager.ClientRMService: Allocated new applicationId: 5
2017-11-01 19:44:20,901 INFO org.apache.hadoop.yarn.server.resourcemanager.scheduler.capacity.CapacityScheduler: Application 'application_1509585476261_0005' is submitted without priority hence considering default queue/cluster priority: 0
2017-11-01 19:44:20,901 INFO org.apache.hadoop.yarn.server.resourcemanager.scheduler.capacity.CapacityScheduler: Priority '0' is acceptable in queue : default for application: application_1509585476261_0005
2017-11-01 19:44:20,901 INFO org.apache.hadoop.yarn.server.resourcemanager.ClientRMService: Application with id 5 submitted by user wentingt
2017-11-01 19:44:20,901 INFO org.apache.hadoop.yarn.server.resourcemanager.RMAuditLogger: USER=wentingt	IP=10.0.0.1	OPERATION=Submit Application Request	TARGET=ClientRMService	RESULT=SUCCESS	APPID=application_1509585476261_0005	CALLERCONTEXT=CLI
2017-11-01 19:44:20,901 INFO org.apache.hadoop.yarn.server.resourcemanager.rmapp.RMAppImpl: Storing application with id application_1509585476261_0005
2017-11-01 19:44:20,903 INFO org.apache.hadoop.yarn.server.resourcemanager.recovery.RMStateStore: Storing info for app: application_1509585476261_0005
2017-11-01 19:44:20,903 INFO org.apache.hadoop.yarn.server.resourcemanager.rmapp.RMAppImpl: application_1509585476261_0005 State change from NEW to NEW_SAVING on event = START
2017-11-01 19:44:20,903 INFO org.apache.hadoop.yarn.server.resourcemanager.rmapp.RMAppImpl: application_1509585476261_0005 State change from NEW_SAVING to SUBMITTED on event = APP_NEW_SAVED
2017-11-01 19:44:20,903 INFO org.apache.hadoop.yarn.server.resourcemanager.scheduler.capacity.ParentQueue: Application added - appId: application_1509585476261_0005 user: wentingt leaf-queue of parent: root #applications: 1
2017-11-01 19:44:20,903 INFO org.apache.hadoop.yarn.server.resourcemanager.scheduler.capacity.CapacityScheduler: Accepted application application_1509585476261_0005 from user: wentingt, in queue: default
2017-11-01 19:44:20,905 INFO org.apache.hadoop.yarn.server.resourcemanager.rmapp.RMAppImpl: application_1509585476261_0005 State change from SUBMITTED to ACCEPTED on event = APP_ACCEPTED
2017-11-01 19:44:20,905 INFO org.apache.hadoop.yarn.server.resourcemanager.ApplicationMasterService: Registering app attempt : appattempt_1509585476261_0005_000001
2017-11-01 19:44:20,905 INFO org.apache.hadoop.yarn.server.resourcemanager.rmapp.attempt.RMAppAttemptImpl: appattempt_1509585476261_0005_000001 State change from NEW to SUBMITTED on event = START
2017-11-01 19:44:20,906 INFO org.apache.hadoop.yarn.server.resourcemanager.scheduler.capacity.LeafQueue: Application application_1509585476261_0005 from user: wentingt activated in queue: default
2017-11-01 19:44:20,906 INFO org.apache.hadoop.yarn.server.resourcemanager.scheduler.capacity.LeafQueue: Application added - appId: application_1509585476261_0005 user: wentingt, leaf-queue: default #user-pending-applications: 0 #user-active-applications: 1 #queue-pending-applications: 0 #queue-active-applications: 1
2017-11-01 19:44:20,906 INFO org.apache.hadoop.yarn.server.resourcemanager.scheduler.capacity.CapacityScheduler: Added Application Attempt appattempt_1509585476261_0005_000001 to scheduler from user wentingt in queue default
2017-11-01 19:44:20,907 INFO org.apache.hadoop.yarn.server.resourcemanager.rmapp.attempt.RMAppAttemptImpl: appattempt_1509585476261_0005_000001 State change from SUBMITTED to SCHEDULED on event = ATTEMPT_ADDED
2017-11-01 19:44:21,515 INFO org.apache.hadoop.yarn.server.resourcemanager.scheduler.capacity.allocator.AbstractContainerAllocator: assignedContainer application attempt=appattempt_1509585476261_0005_000001 container=null queue=org.apache.hadoop.yarn.server.resourcemanager.scheduler.capacity.allocator.RegularContainerAllocator@168e6449 clusterResource=<memory:24576, vCores:24> type=OFF_SWITCH requestedPartition=
2017-11-01 19:44:21,515 INFO org.apache.hadoop.yarn.server.resourcemanager.scheduler.capacity.ParentQueue: assignedContainer queue=root usedCapacity=0.0 absoluteUsedCapacity=0.0 used=<memory:0, vCores:0> cluster=<memory:24576, vCores:24>
2017-11-01 19:44:21,515 INFO org.apache.hadoop.yarn.server.resourcemanager.rmcontainer.RMContainerImpl: container_1509585476261_0005_01_000001 Container Transitioned from NEW to ALLOCATED
2017-11-01 19:44:21,515 INFO org.apache.hadoop.yarn.server.resourcemanager.scheduler.common.fica.FiCaSchedulerNode: Assigned container container_1509585476261_0005_01_000001 of capacity <memory:2048, vCores:1> on host c220g1-031118.wisc.cloudlab.us:33290, which has 1 containers, <memory:2048, vCores:1> used and <memory:6144, vCores:7> available after allocation
2017-11-01 19:44:21,515 INFO org.apache.hadoop.yarn.server.resourcemanager.RMAuditLogger: USER=wentingt	OPERATION=AM Allocated Container	TARGET=SchedulerApp	RESULT=SUCCESS	APPID=application_1509585476261_0005	CONTAINERID=container_1509585476261_0005_01_000001	RESOURCE=<memory:2048, vCores:1>
2017-11-01 19:44:21,516 INFO org.apache.hadoop.yarn.server.resourcemanager.security.NMTokenSecretManagerInRM: Sending NMToken for nodeId : c220g1-031118.wisc.cloudlab.us:33290 for container : container_1509585476261_0005_01_000001
2017-11-01 19:44:21,517 INFO org.apache.hadoop.yarn.server.resourcemanager.rmcontainer.RMContainerImpl: container_1509585476261_0005_01_000001 Container Transitioned from ALLOCATED to ACQUIRED
2017-11-01 19:44:21,517 INFO org.apache.hadoop.yarn.server.resourcemanager.security.NMTokenSecretManagerInRM: Clear node set for appattempt_1509585476261_0005_000001
2017-11-01 19:44:21,517 INFO org.apache.hadoop.yarn.server.resourcemanager.rmapp.attempt.RMAppAttemptImpl: Storing attempt: AppId: application_1509585476261_0005 AttemptId: appattempt_1509585476261_0005_000001 MasterContainer: Container: [ContainerId: container_1509585476261_0005_01_000001, AllocationRequestId: 0, Version: 0, NodeId: c220g1-031118.wisc.cloudlab.us:33290, NodeHttpAddress: c220g1-031118.wisc.cloudlab.us:8042, Resource: <memory:2048, vCores:1>, Priority: 0, Token: Token { kind: ContainerToken, service: 128.104.222.28:33290 }, ExecutionType: GUARANTEED, ]
2017-11-01 19:44:21,517 INFO org.apache.hadoop.yarn.server.resourcemanager.scheduler.capacity.ParentQueue: assignedContainer queue=root usedCapacity=0.083333336 absoluteUsedCapacity=0.083333336 used=<memory:2048, vCores:1> cluster=<memory:24576, vCores:24>
2017-11-01 19:44:21,517 INFO org.apache.hadoop.yarn.server.resourcemanager.scheduler.capacity.CapacityScheduler: Allocation proposal accepted
2017-11-01 19:44:21,518 INFO org.apache.hadoop.yarn.server.resourcemanager.rmapp.attempt.RMAppAttemptImpl: appattempt_1509585476261_0005_000001 State change from SCHEDULED to ALLOCATED_SAVING on event = CONTAINER_ALLOCATED
2017-11-01 19:44:21,518 INFO org.apache.hadoop.yarn.server.resourcemanager.rmapp.attempt.RMAppAttemptImpl: appattempt_1509585476261_0005_000001 State change from ALLOCATED_SAVING to ALLOCATED on event = ATTEMPT_NEW_SAVED
2017-11-01 19:44:21,519 INFO org.apache.hadoop.yarn.server.resourcemanager.amlauncher.AMLauncher: Launching masterappattempt_1509585476261_0005_000001
2017-11-01 19:44:21,521 INFO org.apache.hadoop.yarn.server.resourcemanager.amlauncher.AMLauncher: Setting up container Container: [ContainerId: container_1509585476261_0005_01_000001, AllocationRequestId: 0, Version: 0, NodeId: c220g1-031118.wisc.cloudlab.us:33290, NodeHttpAddress: c220g1-031118.wisc.cloudlab.us:8042, Resource: <memory:2048, vCores:1>, Priority: 0, Token: Token { kind: ContainerToken, service: 128.104.222.28:33290 }, ExecutionType: GUARANTEED, ] for AM appattempt_1509585476261_0005_000001
2017-11-01 19:44:21,521 INFO org.apache.hadoop.yarn.server.resourcemanager.security.AMRMTokenSecretManager: Create AMRMToken for ApplicationAttempt: appattempt_1509585476261_0005_000001
2017-11-01 19:44:21,521 INFO org.apache.hadoop.yarn.server.resourcemanager.security.AMRMTokenSecretManager: Creating password for appattempt_1509585476261_0005_000001
2017-11-01 19:44:21,549 INFO org.apache.hadoop.yarn.server.resourcemanager.amlauncher.AMLauncher: Done launching container Container: [ContainerId: container_1509585476261_0005_01_000001, AllocationRequestId: 0, Version: 0, NodeId: c220g1-031118.wisc.cloudlab.us:33290, NodeHttpAddress: c220g1-031118.wisc.cloudlab.us:8042, Resource: <memory:2048, vCores:1>, Priority: 0, Token: Token { kind: ContainerToken, service: 128.104.222.28:33290 }, ExecutionType: GUARANTEED, ] for AM appattempt_1509585476261_0005_000001
2017-11-01 19:44:21,550 INFO org.apache.hadoop.yarn.server.resourcemanager.rmapp.attempt.RMAppAttemptImpl: appattempt_1509585476261_0005_000001 State change from ALLOCATED to LAUNCHED on event = LAUNCHED
2017-11-01 19:44:22,516 INFO org.apache.hadoop.yarn.server.resourcemanager.rmcontainer.RMContainerImpl: container_1509585476261_0005_01_000001 Container Transitioned from ACQUIRED to RUNNING
2017-11-01 19:44:26,682 INFO SecurityLogger.org.apache.hadoop.ipc.Server: Auth successful for appattempt_1509585476261_0005_000001 (auth:SIMPLE)
2017-11-01 19:44:26,691 INFO org.apache.hadoop.yarn.server.resourcemanager.DefaultAMSProcessor: AM registration appattempt_1509585476261_0005_000001
2017-11-01 19:44:26,693 INFO org.apache.hadoop.yarn.server.resourcemanager.RMAuditLogger: USER=wentingt	IP=10.0.0.3	OPERATION=Register App Master	TARGET=ApplicationMasterService	RESULT=SUCCESS	APPID=application_1509585476261_0005	APPATTEMPTID=appattempt_1509585476261_0005_000001
2017-11-01 19:44:26,693 INFO org.apache.hadoop.yarn.server.resourcemanager.rmapp.attempt.RMAppAttemptImpl: appattempt_1509585476261_0005_000001 State change from LAUNCHED to RUNNING on event = REGISTERED
2017-11-01 19:44:26,694 INFO org.apache.hadoop.yarn.server.resourcemanager.rmapp.RMAppImpl: application_1509585476261_0005 State change from ACCEPTED to RUNNING on event = ATTEMPT_REGISTERED
2017-11-01 19:44:27,913 INFO org.apache.hadoop.yarn.server.resourcemanager.scheduler.capacity.allocator.AbstractContainerAllocator: assignedContainer application attempt=appattempt_1509585476261_0005_000001 container=null queue=org.apache.hadoop.yarn.server.resourcemanager.scheduler.capacity.allocator.RegularContainerAllocator@168e6449 clusterResource=<memory:24576, vCores:24> type=NODE_LOCAL requestedPartition=
2017-11-01 19:44:27,914 INFO org.apache.hadoop.yarn.server.resourcemanager.scheduler.capacity.ParentQueue: assignedContainer queue=root usedCapacity=0.083333336 absoluteUsedCapacity=0.083333336 used=<memory:2048, vCores:1> cluster=<memory:24576, vCores:24>
2017-11-01 19:44:27,914 INFO org.apache.hadoop.yarn.server.resourcemanager.rmcontainer.RMContainerImpl: container_1509585476261_0005_01_000002 Container Transitioned from NEW to ALLOCATED
2017-11-01 19:44:27,914 INFO org.apache.hadoop.yarn.server.resourcemanager.scheduler.common.fica.FiCaSchedulerNode: Assigned container container_1509585476261_0005_01_000002 of capacity <memory:1024, vCores:1> on host c220g1-031119.wisc.cloudlab.us:38777, which has 1 containers, <memory:1024, vCores:1> used and <memory:7168, vCores:7> available after allocation
2017-11-01 19:44:27,914 INFO org.apache.hadoop.yarn.server.resourcemanager.RMAuditLogger: USER=wentingt	OPERATION=AM Allocated Container	TARGET=SchedulerApp	RESULT=SUCCESS	APPID=application_1509585476261_0005	CONTAINERID=container_1509585476261_0005_01_000002	RESOURCE=<memory:1024, vCores:1>
2017-11-01 19:44:27,915 INFO org.apache.hadoop.yarn.server.resourcemanager.scheduler.capacity.ParentQueue: assignedContainer queue=root usedCapacity=0.125 absoluteUsedCapacity=0.125 used=<memory:3072, vCores:2> cluster=<memory:24576, vCores:24>
2017-11-01 19:44:27,915 INFO org.apache.hadoop.yarn.server.resourcemanager.scheduler.capacity.CapacityScheduler: Allocation proposal accepted
2017-11-01 19:44:27,915 INFO org.apache.hadoop.yarn.server.resourcemanager.scheduler.capacity.allocator.AbstractContainerAllocator: assignedContainer application attempt=appattempt_1509585476261_0005_000001 container=null queue=org.apache.hadoop.yarn.server.resourcemanager.scheduler.capacity.allocator.RegularContainerAllocator@168e6449 clusterResource=<memory:24576, vCores:24> type=NODE_LOCAL requestedPartition=
2017-11-01 19:44:27,915 INFO org.apache.hadoop.yarn.server.resourcemanager.scheduler.capacity.ParentQueue: assignedContainer queue=root usedCapacity=0.125 absoluteUsedCapacity=0.125 used=<memory:3072, vCores:2> cluster=<memory:24576, vCores:24>
2017-11-01 19:44:27,915 INFO org.apache.hadoop.yarn.server.resourcemanager.rmcontainer.RMContainerImpl: container_1509585476261_0005_01_000003 Container Transitioned from NEW to ALLOCATED
2017-11-01 19:44:27,915 INFO org.apache.hadoop.yarn.server.resourcemanager.scheduler.common.fica.FiCaSchedulerNode: Assigned container container_1509585476261_0005_01_000003 of capacity <memory:1024, vCores:1> on host c220g1-031119.wisc.cloudlab.us:38777, which has 2 containers, <memory:2048, vCores:2> used and <memory:6144, vCores:6> available after allocation
2017-11-01 19:44:27,915 INFO org.apache.hadoop.yarn.server.resourcemanager.RMAuditLogger: USER=wentingt	OPERATION=AM Allocated Container	TARGET=SchedulerApp	RESULT=SUCCESS	APPID=application_1509585476261_0005	CONTAINERID=container_1509585476261_0005_01_000003	RESOURCE=<memory:1024, vCores:1>
2017-11-01 19:44:27,916 INFO org.apache.hadoop.yarn.server.resourcemanager.scheduler.capacity.ParentQueue: assignedContainer queue=root usedCapacity=0.16666667 absoluteUsedCapacity=0.16666667 used=<memory:4096, vCores:3> cluster=<memory:24576, vCores:24>
2017-11-01 19:44:27,916 INFO org.apache.hadoop.yarn.server.resourcemanager.scheduler.capacity.CapacityScheduler: Allocation proposal accepted
2017-11-01 19:44:27,916 INFO org.apache.hadoop.yarn.server.resourcemanager.scheduler.capacity.allocator.AbstractContainerAllocator: assignedContainer application attempt=appattempt_1509585476261_0005_000001 container=null queue=org.apache.hadoop.yarn.server.resourcemanager.scheduler.capacity.allocator.RegularContainerAllocator@168e6449 clusterResource=<memory:24576, vCores:24> type=NODE_LOCAL requestedPartition=
2017-11-01 19:44:27,916 INFO org.apache.hadoop.yarn.server.resourcemanager.scheduler.capacity.ParentQueue: assignedContainer queue=root usedCapacity=0.16666667 absoluteUsedCapacity=0.16666667 used=<memory:4096, vCores:3> cluster=<memory:24576, vCores:24>
2017-11-01 19:44:27,917 INFO org.apache.hadoop.yarn.server.resourcemanager.rmcontainer.RMContainerImpl: container_1509585476261_0005_01_000004 Container Transitioned from NEW to ALLOCATED
2017-11-01 19:44:27,917 INFO org.apache.hadoop.yarn.server.resourcemanager.scheduler.common.fica.FiCaSchedulerNode: Assigned container container_1509585476261_0005_01_000004 of capacity <memory:1024, vCores:1> on host c220g1-031119.wisc.cloudlab.us:38777, which has 3 containers, <memory:3072, vCores:3> used and <memory:5120, vCores:5> available after allocation
2017-11-01 19:44:27,917 INFO org.apache.hadoop.yarn.server.resourcemanager.RMAuditLogger: USER=wentingt	OPERATION=AM Allocated Container	TARGET=SchedulerApp	RESULT=SUCCESS	APPID=application_1509585476261_0005	CONTAINERID=container_1509585476261_0005_01_000004	RESOURCE=<memory:1024, vCores:1>
2017-11-01 19:44:27,917 INFO org.apache.hadoop.yarn.server.resourcemanager.scheduler.capacity.ParentQueue: assignedContainer queue=root usedCapacity=0.20833333 absoluteUsedCapacity=0.20833333 used=<memory:5120, vCores:4> cluster=<memory:24576, vCores:24>
2017-11-01 19:44:27,917 INFO org.apache.hadoop.yarn.server.resourcemanager.scheduler.capacity.CapacityScheduler: Allocation proposal accepted
2017-11-01 19:44:28,775 INFO org.apache.hadoop.yarn.server.resourcemanager.security.NMTokenSecretManagerInRM: Sending NMToken for nodeId : c220g1-031119.wisc.cloudlab.us:38777 for container : container_1509585476261_0005_01_000002
2017-11-01 19:44:28,776 INFO org.apache.hadoop.yarn.server.resourcemanager.rmcontainer.RMContainerImpl: container_1509585476261_0005_01_000002 Container Transitioned from ALLOCATED to ACQUIRED
2017-11-01 19:44:28,777 INFO org.apache.hadoop.yarn.server.resourcemanager.rmcontainer.RMContainerImpl: container_1509585476261_0005_01_000003 Container Transitioned from ALLOCATED to ACQUIRED
2017-11-01 19:44:28,778 INFO org.apache.hadoop.yarn.server.resourcemanager.rmcontainer.RMContainerImpl: container_1509585476261_0005_01_000004 Container Transitioned from ALLOCATED to ACQUIRED
2017-11-01 19:44:29,802 INFO org.apache.hadoop.yarn.server.resourcemanager.scheduler.AppSchedulingInfo: checking for deactivate of application :application_1509585476261_0005
2017-11-01 19:44:29,915 INFO org.apache.hadoop.yarn.server.resourcemanager.rmcontainer.RMContainerImpl: container_1509585476261_0005_01_000002 Container Transitioned from ACQUIRED to RUNNING
2017-11-01 19:44:29,915 INFO org.apache.hadoop.yarn.server.resourcemanager.rmcontainer.RMContainerImpl: container_1509585476261_0005_01_000003 Container Transitioned from ACQUIRED to RUNNING
2017-11-01 19:44:29,916 INFO org.apache.hadoop.yarn.server.resourcemanager.rmcontainer.RMContainerImpl: container_1509585476261_0005_01_000004 Container Transitioned from ACQUIRED to RUNNING
2017-11-01 19:44:32,644 INFO org.apache.hadoop.yarn.server.resourcemanager.rmcontainer.RMContainerImpl: container_1509585476261_0005_01_000003 Container Transitioned from RUNNING to COMPLETED
2017-11-01 19:44:32,644 INFO org.apache.hadoop.yarn.server.resourcemanager.RMAuditLogger: USER=wentingt	OPERATION=AM Released Container	TARGET=SchedulerApp	RESULT=SUCCESS	APPID=application_1509585476261_0005	CONTAINERID=container_1509585476261_0005_01_000003	RESOURCE=<memory:1024, vCores:1>
2017-11-01 19:44:32,662 INFO org.apache.hadoop.yarn.server.resourcemanager.rmcontainer.RMContainerImpl: container_1509585476261_0005_01_000002 Container Transitioned from RUNNING to COMPLETED
2017-11-01 19:44:32,662 INFO org.apache.hadoop.yarn.server.resourcemanager.RMAuditLogger: USER=wentingt	OPERATION=AM Released Container	TARGET=SchedulerApp	RESULT=SUCCESS	APPID=application_1509585476261_0005	CONTAINERID=container_1509585476261_0005_01_000002	RESOURCE=<memory:1024, vCores:1>
2017-11-01 19:44:32,709 INFO org.apache.hadoop.yarn.server.resourcemanager.rmcontainer.RMContainerImpl: container_1509585476261_0005_01_000004 Container Transitioned from RUNNING to COMPLETED
2017-11-01 19:44:32,709 INFO org.apache.hadoop.yarn.server.resourcemanager.RMAuditLogger: USER=wentingt	OPERATION=AM Released Container	TARGET=SchedulerApp	RESULT=SUCCESS	APPID=application_1509585476261_0005	CONTAINERID=container_1509585476261_0005_01_000004	RESOURCE=<memory:1024, vCores:1>
2017-11-01 19:44:34,535 INFO org.apache.hadoop.yarn.server.resourcemanager.scheduler.capacity.allocator.AbstractContainerAllocator: assignedContainer application attempt=appattempt_1509585476261_0005_000001 container=null queue=org.apache.hadoop.yarn.server.resourcemanager.scheduler.capacity.allocator.RegularContainerAllocator@168e6449 clusterResource=<memory:24576, vCores:24> type=OFF_SWITCH requestedPartition=
2017-11-01 19:44:34,536 INFO org.apache.hadoop.yarn.server.resourcemanager.scheduler.capacity.ParentQueue: assignedContainer queue=root usedCapacity=0.083333336 absoluteUsedCapacity=0.083333336 used=<memory:2048, vCores:1> cluster=<memory:24576, vCores:24>
2017-11-01 19:44:34,536 INFO org.apache.hadoop.yarn.server.resourcemanager.rmcontainer.RMContainerImpl: container_1509585476261_0005_01_000005 Container Transitioned from NEW to ALLOCATED
2017-11-01 19:44:34,536 INFO org.apache.hadoop.yarn.server.resourcemanager.scheduler.common.fica.FiCaSchedulerNode: Assigned container container_1509585476261_0005_01_000005 of capacity <memory:1024, vCores:1> on host c220g1-031118.wisc.cloudlab.us:33290, which has 2 containers, <memory:3072, vCores:2> used and <memory:5120, vCores:6> available after allocation
2017-11-01 19:44:34,536 INFO org.apache.hadoop.yarn.server.resourcemanager.RMAuditLogger: USER=wentingt	OPERATION=AM Allocated Container	TARGET=SchedulerApp	RESULT=SUCCESS	APPID=application_1509585476261_0005	CONTAINERID=container_1509585476261_0005_01_000005	RESOURCE=<memory:1024, vCores:1>
2017-11-01 19:44:34,536 INFO org.apache.hadoop.yarn.server.resourcemanager.scheduler.capacity.ParentQueue: assignedContainer queue=root usedCapacity=0.125 absoluteUsedCapacity=0.125 used=<memory:3072, vCores:2> cluster=<memory:24576, vCores:24>
2017-11-01 19:44:34,536 INFO org.apache.hadoop.yarn.server.resourcemanager.scheduler.capacity.CapacityScheduler: Allocation proposal accepted
2017-11-01 19:44:34,827 INFO org.apache.hadoop.yarn.server.resourcemanager.security.NMTokenSecretManagerInRM: Sending NMToken for nodeId : c220g1-031118.wisc.cloudlab.us:33290 for container : container_1509585476261_0005_01_000005
2017-11-01 19:44:34,828 INFO org.apache.hadoop.yarn.server.resourcemanager.rmcontainer.RMContainerImpl: container_1509585476261_0005_01_000005 Container Transitioned from ALLOCATED to ACQUIRED
2017-11-01 19:44:35,536 INFO org.apache.hadoop.yarn.server.resourcemanager.rmcontainer.RMContainerImpl: container_1509585476261_0005_01_000005 Container Transitioned from ACQUIRED to RUNNING
2017-11-01 19:44:35,832 INFO org.apache.hadoop.yarn.server.resourcemanager.scheduler.AppSchedulingInfo: checking for deactivate of application :application_1509585476261_0005
2017-11-01 19:44:38,768 INFO org.apache.hadoop.yarn.server.resourcemanager.rmapp.attempt.RMAppAttemptImpl: Updating application attempt appattempt_1509585476261_0005_000001 with final state: FINISHING, and exit status: -1000
2017-11-01 19:44:38,768 INFO org.apache.hadoop.yarn.server.resourcemanager.rmapp.attempt.RMAppAttemptImpl: appattempt_1509585476261_0005_000001 State change from RUNNING to FINAL_SAVING on event = UNREGISTERED
2017-11-01 19:44:38,768 INFO org.apache.hadoop.yarn.server.resourcemanager.rmapp.RMAppImpl: Updating application application_1509585476261_0005 with final state: FINISHING
2017-11-01 19:44:38,768 INFO org.apache.hadoop.yarn.server.resourcemanager.recovery.RMStateStore: Updating info for app: application_1509585476261_0005
2017-11-01 19:44:38,768 INFO org.apache.hadoop.yarn.server.resourcemanager.rmapp.RMAppImpl: application_1509585476261_0005 State change from RUNNING to FINAL_SAVING on event = ATTEMPT_UNREGISTERED
2017-11-01 19:44:38,769 INFO org.apache.hadoop.yarn.server.resourcemanager.rmapp.attempt.RMAppAttemptImpl: appattempt_1509585476261_0005_000001 State change from FINAL_SAVING to FINISHING on event = ATTEMPT_UPDATE_SAVED
2017-11-01 19:44:38,769 INFO org.apache.hadoop.yarn.server.resourcemanager.rmapp.RMAppImpl: application_1509585476261_0005 State change from FINAL_SAVING to FINISHING on event = APP_UPDATE_SAVED
2017-11-01 19:44:38,785 INFO org.apache.hadoop.yarn.server.resourcemanager.rmcontainer.RMContainerImpl: container_1509585476261_0005_01_000005 Container Transitioned from RUNNING to COMPLETED
2017-11-01 19:44:38,786 INFO org.apache.hadoop.yarn.server.resourcemanager.RMAuditLogger: USER=wentingt	OPERATION=AM Released Container	TARGET=SchedulerApp	RESULT=SUCCESS	APPID=application_1509585476261_0005	CONTAINERID=container_1509585476261_0005_01_000005	RESOURCE=<memory:1024, vCores:1>
2017-11-01 19:44:39,769 INFO org.apache.hadoop.yarn.server.resourcemanager.ApplicationMasterService: application_1509585476261_0005 unregistered successfully. 
2017-11-01 19:44:45,184 INFO org.apache.hadoop.yarn.server.resourcemanager.rmcontainer.RMContainerImpl: container_1509585476261_0005_01_000001 Container Transitioned from RUNNING to COMPLETED
2017-11-01 19:44:45,184 INFO org.apache.hadoop.yarn.server.resourcemanager.ApplicationMasterService: Unregistering app attempt : appattempt_1509585476261_0005_000001
2017-11-01 19:44:45,184 INFO org.apache.hadoop.yarn.server.resourcemanager.RMAuditLogger: USER=wentingt	OPERATION=AM Released Container	TARGET=SchedulerApp	RESULT=SUCCESS	APPID=application_1509585476261_0005	CONTAINERID=container_1509585476261_0005_01_000001	RESOURCE=<memory:2048, vCores:1>
2017-11-01 19:44:45,184 INFO org.apache.hadoop.yarn.server.resourcemanager.security.AMRMTokenSecretManager: Application finished, removing password for appattempt_1509585476261_0005_000001
2017-11-01 19:44:45,184 INFO org.apache.hadoop.yarn.server.resourcemanager.rmapp.attempt.RMAppAttemptImpl: appattempt_1509585476261_0005_000001 State change from FINISHING to FINISHED on event = CONTAINER_FINISHED
2017-11-01 19:44:45,185 INFO org.apache.hadoop.yarn.server.resourcemanager.rmapp.RMAppImpl: application_1509585476261_0005 State change from FINISHING to FINISHED on event = ATTEMPT_FINISHED
2017-11-01 19:44:45,185 INFO org.apache.hadoop.yarn.server.resourcemanager.scheduler.capacity.CapacityScheduler: Application Attempt appattempt_1509585476261_0005_000001 is done. finalState=FINISHED
2017-11-01 19:44:45,185 INFO org.apache.hadoop.yarn.server.resourcemanager.RMAuditLogger: USER=wentingt	OPERATION=Application Finished - Succeeded	TARGET=RMAppManager	RESULT=SUCCESS	APPID=application_1509585476261_0005
2017-11-01 19:44:45,185 INFO org.apache.hadoop.yarn.server.resourcemanager.scheduler.AppSchedulingInfo: Application application_1509585476261_0005 requests cleared
2017-11-01 19:44:45,185 INFO org.apache.hadoop.yarn.server.resourcemanager.scheduler.capacity.LeafQueue: Application removed - appId: application_1509585476261_0005 user: wentingt queue: default #user-pending-applications: 0 #user-active-applications: 0 #queue-pending-applications: 0 #queue-active-applications: 0
2017-11-01 19:44:45,185 INFO org.apache.hadoop.yarn.server.resourcemanager.scheduler.capacity.ParentQueue: Application removed - appId: application_1509585476261_0005 user: wentingt leaf-queue of parent: root #applications: 0
2017-11-01 19:44:45,185 INFO org.apache.hadoop.yarn.server.resourcemanager.amlauncher.AMLauncher: Cleaning master appattempt_1509585476261_0005_000001
2017-11-01 19:44:45,186 INFO org.apache.hadoop.yarn.server.resourcemanager.RMAppManager$ApplicationSummary: appId=application_1509585476261_0005,name=QuasiMonteCarlo,user=wentingt,queue=default,state=FINISHED,trackingUrl=http://c220g1-031117.wisc.cloudlab.us:8088/proxy/application_1509585476261_0005/,appMasterHost=c220g1-031118.wisc.cloudlab.us,submitTime=1509587060900,startTime=1509587060901,finishTime=1509587078768,finalStatus=SUCCEEDED,memorySeconds=67438,vcoreSeconds=39,preemptedMemorySeconds=0,preemptedVcoreSeconds=0,preemptedAMContainers=0,preemptedNonAMContainers=0,preemptedResources=<memory:0\, vCores:0>,applicationType=MAPREDUCE
2017-11-01 19:59:09,494 INFO org.apache.hadoop.yarn.server.resourcemanager.ClientRMService: Allocated new applicationId: 6
2017-11-01 19:59:10,276 INFO org.apache.hadoop.yarn.server.resourcemanager.scheduler.capacity.CapacityScheduler: Application 'application_1509585476261_0006' is submitted without priority hence considering default queue/cluster priority: 0
2017-11-01 19:59:10,276 INFO org.apache.hadoop.yarn.server.resourcemanager.scheduler.capacity.CapacityScheduler: Priority '0' is acceptable in queue : default for application: application_1509585476261_0006
2017-11-01 19:59:10,277 INFO org.apache.hadoop.yarn.server.resourcemanager.ClientRMService: Application with id 6 submitted by user wentingt
2017-11-01 19:59:10,277 INFO org.apache.hadoop.yarn.server.resourcemanager.RMAuditLogger: USER=wentingt	IP=10.0.0.1	OPERATION=Submit Application Request	TARGET=ClientRMService	RESULT=SUCCESS	APPID=application_1509585476261_0006	CALLERCONTEXT=CLI
2017-11-01 19:59:10,277 INFO org.apache.hadoop.yarn.server.resourcemanager.rmapp.RMAppImpl: Storing application with id application_1509585476261_0006
2017-11-01 19:59:10,278 INFO org.apache.hadoop.yarn.server.resourcemanager.rmapp.RMAppImpl: application_1509585476261_0006 State change from NEW to NEW_SAVING on event = START
2017-11-01 19:59:10,278 INFO org.apache.hadoop.yarn.server.resourcemanager.recovery.RMStateStore: Storing info for app: application_1509585476261_0006
2017-11-01 19:59:10,278 INFO org.apache.hadoop.yarn.server.resourcemanager.rmapp.RMAppImpl: application_1509585476261_0006 State change from NEW_SAVING to SUBMITTED on event = APP_NEW_SAVED
2017-11-01 19:59:10,278 INFO org.apache.hadoop.yarn.server.resourcemanager.scheduler.capacity.ParentQueue: Application added - appId: application_1509585476261_0006 user: wentingt leaf-queue of parent: root #applications: 1
2017-11-01 19:59:10,278 INFO org.apache.hadoop.yarn.server.resourcemanager.scheduler.capacity.CapacityScheduler: Accepted application application_1509585476261_0006 from user: wentingt, in queue: default
2017-11-01 19:59:10,281 INFO org.apache.hadoop.yarn.server.resourcemanager.rmapp.RMAppImpl: application_1509585476261_0006 State change from SUBMITTED to ACCEPTED on event = APP_ACCEPTED
2017-11-01 19:59:10,281 INFO org.apache.hadoop.yarn.server.resourcemanager.ApplicationMasterService: Registering app attempt : appattempt_1509585476261_0006_000001
2017-11-01 19:59:10,281 INFO org.apache.hadoop.yarn.server.resourcemanager.rmapp.attempt.RMAppAttemptImpl: appattempt_1509585476261_0006_000001 State change from NEW to SUBMITTED on event = START
2017-11-01 19:59:10,281 INFO org.apache.hadoop.yarn.server.resourcemanager.scheduler.capacity.LeafQueue: Application application_1509585476261_0006 from user: wentingt activated in queue: default
2017-11-01 19:59:10,281 INFO org.apache.hadoop.yarn.server.resourcemanager.scheduler.capacity.LeafQueue: Application added - appId: application_1509585476261_0006 user: wentingt, leaf-queue: default #user-pending-applications: 0 #user-active-applications: 1 #queue-pending-applications: 0 #queue-active-applications: 1
2017-11-01 19:59:10,281 INFO org.apache.hadoop.yarn.server.resourcemanager.scheduler.capacity.CapacityScheduler: Added Application Attempt appattempt_1509585476261_0006_000001 to scheduler from user wentingt in queue default
2017-11-01 19:59:10,282 INFO org.apache.hadoop.yarn.server.resourcemanager.rmapp.attempt.RMAppAttemptImpl: appattempt_1509585476261_0006_000001 State change from SUBMITTED to SCHEDULED on event = ATTEMPT_ADDED
2017-11-01 19:59:10,481 INFO org.apache.hadoop.yarn.server.resourcemanager.scheduler.capacity.allocator.AbstractContainerAllocator: assignedContainer application attempt=appattempt_1509585476261_0006_000001 container=null queue=org.apache.hadoop.yarn.server.resourcemanager.scheduler.capacity.allocator.RegularContainerAllocator@5d11a263 clusterResource=<memory:24576, vCores:24> type=OFF_SWITCH requestedPartition=
2017-11-01 19:59:10,481 INFO org.apache.hadoop.yarn.server.resourcemanager.scheduler.capacity.ParentQueue: assignedContainer queue=root usedCapacity=0.0 absoluteUsedCapacity=0.0 used=<memory:0, vCores:0> cluster=<memory:24576, vCores:24>
2017-11-01 19:59:10,481 INFO org.apache.hadoop.yarn.server.resourcemanager.rmcontainer.RMContainerImpl: container_1509585476261_0006_01_000001 Container Transitioned from NEW to ALLOCATED
2017-11-01 19:59:10,481 INFO org.apache.hadoop.yarn.server.resourcemanager.scheduler.common.fica.FiCaSchedulerNode: Assigned container container_1509585476261_0006_01_000001 of capacity <memory:2048, vCores:1> on host c220g1-031119.wisc.cloudlab.us:38777, which has 1 containers, <memory:2048, vCores:1> used and <memory:6144, vCores:7> available after allocation
2017-11-01 19:59:10,481 INFO org.apache.hadoop.yarn.server.resourcemanager.RMAuditLogger: USER=wentingt	OPERATION=AM Allocated Container	TARGET=SchedulerApp	RESULT=SUCCESS	APPID=application_1509585476261_0006	CONTAINERID=container_1509585476261_0006_01_000001	RESOURCE=<memory:2048, vCores:1>
2017-11-01 19:59:10,482 INFO org.apache.hadoop.yarn.server.resourcemanager.security.NMTokenSecretManagerInRM: Sending NMToken for nodeId : c220g1-031119.wisc.cloudlab.us:38777 for container : container_1509585476261_0006_01_000001
2017-11-01 19:59:10,483 INFO org.apache.hadoop.yarn.server.resourcemanager.rmcontainer.RMContainerImpl: container_1509585476261_0006_01_000001 Container Transitioned from ALLOCATED to ACQUIRED
2017-11-01 19:59:10,484 INFO org.apache.hadoop.yarn.server.resourcemanager.security.NMTokenSecretManagerInRM: Clear node set for appattempt_1509585476261_0006_000001
2017-11-01 19:59:10,484 INFO org.apache.hadoop.yarn.server.resourcemanager.rmapp.attempt.RMAppAttemptImpl: Storing attempt: AppId: application_1509585476261_0006 AttemptId: appattempt_1509585476261_0006_000001 MasterContainer: Container: [ContainerId: container_1509585476261_0006_01_000001, AllocationRequestId: 0, Version: 0, NodeId: c220g1-031119.wisc.cloudlab.us:38777, NodeHttpAddress: c220g1-031119.wisc.cloudlab.us:8042, Resource: <memory:2048, vCores:1>, Priority: 0, Token: Token { kind: ContainerToken, service: 128.104.222.29:38777 }, ExecutionType: GUARANTEED, ]
2017-11-01 19:59:10,484 INFO org.apache.hadoop.yarn.server.resourcemanager.scheduler.capacity.ParentQueue: assignedContainer queue=root usedCapacity=0.083333336 absoluteUsedCapacity=0.083333336 used=<memory:2048, vCores:1> cluster=<memory:24576, vCores:24>
2017-11-01 19:59:10,484 INFO org.apache.hadoop.yarn.server.resourcemanager.scheduler.capacity.CapacityScheduler: Allocation proposal accepted
2017-11-01 19:59:10,484 INFO org.apache.hadoop.yarn.server.resourcemanager.rmapp.attempt.RMAppAttemptImpl: appattempt_1509585476261_0006_000001 State change from SCHEDULED to ALLOCATED_SAVING on event = CONTAINER_ALLOCATED
2017-11-01 19:59:10,485 INFO org.apache.hadoop.yarn.server.resourcemanager.rmapp.attempt.RMAppAttemptImpl: appattempt_1509585476261_0006_000001 State change from ALLOCATED_SAVING to ALLOCATED on event = ATTEMPT_NEW_SAVED
2017-11-01 19:59:10,486 INFO org.apache.hadoop.yarn.server.resourcemanager.amlauncher.AMLauncher: Launching masterappattempt_1509585476261_0006_000001
2017-11-01 19:59:10,489 INFO org.apache.hadoop.yarn.server.resourcemanager.amlauncher.AMLauncher: Setting up container Container: [ContainerId: container_1509585476261_0006_01_000001, AllocationRequestId: 0, Version: 0, NodeId: c220g1-031119.wisc.cloudlab.us:38777, NodeHttpAddress: c220g1-031119.wisc.cloudlab.us:8042, Resource: <memory:2048, vCores:1>, Priority: 0, Token: Token { kind: ContainerToken, service: 128.104.222.29:38777 }, ExecutionType: GUARANTEED, ] for AM appattempt_1509585476261_0006_000001
2017-11-01 19:59:10,489 INFO org.apache.hadoop.yarn.server.resourcemanager.security.AMRMTokenSecretManager: Create AMRMToken for ApplicationAttempt: appattempt_1509585476261_0006_000001
2017-11-01 19:59:10,489 INFO org.apache.hadoop.yarn.server.resourcemanager.security.AMRMTokenSecretManager: Creating password for appattempt_1509585476261_0006_000001
2017-11-01 19:59:10,515 INFO org.apache.hadoop.yarn.server.resourcemanager.amlauncher.AMLauncher: Done launching container Container: [ContainerId: container_1509585476261_0006_01_000001, AllocationRequestId: 0, Version: 0, NodeId: c220g1-031119.wisc.cloudlab.us:38777, NodeHttpAddress: c220g1-031119.wisc.cloudlab.us:8042, Resource: <memory:2048, vCores:1>, Priority: 0, Token: Token { kind: ContainerToken, service: 128.104.222.29:38777 }, ExecutionType: GUARANTEED, ] for AM appattempt_1509585476261_0006_000001
2017-11-01 19:59:10,515 INFO org.apache.hadoop.yarn.server.resourcemanager.rmapp.attempt.RMAppAttemptImpl: appattempt_1509585476261_0006_000001 State change from ALLOCATED to LAUNCHED on event = LAUNCHED
2017-11-01 19:59:11,482 INFO org.apache.hadoop.yarn.server.resourcemanager.rmcontainer.RMContainerImpl: container_1509585476261_0006_01_000001 Container Transitioned from ACQUIRED to RUNNING
2017-11-01 19:59:15,634 INFO SecurityLogger.org.apache.hadoop.ipc.Server: Auth successful for appattempt_1509585476261_0006_000001 (auth:SIMPLE)
2017-11-01 19:59:15,640 INFO org.apache.hadoop.yarn.server.resourcemanager.DefaultAMSProcessor: AM registration appattempt_1509585476261_0006_000001
2017-11-01 19:59:15,640 INFO org.apache.hadoop.yarn.server.resourcemanager.RMAuditLogger: USER=wentingt	IP=10.0.0.4	OPERATION=Register App Master	TARGET=ApplicationMasterService	RESULT=SUCCESS	APPID=application_1509585476261_0006	APPATTEMPTID=appattempt_1509585476261_0006_000001
2017-11-01 19:59:15,640 INFO org.apache.hadoop.yarn.server.resourcemanager.rmapp.attempt.RMAppAttemptImpl: appattempt_1509585476261_0006_000001 State change from LAUNCHED to RUNNING on event = REGISTERED
2017-11-01 19:59:15,640 INFO org.apache.hadoop.yarn.server.resourcemanager.rmapp.RMAppImpl: application_1509585476261_0006 State change from ACCEPTED to RUNNING on event = ATTEMPT_REGISTERED
2017-11-01 19:59:16,969 INFO org.apache.hadoop.yarn.server.resourcemanager.scheduler.capacity.allocator.AbstractContainerAllocator: assignedContainer application attempt=appattempt_1509585476261_0006_000001 container=null queue=org.apache.hadoop.yarn.server.resourcemanager.scheduler.capacity.allocator.RegularContainerAllocator@5d11a263 clusterResource=<memory:24576, vCores:24> type=NODE_LOCAL requestedPartition=
2017-11-01 19:59:16,969 INFO org.apache.hadoop.yarn.server.resourcemanager.scheduler.capacity.ParentQueue: assignedContainer queue=root usedCapacity=0.083333336 absoluteUsedCapacity=0.083333336 used=<memory:2048, vCores:1> cluster=<memory:24576, vCores:24>
2017-11-01 19:59:16,969 INFO org.apache.hadoop.yarn.server.resourcemanager.rmcontainer.RMContainerImpl: container_1509585476261_0006_01_000002 Container Transitioned from NEW to ALLOCATED
2017-11-01 19:59:16,969 INFO org.apache.hadoop.yarn.server.resourcemanager.scheduler.common.fica.FiCaSchedulerNode: Assigned container container_1509585476261_0006_01_000002 of capacity <memory:1024, vCores:1> on host c220g1-031118.wisc.cloudlab.us:33290, which has 1 containers, <memory:1024, vCores:1> used and <memory:7168, vCores:7> available after allocation
2017-11-01 19:59:16,970 INFO org.apache.hadoop.yarn.server.resourcemanager.RMAuditLogger: USER=wentingt	OPERATION=AM Allocated Container	TARGET=SchedulerApp	RESULT=SUCCESS	APPID=application_1509585476261_0006	CONTAINERID=container_1509585476261_0006_01_000002	RESOURCE=<memory:1024, vCores:1>
2017-11-01 19:59:16,970 INFO org.apache.hadoop.yarn.server.resourcemanager.scheduler.capacity.ParentQueue: assignedContainer queue=root usedCapacity=0.125 absoluteUsedCapacity=0.125 used=<memory:3072, vCores:2> cluster=<memory:24576, vCores:24>
2017-11-01 19:59:16,970 INFO org.apache.hadoop.yarn.server.resourcemanager.scheduler.capacity.CapacityScheduler: Allocation proposal accepted
2017-11-01 19:59:16,970 INFO org.apache.hadoop.yarn.server.resourcemanager.scheduler.capacity.allocator.AbstractContainerAllocator: assignedContainer application attempt=appattempt_1509585476261_0006_000001 container=null queue=org.apache.hadoop.yarn.server.resourcemanager.scheduler.capacity.allocator.RegularContainerAllocator@5d11a263 clusterResource=<memory:24576, vCores:24> type=NODE_LOCAL requestedPartition=
2017-11-01 19:59:16,970 INFO org.apache.hadoop.yarn.server.resourcemanager.scheduler.capacity.ParentQueue: assignedContainer queue=root usedCapacity=0.125 absoluteUsedCapacity=0.125 used=<memory:3072, vCores:2> cluster=<memory:24576, vCores:24>
2017-11-01 19:59:16,971 INFO org.apache.hadoop.yarn.server.resourcemanager.rmcontainer.RMContainerImpl: container_1509585476261_0006_01_000003 Container Transitioned from NEW to ALLOCATED
2017-11-01 19:59:16,971 INFO org.apache.hadoop.yarn.server.resourcemanager.scheduler.common.fica.FiCaSchedulerNode: Assigned container container_1509585476261_0006_01_000003 of capacity <memory:1024, vCores:1> on host c220g1-031118.wisc.cloudlab.us:33290, which has 2 containers, <memory:2048, vCores:2> used and <memory:6144, vCores:6> available after allocation
2017-11-01 19:59:16,971 INFO org.apache.hadoop.yarn.server.resourcemanager.RMAuditLogger: USER=wentingt	OPERATION=AM Allocated Container	TARGET=SchedulerApp	RESULT=SUCCESS	APPID=application_1509585476261_0006	CONTAINERID=container_1509585476261_0006_01_000003	RESOURCE=<memory:1024, vCores:1>
2017-11-01 19:59:16,971 INFO org.apache.hadoop.yarn.server.resourcemanager.scheduler.capacity.ParentQueue: assignedContainer queue=root usedCapacity=0.16666667 absoluteUsedCapacity=0.16666667 used=<memory:4096, vCores:3> cluster=<memory:24576, vCores:24>
2017-11-01 19:59:16,971 INFO org.apache.hadoop.yarn.server.resourcemanager.scheduler.capacity.CapacityScheduler: Allocation proposal accepted
2017-11-01 19:59:16,971 INFO org.apache.hadoop.yarn.server.resourcemanager.scheduler.capacity.allocator.AbstractContainerAllocator: assignedContainer application attempt=appattempt_1509585476261_0006_000001 container=null queue=org.apache.hadoop.yarn.server.resourcemanager.scheduler.capacity.allocator.RegularContainerAllocator@5d11a263 clusterResource=<memory:24576, vCores:24> type=NODE_LOCAL requestedPartition=
2017-11-01 19:59:16,971 INFO org.apache.hadoop.yarn.server.resourcemanager.scheduler.capacity.ParentQueue: assignedContainer queue=root usedCapacity=0.16666667 absoluteUsedCapacity=0.16666667 used=<memory:4096, vCores:3> cluster=<memory:24576, vCores:24>
2017-11-01 19:59:16,972 INFO org.apache.hadoop.yarn.server.resourcemanager.rmcontainer.RMContainerImpl: container_1509585476261_0006_01_000004 Container Transitioned from NEW to ALLOCATED
2017-11-01 19:59:16,972 INFO org.apache.hadoop.yarn.server.resourcemanager.scheduler.common.fica.FiCaSchedulerNode: Assigned container container_1509585476261_0006_01_000004 of capacity <memory:1024, vCores:1> on host c220g1-031118.wisc.cloudlab.us:33290, which has 3 containers, <memory:3072, vCores:3> used and <memory:5120, vCores:5> available after allocation
2017-11-01 19:59:16,972 INFO org.apache.hadoop.yarn.server.resourcemanager.RMAuditLogger: USER=wentingt	OPERATION=AM Allocated Container	TARGET=SchedulerApp	RESULT=SUCCESS	APPID=application_1509585476261_0006	CONTAINERID=container_1509585476261_0006_01_000004	RESOURCE=<memory:1024, vCores:1>
2017-11-01 19:59:16,973 INFO org.apache.hadoop.yarn.server.resourcemanager.scheduler.capacity.ParentQueue: assignedContainer queue=root usedCapacity=0.20833333 absoluteUsedCapacity=0.20833333 used=<memory:5120, vCores:4> cluster=<memory:24576, vCores:24>
2017-11-01 19:59:16,973 INFO org.apache.hadoop.yarn.server.resourcemanager.scheduler.capacity.CapacityScheduler: Allocation proposal accepted
2017-11-01 19:59:17,722 INFO org.apache.hadoop.yarn.server.resourcemanager.security.NMTokenSecretManagerInRM: Sending NMToken for nodeId : c220g1-031118.wisc.cloudlab.us:33290 for container : container_1509585476261_0006_01_000002
2017-11-01 19:59:17,723 INFO org.apache.hadoop.yarn.server.resourcemanager.rmcontainer.RMContainerImpl: container_1509585476261_0006_01_000002 Container Transitioned from ALLOCATED to ACQUIRED
2017-11-01 19:59:17,725 INFO org.apache.hadoop.yarn.server.resourcemanager.rmcontainer.RMContainerImpl: container_1509585476261_0006_01_000003 Container Transitioned from ALLOCATED to ACQUIRED
2017-11-01 19:59:17,727 INFO org.apache.hadoop.yarn.server.resourcemanager.rmcontainer.RMContainerImpl: container_1509585476261_0006_01_000004 Container Transitioned from ALLOCATED to ACQUIRED
2017-11-01 19:59:18,750 INFO org.apache.hadoop.yarn.server.resourcemanager.scheduler.AppSchedulingInfo: checking for deactivate of application :application_1509585476261_0006
2017-11-01 19:59:18,970 INFO org.apache.hadoop.yarn.server.resourcemanager.rmcontainer.RMContainerImpl: container_1509585476261_0006_01_000002 Container Transitioned from ACQUIRED to RUNNING
2017-11-01 19:59:18,971 INFO org.apache.hadoop.yarn.server.resourcemanager.rmcontainer.RMContainerImpl: container_1509585476261_0006_01_000003 Container Transitioned from ACQUIRED to RUNNING
2017-11-01 19:59:18,972 INFO org.apache.hadoop.yarn.server.resourcemanager.rmcontainer.RMContainerImpl: container_1509585476261_0006_01_000004 Container Transitioned from ACQUIRED to RUNNING
2017-11-01 19:59:21,406 INFO org.apache.hadoop.yarn.server.resourcemanager.rmcontainer.RMContainerImpl: container_1509585476261_0006_01_000004 Container Transitioned from RUNNING to COMPLETED
2017-11-01 19:59:21,406 INFO org.apache.hadoop.yarn.server.resourcemanager.RMAuditLogger: USER=wentingt	OPERATION=AM Released Container	TARGET=SchedulerApp	RESULT=SUCCESS	APPID=application_1509585476261_0006	CONTAINERID=container_1509585476261_0006_01_000004	RESOURCE=<memory:1024, vCores:1>
2017-11-01 19:59:21,422 INFO org.apache.hadoop.yarn.server.resourcemanager.rmcontainer.RMContainerImpl: container_1509585476261_0006_01_000003 Container Transitioned from RUNNING to COMPLETED
2017-11-01 19:59:21,422 INFO org.apache.hadoop.yarn.server.resourcemanager.RMAuditLogger: USER=wentingt	OPERATION=AM Released Container	TARGET=SchedulerApp	RESULT=SUCCESS	APPID=application_1509585476261_0006	CONTAINERID=container_1509585476261_0006_01_000003	RESOURCE=<memory:1024, vCores:1>
2017-11-01 19:59:21,506 INFO org.apache.hadoop.yarn.server.resourcemanager.rmcontainer.RMContainerImpl: container_1509585476261_0006_01_000002 Container Transitioned from RUNNING to COMPLETED
2017-11-01 19:59:21,506 INFO org.apache.hadoop.yarn.server.resourcemanager.RMAuditLogger: USER=wentingt	OPERATION=AM Released Container	TARGET=SchedulerApp	RESULT=SUCCESS	APPID=application_1509585476261_0006	CONTAINERID=container_1509585476261_0006_01_000002	RESOURCE=<memory:1024, vCores:1>
2017-11-01 19:59:23,498 INFO org.apache.hadoop.yarn.server.resourcemanager.scheduler.capacity.allocator.AbstractContainerAllocator: assignedContainer application attempt=appattempt_1509585476261_0006_000001 container=null queue=org.apache.hadoop.yarn.server.resourcemanager.scheduler.capacity.allocator.RegularContainerAllocator@5d11a263 clusterResource=<memory:24576, vCores:24> type=OFF_SWITCH requestedPartition=
2017-11-01 19:59:23,498 INFO org.apache.hadoop.yarn.server.resourcemanager.scheduler.capacity.ParentQueue: assignedContainer queue=root usedCapacity=0.083333336 absoluteUsedCapacity=0.083333336 used=<memory:2048, vCores:1> cluster=<memory:24576, vCores:24>
2017-11-01 19:59:23,498 INFO org.apache.hadoop.yarn.server.resourcemanager.rmcontainer.RMContainerImpl: container_1509585476261_0006_01_000005 Container Transitioned from NEW to ALLOCATED
2017-11-01 19:59:23,498 INFO org.apache.hadoop.yarn.server.resourcemanager.scheduler.common.fica.FiCaSchedulerNode: Assigned container container_1509585476261_0006_01_000005 of capacity <memory:1024, vCores:1> on host c220g1-031119.wisc.cloudlab.us:38777, which has 2 containers, <memory:3072, vCores:2> used and <memory:5120, vCores:6> available after allocation
2017-11-01 19:59:23,498 INFO org.apache.hadoop.yarn.server.resourcemanager.RMAuditLogger: USER=wentingt	OPERATION=AM Allocated Container	TARGET=SchedulerApp	RESULT=SUCCESS	APPID=application_1509585476261_0006	CONTAINERID=container_1509585476261_0006_01_000005	RESOURCE=<memory:1024, vCores:1>
2017-11-01 19:59:23,499 INFO org.apache.hadoop.yarn.server.resourcemanager.scheduler.capacity.ParentQueue: assignedContainer queue=root usedCapacity=0.125 absoluteUsedCapacity=0.125 used=<memory:3072, vCores:2> cluster=<memory:24576, vCores:24>
2017-11-01 19:59:23,499 INFO org.apache.hadoop.yarn.server.resourcemanager.scheduler.capacity.CapacityScheduler: Allocation proposal accepted
2017-11-01 19:59:23,775 INFO org.apache.hadoop.yarn.server.resourcemanager.security.NMTokenSecretManagerInRM: Sending NMToken for nodeId : c220g1-031119.wisc.cloudlab.us:38777 for container : container_1509585476261_0006_01_000005
2017-11-01 19:59:23,776 INFO org.apache.hadoop.yarn.server.resourcemanager.rmcontainer.RMContainerImpl: container_1509585476261_0006_01_000005 Container Transitioned from ALLOCATED to ACQUIRED
2017-11-01 19:59:24,499 INFO org.apache.hadoop.yarn.server.resourcemanager.rmcontainer.RMContainerImpl: container_1509585476261_0006_01_000005 Container Transitioned from ACQUIRED to RUNNING
2017-11-01 19:59:24,780 INFO org.apache.hadoop.yarn.server.resourcemanager.scheduler.AppSchedulingInfo: checking for deactivate of application :application_1509585476261_0006
2017-11-01 19:59:27,678 INFO org.apache.hadoop.yarn.server.resourcemanager.rmapp.attempt.RMAppAttemptImpl: Updating application attempt appattempt_1509585476261_0006_000001 with final state: FINISHING, and exit status: -1000
2017-11-01 19:59:27,678 INFO org.apache.hadoop.yarn.server.resourcemanager.rmapp.attempt.RMAppAttemptImpl: appattempt_1509585476261_0006_000001 State change from RUNNING to FINAL_SAVING on event = UNREGISTERED
2017-11-01 19:59:27,678 INFO org.apache.hadoop.yarn.server.resourcemanager.rmapp.RMAppImpl: Updating application application_1509585476261_0006 with final state: FINISHING
2017-11-01 19:59:27,678 INFO org.apache.hadoop.yarn.server.resourcemanager.recovery.RMStateStore: Updating info for app: application_1509585476261_0006
2017-11-01 19:59:27,678 INFO org.apache.hadoop.yarn.server.resourcemanager.rmapp.RMAppImpl: application_1509585476261_0006 State change from RUNNING to FINAL_SAVING on event = ATTEMPT_UNREGISTERED
2017-11-01 19:59:27,679 INFO org.apache.hadoop.yarn.server.resourcemanager.rmapp.attempt.RMAppAttemptImpl: appattempt_1509585476261_0006_000001 State change from FINAL_SAVING to FINISHING on event = ATTEMPT_UPDATE_SAVED
2017-11-01 19:59:27,679 INFO org.apache.hadoop.yarn.server.resourcemanager.rmapp.RMAppImpl: application_1509585476261_0006 State change from FINAL_SAVING to FINISHING on event = APP_UPDATE_SAVED
2017-11-01 19:59:27,697 INFO org.apache.hadoop.yarn.server.resourcemanager.rmcontainer.RMContainerImpl: container_1509585476261_0006_01_000005 Container Transitioned from RUNNING to COMPLETED
2017-11-01 19:59:27,697 INFO org.apache.hadoop.yarn.server.resourcemanager.RMAuditLogger: USER=wentingt	OPERATION=AM Released Container	TARGET=SchedulerApp	RESULT=SUCCESS	APPID=application_1509585476261_0006	CONTAINERID=container_1509585476261_0006_01_000005	RESOURCE=<memory:1024, vCores:1>
2017-11-01 19:59:28,680 INFO org.apache.hadoop.yarn.server.resourcemanager.ApplicationMasterService: application_1509585476261_0006 unregistered successfully. 
2017-11-01 19:59:34,095 INFO org.apache.hadoop.yarn.server.resourcemanager.rmcontainer.RMContainerImpl: container_1509585476261_0006_01_000001 Container Transitioned from RUNNING to COMPLETED
2017-11-01 19:59:34,095 INFO org.apache.hadoop.yarn.server.resourcemanager.RMAuditLogger: USER=wentingt	OPERATION=AM Released Container	TARGET=SchedulerApp	RESULT=SUCCESS	APPID=application_1509585476261_0006	CONTAINERID=container_1509585476261_0006_01_000001	RESOURCE=<memory:2048, vCores:1>
2017-11-01 19:59:34,095 INFO org.apache.hadoop.yarn.server.resourcemanager.ApplicationMasterService: Unregistering app attempt : appattempt_1509585476261_0006_000001
2017-11-01 19:59:34,095 INFO org.apache.hadoop.yarn.server.resourcemanager.security.AMRMTokenSecretManager: Application finished, removing password for appattempt_1509585476261_0006_000001
2017-11-01 19:59:34,095 INFO org.apache.hadoop.yarn.server.resourcemanager.rmapp.attempt.RMAppAttemptImpl: appattempt_1509585476261_0006_000001 State change from FINISHING to FINISHED on event = CONTAINER_FINISHED
2017-11-01 19:59:34,096 INFO org.apache.hadoop.yarn.server.resourcemanager.rmapp.RMAppImpl: application_1509585476261_0006 State change from FINISHING to FINISHED on event = ATTEMPT_FINISHED
2017-11-01 19:59:34,096 INFO org.apache.hadoop.yarn.server.resourcemanager.scheduler.capacity.CapacityScheduler: Application Attempt appattempt_1509585476261_0006_000001 is done. finalState=FINISHED
2017-11-01 19:59:34,096 INFO org.apache.hadoop.yarn.server.resourcemanager.RMAuditLogger: USER=wentingt	OPERATION=Application Finished - Succeeded	TARGET=RMAppManager	RESULT=SUCCESS	APPID=application_1509585476261_0006
2017-11-01 19:59:34,096 INFO org.apache.hadoop.yarn.server.resourcemanager.scheduler.AppSchedulingInfo: Application application_1509585476261_0006 requests cleared
2017-11-01 19:59:34,096 INFO org.apache.hadoop.yarn.server.resourcemanager.scheduler.capacity.LeafQueue: Application removed - appId: application_1509585476261_0006 user: wentingt queue: default #user-pending-applications: 0 #user-active-applications: 0 #queue-pending-applications: 0 #queue-active-applications: 0
2017-11-01 19:59:34,096 INFO org.apache.hadoop.yarn.server.resourcemanager.scheduler.capacity.ParentQueue: Application removed - appId: application_1509585476261_0006 user: wentingt leaf-queue of parent: root #applications: 0
2017-11-01 19:59:34,096 INFO org.apache.hadoop.yarn.server.resourcemanager.amlauncher.AMLauncher: Cleaning master appattempt_1509585476261_0006_000001
2017-11-01 19:59:34,096 INFO org.apache.hadoop.yarn.server.resourcemanager.RMAppManager$ApplicationSummary: appId=application_1509585476261_0006,name=QuasiMonteCarlo,user=wentingt,queue=default,state=FINISHED,trackingUrl=http://c220g1-031117.wisc.cloudlab.us:8088/proxy/application_1509585476261_0006/,appMasterHost=c220g1-031119.wisc.cloudlab.us,submitTime=1509587950276,startTime=1509587950276,finishTime=1509587967678,finalStatus=SUCCEEDED,memorySeconds=66406,vcoreSeconds=39,preemptedMemorySeconds=0,preemptedVcoreSeconds=0,preemptedAMContainers=0,preemptedNonAMContainers=0,preemptedResources=<memory:0\, vCores:0>,applicationType=MAPREDUCE
