2017-11-01 12:17:06,869 INFO org.apache.hadoop.yarn.server.resourcemanager.ResourceManager: STARTUP_MSG: 
/************************************************************
STARTUP_MSG: Starting ResourceManager
STARTUP_MSG:   host = c220g1-030817.wisc.cloudlab.us/128.104.222.47
STARTUP_MSG:   args = []
STARTUP_MSG:   version = 3.0.0-beta1
STARTUP_MSG:   build = https://github.com/wentingt/hadoop-3.0.0-beta1-src.git -r a2ea8361bab4f0655d274025c59f1f00d491d526; compiled by 'wentingt' on 2017-11-01T18:05Z
STARTUP_MSG:   java = 1.8.0_131
************************************************************/
2017-11-01 12:17:06,880 INFO org.apache.hadoop.yarn.server.resourcemanager.ResourceManager: registered UNIX signal handlers for [TERM, HUP, INT]
2017-11-01 12:17:07,046 INFO org.apache.hadoop.conf.Configuration: found resource core-site.xml at file:/users/wentingt/hadoop-3.0.0-beta1-src/hadoop-dist/target/hadoop-3.0.0-beta1/etc/hadoop/core-site.xml
2017-11-01 12:17:07,077 WARN org.apache.hadoop.util.NativeCodeLoader: Unable to load native-hadoop library for your platform... using builtin-java classes where applicable
2017-11-01 12:17:07,104 INFO org.apache.hadoop.security.Groups: clearing userToGroupsMap cache
2017-11-01 12:17:07,149 INFO org.apache.hadoop.conf.Configuration: found resource yarn-site.xml at file:/users/wentingt/hadoop-3.0.0-beta1-src/hadoop-dist/target/hadoop-3.0.0-beta1/etc/hadoop/yarn-site.xml
2017-11-01 12:17:07,247 INFO org.apache.hadoop.yarn.event.AsyncDispatcher: Registering class org.apache.hadoop.yarn.server.resourcemanager.RMFatalEventType for class org.apache.hadoop.yarn.server.resourcemanager.ResourceManager$RMFatalEventDispatcher
2017-11-01 12:17:07,398 INFO org.apache.hadoop.yarn.server.resourcemanager.security.NMTokenSecretManagerInRM: NMTokenKeyRollingInterval: 86400000ms and NMTokenKeyActivationDelay: 900000ms
2017-11-01 12:17:07,405 INFO org.apache.hadoop.yarn.server.resourcemanager.security.RMContainerTokenSecretManager: ContainerTokenKeyRollingInterval: 86400000ms and ContainerTokenKeyActivationDelay: 900000ms
2017-11-01 12:17:07,433 INFO org.apache.hadoop.yarn.server.resourcemanager.security.AMRMTokenSecretManager: AMRMTokenKeyRollingInterval: 86400000ms and AMRMTokenKeyActivationDelay: 900000 ms
2017-11-01 12:17:07,487 INFO org.apache.hadoop.yarn.event.AsyncDispatcher: Registering class org.apache.hadoop.yarn.server.resourcemanager.recovery.RMStateStoreEventType for class org.apache.hadoop.yarn.server.resourcemanager.recovery.RMStateStore$ForwardingEventHandler
2017-11-01 12:17:07,492 INFO org.apache.hadoop.yarn.event.AsyncDispatcher: Registering class org.apache.hadoop.yarn.server.resourcemanager.NodesListManagerEventType for class org.apache.hadoop.yarn.server.resourcemanager.NodesListManager
2017-11-01 12:17:07,492 INFO org.apache.hadoop.yarn.server.resourcemanager.ResourceManager: Using Scheduler: org.apache.hadoop.yarn.server.resourcemanager.scheduler.capacity.CapacityScheduler
2017-11-01 12:17:07,524 INFO org.apache.hadoop.yarn.event.AsyncDispatcher: Registering class org.apache.hadoop.yarn.server.resourcemanager.scheduler.event.SchedulerEventType for class org.apache.hadoop.yarn.event.EventDispatcher
2017-11-01 12:17:07,525 INFO org.apache.hadoop.yarn.event.AsyncDispatcher: Registering class org.apache.hadoop.yarn.server.resourcemanager.rmapp.RMAppEventType for class org.apache.hadoop.yarn.server.resourcemanager.ResourceManager$ApplicationEventDispatcher
2017-11-01 12:17:07,526 INFO org.apache.hadoop.yarn.event.AsyncDispatcher: Registering class org.apache.hadoop.yarn.server.resourcemanager.rmapp.attempt.RMAppAttemptEventType for class org.apache.hadoop.yarn.server.resourcemanager.ResourceManager$ApplicationAttemptEventDispatcher
2017-11-01 12:17:07,527 INFO org.apache.hadoop.yarn.event.AsyncDispatcher: Registering class org.apache.hadoop.yarn.server.resourcemanager.rmnode.RMNodeEventType for class org.apache.hadoop.yarn.server.resourcemanager.ResourceManager$NodeEventDispatcher
2017-11-01 12:17:07,657 INFO org.apache.commons.beanutils.FluentPropertyBeanIntrospector: Error when creating PropertyDescriptor for public final void org.apache.commons.configuration2.AbstractConfiguration.setProperty(java.lang.String,java.lang.Object)! Ignoring this property.
2017-11-01 12:17:07,693 INFO org.apache.hadoop.metrics2.impl.MetricsConfig: loaded properties from hadoop-metrics2.properties
2017-11-01 12:17:07,751 INFO org.apache.hadoop.metrics2.impl.MetricsSystemImpl: Scheduled Metric snapshot period at 10 second(s).
2017-11-01 12:17:07,751 INFO org.apache.hadoop.metrics2.impl.MetricsSystemImpl: ResourceManager metrics system started
2017-11-01 12:17:07,775 INFO org.apache.hadoop.yarn.security.YarnAuthorizationProvider: org.apache.hadoop.yarn.security.ConfiguredYarnAuthorizer is instantiated.
2017-11-01 12:17:07,780 INFO org.apache.hadoop.yarn.event.AsyncDispatcher: Registering class org.apache.hadoop.yarn.server.resourcemanager.RMAppManagerEventType for class org.apache.hadoop.yarn.server.resourcemanager.RMAppManager
2017-11-01 12:17:07,793 INFO org.apache.hadoop.yarn.event.AsyncDispatcher: Registering class org.apache.hadoop.yarn.server.resourcemanager.amlauncher.AMLauncherEventType for class org.apache.hadoop.yarn.server.resourcemanager.amlauncher.ApplicationMasterLauncher
2017-11-01 12:17:07,796 INFO org.apache.hadoop.yarn.server.resourcemanager.RMNMInfo: Registered RMNMInfo MBean
2017-11-01 12:17:07,796 INFO org.apache.hadoop.yarn.server.resourcemanager.rmapp.monitor.RMAppLifetimeMonitor: Application lifelime monitor interval set to 3000 ms.
2017-11-01 12:17:07,807 INFO org.apache.hadoop.util.HostsFileReader: Refreshing hosts (include/exclude) list
2017-11-01 12:17:07,817 INFO org.apache.hadoop.conf.Configuration: found resource capacity-scheduler.xml at file:/users/wentingt/hadoop-3.0.0-beta1-src/hadoop-dist/target/hadoop-3.0.0-beta1/etc/hadoop/capacity-scheduler.xml
2017-11-01 12:17:07,885 INFO org.apache.hadoop.yarn.server.resourcemanager.scheduler.capacity.CapacitySchedulerConfiguration: max alloc mb per queue for root is undefined
2017-11-01 12:17:07,885 INFO org.apache.hadoop.yarn.server.resourcemanager.scheduler.capacity.CapacitySchedulerConfiguration: max alloc vcore per queue for root is undefined
2017-11-01 12:17:07,904 INFO org.apache.hadoop.yarn.server.resourcemanager.scheduler.capacity.ParentQueue: root, capacity=1.0, absoluteCapacity=1.0, maxCapacity=1.0, absoluteMaxCapacity=1.0, state=RUNNING, acls=ADMINISTER_QUEUE:*SUBMIT_APP:*, labels=*,
, reservationsContinueLooking=true, orderingPolicy=utilization, priority=0
2017-11-01 12:17:07,904 INFO org.apache.hadoop.yarn.server.resourcemanager.scheduler.capacity.ParentQueue: Initialized parent-queue root name=root, fullname=root
2017-11-01 12:17:07,923 INFO org.apache.hadoop.yarn.server.resourcemanager.scheduler.capacity.CapacitySchedulerConfiguration: max alloc mb per queue for root.default is undefined
2017-11-01 12:17:07,923 INFO org.apache.hadoop.yarn.server.resourcemanager.scheduler.capacity.CapacitySchedulerConfiguration: max alloc vcore per queue for root.default is undefined
2017-11-01 12:17:07,926 INFO org.apache.hadoop.yarn.server.resourcemanager.scheduler.capacity.LeafQueue: Initializing default
capacity = 1.0 [= (float) configuredCapacity / 100 ]
absoluteCapacity = 1.0 [= parentAbsoluteCapacity * capacity ]
maxCapacity = 1.0 [= configuredMaxCapacity ]
absoluteMaxCapacity = 1.0 [= 1.0 maximumCapacity undefined, (parentAbsoluteMaxCapacity * maximumCapacity) / 100 otherwise ]
userLimit = 100 [= configuredUserLimit ]
userLimitFactor = 1.0 [= configuredUserLimitFactor ]
maxApplications = 10000 [= configuredMaximumSystemApplicationsPerQueue or (int)(configuredMaximumSystemApplications * absoluteCapacity)]
maxApplicationsPerUser = 10000 [= (int)(maxApplications * (userLimit / 100.0f) * userLimitFactor) ]
usedCapacity = 0.0 [= usedResourcesMemory / (clusterResourceMemory * absoluteCapacity)]
absoluteUsedCapacity = 0.0 [= usedResourcesMemory / clusterResourceMemory]
maxAMResourcePerQueuePercent = 0.1 [= configuredMaximumAMResourcePercent ]
minimumAllocationFactor = 0.875 [= (float)(maximumAllocationMemory - minimumAllocationMemory) / maximumAllocationMemory ]
maximumAllocation = <memory:8192, vCores:4> [= configuredMaxAllocation ]
numContainers = 0 [= currentNumContainers ]
state = RUNNING [= configuredState ]
acls = ADMINISTER_QUEUE:*SUBMIT_APP:* [= configuredAcls ]
nodeLocalityDelay = 40
rackLocalityAdditionalDelay = -1
labels=*,
reservationsContinueLooking = true
preemptionDisabled = true
defaultAppPriorityPerQueue = 0
priority = 0
maxLifetime = -1 seconds
defaultLifetime = -1 seconds
2017-11-01 12:17:07,926 INFO org.apache.hadoop.yarn.server.resourcemanager.scheduler.capacity.CapacitySchedulerQueueManager: Initialized queue: default: capacity=1.0, absoluteCapacity=1.0, usedResources=<memory:0, vCores:0>, usedCapacity=0.0, absoluteUsedCapacity=0.0, numApps=0, numContainers=0
2017-11-01 12:17:07,926 INFO org.apache.hadoop.yarn.server.resourcemanager.scheduler.capacity.CapacitySchedulerQueueManager: Initialized queue: root: numChildQueue= 1, capacity=1.0, absoluteCapacity=1.0, usedResources=<memory:0, vCores:0>usedCapacity=0.0, numApps=0, numContainers=0
2017-11-01 12:17:07,928 INFO org.apache.hadoop.yarn.server.resourcemanager.scheduler.capacity.CapacitySchedulerQueueManager: Initialized root queue root: numChildQueue= 1, capacity=1.0, absoluteCapacity=1.0, usedResources=<memory:0, vCores:0>usedCapacity=0.0, numApps=0, numContainers=0
2017-11-01 12:17:07,928 INFO org.apache.hadoop.yarn.server.resourcemanager.scheduler.capacity.CapacityScheduler: Initialized queue mappings, override: false
2017-11-01 12:17:07,929 INFO org.apache.hadoop.yarn.server.resourcemanager.scheduler.capacity.CapacityScheduler: Initialized CapacityScheduler with calculator=class org.apache.hadoop.yarn.util.resource.DefaultResourceCalculator, minimumAllocation=<<memory:1024, vCores:1>>, maximumAllocation=<<memory:8192, vCores:4>>, asynchronousScheduling=false, asyncScheduleInterval=5ms
2017-11-01 12:17:07,932 INFO org.apache.hadoop.conf.Configuration: dynamic-resources.xml not found
2017-11-01 12:17:07,934 INFO org.apache.hadoop.yarn.server.resourcemanager.AMSProcessingChain: Initializing AMS Processing chain. Root Processor=[org.apache.hadoop.yarn.server.resourcemanager.DefaultAMSProcessor].
2017-11-01 12:17:07,942 INFO org.apache.hadoop.yarn.server.resourcemanager.ResourceManager: TimelineServicePublisher is not configured
2017-11-01 12:17:07,943 INFO org.apache.hadoop.yarn.server.resourcemanager.ResourceManager: Transitioning to active state
2017-11-01 12:17:07,973 INFO org.apache.hadoop.yarn.server.resourcemanager.recovery.RMStateStore: Updating AMRMToken
2017-11-01 12:17:07,973 INFO org.apache.hadoop.yarn.server.resourcemanager.security.RMContainerTokenSecretManager: Rolling master-key for container-tokens
2017-11-01 12:17:07,973 INFO org.apache.hadoop.yarn.server.resourcemanager.security.NMTokenSecretManagerInRM: Rolling master-key for nm-tokens
2017-11-01 12:17:07,973 INFO org.apache.hadoop.security.token.delegation.AbstractDelegationTokenSecretManager: Updating the current master key for generating delegation tokens
2017-11-01 12:17:07,974 INFO org.apache.hadoop.yarn.server.resourcemanager.security.RMDelegationTokenSecretManager: storing master key with keyID 1
2017-11-01 12:17:07,974 INFO org.apache.hadoop.yarn.server.resourcemanager.recovery.RMStateStore: Storing RMDTMasterKey.
2017-11-01 12:17:07,977 INFO org.apache.hadoop.security.token.delegation.AbstractDelegationTokenSecretManager: Starting expired delegation token remover thread, tokenRemoverScanInterval=60 min(s)
2017-11-01 12:17:07,977 INFO org.apache.hadoop.security.token.delegation.AbstractDelegationTokenSecretManager: Updating the current master key for generating delegation tokens
2017-11-01 12:17:07,977 INFO org.apache.hadoop.yarn.server.resourcemanager.security.RMDelegationTokenSecretManager: storing master key with keyID 2
2017-11-01 12:17:07,977 INFO org.apache.hadoop.yarn.server.resourcemanager.recovery.RMStateStore: Storing RMDTMasterKey.
2017-11-01 12:17:07,981 INFO org.apache.hadoop.yarn.event.AsyncDispatcher: Registering class org.apache.hadoop.yarn.nodelabels.event.NodeLabelsStoreEventType for class org.apache.hadoop.yarn.nodelabels.CommonNodeLabelsManager$ForwardingEventHandler
2017-11-01 12:17:08,032 INFO org.apache.hadoop.ipc.CallQueueManager: Using callQueue: class java.util.concurrent.LinkedBlockingQueue queueCapacity: 5000 scheduler: class org.apache.hadoop.ipc.DefaultRpcScheduler
2017-11-01 12:17:08,049 INFO org.apache.hadoop.ipc.Server: Starting Socket Reader #1 for port 8031
2017-11-01 12:17:08,254 INFO org.apache.hadoop.yarn.factories.impl.pb.RpcServerFactoryPBImpl: Adding protocol org.apache.hadoop.yarn.server.api.ResourceTrackerPB to the server
2017-11-01 12:17:08,255 INFO org.apache.hadoop.ipc.Server: IPC Server Responder: starting
2017-11-01 12:17:08,256 INFO org.apache.hadoop.ipc.Server: IPC Server listener on 8031: starting
2017-11-01 12:17:08,394 INFO org.apache.hadoop.util.JvmPauseMonitor: Starting JVM pause monitor
2017-11-01 12:17:08,405 INFO org.apache.hadoop.ipc.CallQueueManager: Using callQueue: class java.util.concurrent.LinkedBlockingQueue queueCapacity: 5000 scheduler: class org.apache.hadoop.ipc.DefaultRpcScheduler
2017-11-01 12:17:08,412 INFO org.apache.hadoop.ipc.Server: Starting Socket Reader #1 for port 8030
2017-11-01 12:17:08,425 INFO org.apache.hadoop.yarn.factories.impl.pb.RpcServerFactoryPBImpl: Adding protocol org.apache.hadoop.yarn.api.ApplicationMasterProtocolPB to the server
2017-11-01 12:17:08,425 INFO org.apache.hadoop.ipc.Server: IPC Server Responder: starting
2017-11-01 12:17:08,425 INFO org.apache.hadoop.ipc.Server: IPC Server listener on 8030: starting
2017-11-01 12:17:08,503 INFO org.apache.hadoop.ipc.CallQueueManager: Using callQueue: class java.util.concurrent.LinkedBlockingQueue queueCapacity: 5000 scheduler: class org.apache.hadoop.ipc.DefaultRpcScheduler
2017-11-01 12:17:08,503 INFO org.apache.hadoop.ipc.Server: Starting Socket Reader #1 for port 8032
2017-11-01 12:17:08,506 INFO org.apache.hadoop.yarn.factories.impl.pb.RpcServerFactoryPBImpl: Adding protocol org.apache.hadoop.yarn.api.ApplicationClientProtocolPB to the server
2017-11-01 12:17:08,506 INFO org.apache.hadoop.ipc.Server: IPC Server Responder: starting
2017-11-01 12:17:08,506 INFO org.apache.hadoop.ipc.Server: IPC Server listener on 8032: starting
2017-11-01 12:17:08,512 INFO org.apache.hadoop.yarn.server.resourcemanager.ResourceManager: Transitioned to active state
2017-11-01 12:17:08,556 INFO org.eclipse.jetty.util.log: Logging initialized @2185ms
2017-11-01 12:17:08,630 INFO org.apache.hadoop.security.authentication.server.AuthenticationFilter: Unable to initialize FileSignerSecretProvider, falling back to use random secrets.
2017-11-01 12:17:08,634 INFO org.apache.hadoop.http.HttpRequestLog: Http request log for http.requests.resourcemanager is not defined
2017-11-01 12:17:08,642 INFO org.apache.hadoop.http.HttpServer2: Added global filter 'safety' (class=org.apache.hadoop.http.HttpServer2$QuotingInputFilter)
2017-11-01 12:17:08,646 INFO org.apache.hadoop.http.HttpServer2: Added filter RMAuthenticationFilter (class=org.apache.hadoop.yarn.server.security.http.RMAuthenticationFilter) to context cluster
2017-11-01 12:17:08,647 INFO org.apache.hadoop.http.HttpServer2: Added filter RMAuthenticationFilter (class=org.apache.hadoop.yarn.server.security.http.RMAuthenticationFilter) to context static
2017-11-01 12:17:08,647 INFO org.apache.hadoop.http.HttpServer2: Added filter RMAuthenticationFilter (class=org.apache.hadoop.yarn.server.security.http.RMAuthenticationFilter) to context logs
2017-11-01 12:17:08,647 INFO org.apache.hadoop.http.HttpServer2: Added filter static_user_filter (class=org.apache.hadoop.http.lib.StaticUserWebFilter$StaticUserFilter) to context cluster
2017-11-01 12:17:08,647 INFO org.apache.hadoop.http.HttpServer2: Added filter static_user_filter (class=org.apache.hadoop.http.lib.StaticUserWebFilter$StaticUserFilter) to context static
2017-11-01 12:17:08,647 INFO org.apache.hadoop.http.HttpServer2: Added filter static_user_filter (class=org.apache.hadoop.http.lib.StaticUserWebFilter$StaticUserFilter) to context logs
2017-11-01 12:17:08,649 INFO org.apache.hadoop.http.HttpServer2: adding path spec: /cluster/*
2017-11-01 12:17:08,649 INFO org.apache.hadoop.http.HttpServer2: adding path spec: /ws/*
2017-11-01 12:17:09,085 INFO org.apache.hadoop.yarn.webapp.WebApps: Registered webapp guice modules
2017-11-01 12:17:09,087 INFO org.apache.hadoop.http.HttpServer2: Jetty bound to port 8088
2017-11-01 12:17:09,089 INFO org.eclipse.jetty.server.Server: jetty-9.3.19.v20170502
2017-11-01 12:17:09,139 INFO org.apache.hadoop.security.authentication.server.AuthenticationFilter: Unable to initialize FileSignerSecretProvider, falling back to use random secrets.
2017-11-01 12:17:09,153 INFO org.apache.hadoop.security.token.delegation.AbstractDelegationTokenSecretManager: Updating the current master key for generating delegation tokens
2017-11-01 12:17:09,153 INFO org.apache.hadoop.security.token.delegation.AbstractDelegationTokenSecretManager: Starting expired delegation token remover thread, tokenRemoverScanInterval=60 min(s)
2017-11-01 12:17:09,153 INFO org.apache.hadoop.security.token.delegation.AbstractDelegationTokenSecretManager: Updating the current master key for generating delegation tokens
2017-11-01 12:17:09,156 INFO org.eclipse.jetty.server.handler.ContextHandler: Started o.e.j.s.ServletContextHandler@4ba534b0{/logs,file:///users/wentingt/hadoop-3.0.0-beta1-src/hadoop-dist/target/hadoop-3.0.0-beta1/logs/,AVAILABLE}
2017-11-01 12:17:09,157 INFO org.eclipse.jetty.server.handler.ContextHandler: Started o.e.j.s.ServletContextHandler@4e517165{/static,jar:file:/users/wentingt/hadoop-3.0.0-beta1-src/hadoop-dist/target/hadoop-3.0.0-beta1/share/hadoop/yarn/hadoop-yarn-common-3.0.0-beta1.jar!/webapps/static,AVAILABLE}
2017-11-01 12:17:10,214 INFO org.eclipse.jetty.server.handler.ContextHandler: Started o.e.j.w.WebAppContext@77774571{/,file:///tmp/jetty-0.0.0.0-8088-cluster-_-any-3228770294242095007.dir/webapp/,AVAILABLE}{/cluster}
2017-11-01 12:17:10,218 INFO org.eclipse.jetty.server.AbstractConnector: Started ServerConnector@3bbf841e{HTTP/1.1,[http/1.1]}{0.0.0.0:8088}
2017-11-01 12:17:10,219 INFO org.eclipse.jetty.server.Server: Started @3849ms
2017-11-01 12:17:10,219 INFO org.apache.hadoop.yarn.webapp.WebApps: Web app cluster started at 8088
2017-11-01 12:17:10,266 INFO org.apache.hadoop.ipc.CallQueueManager: Using callQueue: class java.util.concurrent.LinkedBlockingQueue queueCapacity: 100 scheduler: class org.apache.hadoop.ipc.DefaultRpcScheduler
2017-11-01 12:17:10,268 INFO org.apache.hadoop.ipc.Server: Starting Socket Reader #1 for port 8033
2017-11-01 12:17:10,271 INFO org.apache.hadoop.yarn.factories.impl.pb.RpcServerFactoryPBImpl: Adding protocol org.apache.hadoop.yarn.server.api.ResourceManagerAdministrationProtocolPB to the server
2017-11-01 12:17:10,272 INFO org.apache.hadoop.ipc.Server: IPC Server Responder: starting
2017-11-01 12:17:10,272 INFO org.apache.hadoop.ipc.Server: IPC Server listener on 8033: starting
2017-11-01 12:17:13,131 INFO org.apache.hadoop.yarn.server.resourcemanager.ResourceTrackerService: NodeManager from node c220g1-030814.wisc.cloudlab.us(cmPort: 45451 httpPort: 8042) registered with capability: <memory:8192, vCores:8>, assigned nodeId c220g1-030814.wisc.cloudlab.us:45451
2017-11-01 12:17:13,131 INFO org.apache.hadoop.yarn.server.resourcemanager.ResourceTrackerService: NodeManager from node c220g1-030803.wisc.cloudlab.us(cmPort: 43522 httpPort: 8042) registered with capability: <memory:8192, vCores:8>, assigned nodeId c220g1-030803.wisc.cloudlab.us:43522
2017-11-01 12:17:13,140 INFO org.apache.hadoop.yarn.server.resourcemanager.rmnode.RMNodeImpl: c220g1-030814.wisc.cloudlab.us:45451 Node Transitioned from NEW to RUNNING
2017-11-01 12:17:13,140 INFO org.apache.hadoop.yarn.server.resourcemanager.rmnode.RMNodeImpl: c220g1-030803.wisc.cloudlab.us:43522 Node Transitioned from NEW to RUNNING
2017-11-01 12:17:13,149 INFO org.apache.hadoop.yarn.server.resourcemanager.scheduler.capacity.CapacityScheduler: Added node c220g1-030814.wisc.cloudlab.us:45451 clusterResource: <memory:8192, vCores:8>
2017-11-01 12:17:13,150 INFO org.apache.hadoop.yarn.server.resourcemanager.scheduler.capacity.CapacityScheduler: Added node c220g1-030803.wisc.cloudlab.us:43522 clusterResource: <memory:16384, vCores:16>
2017-11-01 12:19:09,133 INFO org.apache.hadoop.yarn.server.resourcemanager.ClientRMService: Allocated new applicationId: 1
2017-11-01 12:19:10,332 INFO org.apache.hadoop.yarn.server.resourcemanager.scheduler.capacity.CapacityScheduler: Application 'application_1509560227945_0001' is submitted without priority hence considering default queue/cluster priority: 0
2017-11-01 12:19:10,332 INFO org.apache.hadoop.yarn.server.resourcemanager.scheduler.capacity.CapacityScheduler: Priority '0' is acceptable in queue : default for application: application_1509560227945_0001
2017-11-01 12:19:10,364 INFO org.apache.hadoop.yarn.server.resourcemanager.ClientRMService: Application with id 1 submitted by user wentingt
2017-11-01 12:19:10,365 INFO org.apache.hadoop.yarn.server.resourcemanager.rmapp.RMAppImpl: Storing application with id application_1509560227945_0001
2017-11-01 12:19:10,367 INFO org.apache.hadoop.yarn.server.resourcemanager.RMAuditLogger: USER=wentingt	IP=10.0.0.3	OPERATION=Submit Application Request	TARGET=ClientRMService	RESULT=SUCCESS	APPID=application_1509560227945_0001	CALLERCONTEXT=CLI
2017-11-01 12:19:10,382 INFO org.apache.hadoop.yarn.server.resourcemanager.rmapp.RMAppImpl: application_1509560227945_0001 State change from NEW to NEW_SAVING on event = START
2017-11-01 12:19:10,382 INFO org.apache.hadoop.yarn.server.resourcemanager.recovery.RMStateStore: Storing info for app: application_1509560227945_0001
2017-11-01 12:19:10,384 INFO org.apache.hadoop.yarn.server.resourcemanager.rmapp.RMAppImpl: application_1509560227945_0001 State change from NEW_SAVING to SUBMITTED on event = APP_NEW_SAVED
2017-11-01 12:19:10,386 INFO org.apache.hadoop.yarn.server.resourcemanager.scheduler.capacity.ParentQueue: Application added - appId: application_1509560227945_0001 user: wentingt leaf-queue of parent: root #applications: 1
2017-11-01 12:19:10,387 INFO org.apache.hadoop.yarn.server.resourcemanager.scheduler.capacity.CapacityScheduler: Accepted application application_1509560227945_0001 from user: wentingt, in queue: default
2017-11-01 12:19:10,410 INFO org.apache.hadoop.yarn.server.resourcemanager.rmapp.RMAppImpl: application_1509560227945_0001 State change from SUBMITTED to ACCEPTED on event = APP_ACCEPTED
2017-11-01 12:19:10,454 INFO org.apache.hadoop.yarn.server.resourcemanager.ApplicationMasterService: Registering app attempt : appattempt_1509560227945_0001_000001
2017-11-01 12:19:10,455 INFO org.apache.hadoop.yarn.server.resourcemanager.rmapp.attempt.RMAppAttemptImpl: appattempt_1509560227945_0001_000001 State change from NEW to SUBMITTED on event = START
2017-11-01 12:19:10,490 INFO org.apache.hadoop.yarn.server.resourcemanager.scheduler.capacity.LeafQueue: Application application_1509560227945_0001 from user: wentingt activated in queue: default
2017-11-01 12:19:10,490 INFO org.apache.hadoop.yarn.server.resourcemanager.scheduler.capacity.LeafQueue: Application added - appId: application_1509560227945_0001 user: wentingt, leaf-queue: default #user-pending-applications: 0 #user-active-applications: 1 #queue-pending-applications: 0 #queue-active-applications: 1
2017-11-01 12:19:10,490 INFO org.apache.hadoop.yarn.server.resourcemanager.scheduler.capacity.CapacityScheduler: Added Application Attempt appattempt_1509560227945_0001_000001 to scheduler from user wentingt in queue default
2017-11-01 12:19:10,501 INFO org.apache.hadoop.yarn.server.resourcemanager.rmapp.attempt.RMAppAttemptImpl: appattempt_1509560227945_0001_000001 State change from SUBMITTED to SCHEDULED on event = ATTEMPT_ADDED
2017-11-01 12:19:10,562 INFO org.apache.hadoop.yarn.server.resourcemanager.scheduler.capacity.allocator.AbstractContainerAllocator: assignedContainer application attempt=appattempt_1509560227945_0001_000001 container=null queue=org.apache.hadoop.yarn.server.resourcemanager.scheduler.capacity.allocator.RegularContainerAllocator@28abdf93 clusterResource=<memory:16384, vCores:16> type=OFF_SWITCH requestedPartition=
2017-11-01 12:19:10,564 INFO org.apache.hadoop.yarn.server.resourcemanager.scheduler.capacity.ParentQueue: assignedContainer queue=root usedCapacity=0.0 absoluteUsedCapacity=0.0 used=<memory:0, vCores:0> cluster=<memory:16384, vCores:16>
2017-11-01 12:19:10,569 INFO org.apache.hadoop.yarn.server.resourcemanager.rmcontainer.RMContainerImpl: container_1509560227945_0001_01_000001 Container Transitioned from NEW to ALLOCATED
2017-11-01 12:19:10,570 INFO org.apache.hadoop.yarn.server.resourcemanager.scheduler.common.fica.FiCaSchedulerNode: Assigned container container_1509560227945_0001_01_000001 of capacity <memory:2048, vCores:1> on host c220g1-030814.wisc.cloudlab.us:45451, which has 1 containers, <memory:2048, vCores:1> used and <memory:6144, vCores:7> available after allocation
2017-11-01 12:19:10,570 INFO org.apache.hadoop.yarn.server.resourcemanager.RMAuditLogger: USER=wentingt	OPERATION=AM Allocated Container	TARGET=SchedulerApp	RESULT=SUCCESS	APPID=application_1509560227945_0001	CONTAINERID=container_1509560227945_0001_01_000001	RESOURCE=<memory:2048, vCores:1>
2017-11-01 12:19:10,599 INFO org.apache.hadoop.yarn.server.resourcemanager.security.NMTokenSecretManagerInRM: Sending NMToken for nodeId : c220g1-030814.wisc.cloudlab.us:45451 for container : container_1509560227945_0001_01_000001
2017-11-01 12:19:10,613 INFO org.apache.hadoop.yarn.server.resourcemanager.rmcontainer.RMContainerImpl: container_1509560227945_0001_01_000001 Container Transitioned from ALLOCATED to ACQUIRED
2017-11-01 12:19:10,614 INFO org.apache.hadoop.yarn.server.resourcemanager.security.NMTokenSecretManagerInRM: Clear node set for appattempt_1509560227945_0001_000001
2017-11-01 12:19:10,614 INFO org.apache.hadoop.yarn.server.resourcemanager.scheduler.capacity.ParentQueue: assignedContainer queue=root usedCapacity=0.125 absoluteUsedCapacity=0.125 used=<memory:2048, vCores:1> cluster=<memory:16384, vCores:16>
2017-11-01 12:19:10,614 INFO org.apache.hadoop.yarn.server.resourcemanager.rmapp.attempt.RMAppAttemptImpl: Storing attempt: AppId: application_1509560227945_0001 AttemptId: appattempt_1509560227945_0001_000001 MasterContainer: Container: [ContainerId: container_1509560227945_0001_01_000001, AllocationRequestId: 0, Version: 0, NodeId: c220g1-030814.wisc.cloudlab.us:45451, NodeHttpAddress: c220g1-030814.wisc.cloudlab.us:8042, Resource: <memory:2048, vCores:1>, Priority: 0, Token: Token { kind: ContainerToken, service: 128.104.222.44:45451 }, ExecutionType: GUARANTEED, ]
2017-11-01 12:19:10,614 INFO org.apache.hadoop.yarn.server.resourcemanager.scheduler.capacity.CapacityScheduler: Allocation proposal accepted
2017-11-01 12:19:10,640 INFO org.apache.hadoop.yarn.server.resourcemanager.rmapp.attempt.RMAppAttemptImpl: appattempt_1509560227945_0001_000001 State change from SCHEDULED to ALLOCATED_SAVING on event = CONTAINER_ALLOCATED
2017-11-01 12:19:10,650 INFO org.apache.hadoop.yarn.server.resourcemanager.rmapp.attempt.RMAppAttemptImpl: appattempt_1509560227945_0001_000001 State change from ALLOCATED_SAVING to ALLOCATED on event = ATTEMPT_NEW_SAVED
2017-11-01 12:19:10,654 INFO org.apache.hadoop.yarn.server.resourcemanager.amlauncher.AMLauncher: Launching masterappattempt_1509560227945_0001_000001
2017-11-01 12:19:10,712 INFO org.apache.hadoop.yarn.server.resourcemanager.amlauncher.AMLauncher: Setting up container Container: [ContainerId: container_1509560227945_0001_01_000001, AllocationRequestId: 0, Version: 0, NodeId: c220g1-030814.wisc.cloudlab.us:45451, NodeHttpAddress: c220g1-030814.wisc.cloudlab.us:8042, Resource: <memory:2048, vCores:1>, Priority: 0, Token: Token { kind: ContainerToken, service: 128.104.222.44:45451 }, ExecutionType: GUARANTEED, ] for AM appattempt_1509560227945_0001_000001
2017-11-01 12:19:10,714 INFO org.apache.hadoop.yarn.server.resourcemanager.security.AMRMTokenSecretManager: Create AMRMToken for ApplicationAttempt: appattempt_1509560227945_0001_000001
2017-11-01 12:19:10,717 INFO org.apache.hadoop.yarn.server.resourcemanager.security.AMRMTokenSecretManager: Creating password for appattempt_1509560227945_0001_000001
2017-11-01 12:19:11,344 INFO org.apache.hadoop.yarn.server.resourcemanager.amlauncher.AMLauncher: Done launching container Container: [ContainerId: container_1509560227945_0001_01_000001, AllocationRequestId: 0, Version: 0, NodeId: c220g1-030814.wisc.cloudlab.us:45451, NodeHttpAddress: c220g1-030814.wisc.cloudlab.us:8042, Resource: <memory:2048, vCores:1>, Priority: 0, Token: Token { kind: ContainerToken, service: 128.104.222.44:45451 }, ExecutionType: GUARANTEED, ] for AM appattempt_1509560227945_0001_000001
2017-11-01 12:19:11,345 INFO org.apache.hadoop.yarn.server.resourcemanager.rmapp.attempt.RMAppAttemptImpl: appattempt_1509560227945_0001_000001 State change from ALLOCATED to LAUNCHED on event = LAUNCHED
2017-11-01 12:19:11,559 INFO org.apache.hadoop.yarn.server.resourcemanager.rmcontainer.RMContainerImpl: container_1509560227945_0001_01_000001 Container Transitioned from ACQUIRED to RUNNING
2017-11-01 12:19:17,748 INFO SecurityLogger.org.apache.hadoop.ipc.Server: Auth successful for appattempt_1509560227945_0001_000001 (auth:SIMPLE)
2017-11-01 12:19:17,771 INFO org.apache.hadoop.yarn.server.resourcemanager.DefaultAMSProcessor: AM registration appattempt_1509560227945_0001_000001
2017-11-01 12:19:17,772 INFO org.apache.hadoop.yarn.server.resourcemanager.RMAuditLogger: USER=wentingt	IP=10.0.0.2	OPERATION=Register App Master	TARGET=ApplicationMasterService	RESULT=SUCCESS	APPID=application_1509560227945_0001	APPATTEMPTID=appattempt_1509560227945_0001_000001
2017-11-01 12:19:17,773 INFO org.apache.hadoop.yarn.server.resourcemanager.rmapp.attempt.RMAppAttemptImpl: appattempt_1509560227945_0001_000001 State change from LAUNCHED to RUNNING on event = REGISTERED
2017-11-01 12:19:17,773 INFO org.apache.hadoop.yarn.server.resourcemanager.rmapp.RMAppImpl: application_1509560227945_0001 State change from ACCEPTED to RUNNING on event = ATTEMPT_REGISTERED
2017-11-01 12:19:19,550 INFO org.apache.hadoop.yarn.server.resourcemanager.scheduler.capacity.allocator.AbstractContainerAllocator: assignedContainer application attempt=appattempt_1509560227945_0001_000001 container=null queue=org.apache.hadoop.yarn.server.resourcemanager.scheduler.capacity.allocator.RegularContainerAllocator@28abdf93 clusterResource=<memory:16384, vCores:16> type=NODE_LOCAL requestedPartition=
2017-11-01 12:19:19,551 INFO org.apache.hadoop.yarn.server.resourcemanager.scheduler.capacity.ParentQueue: assignedContainer queue=root usedCapacity=0.125 absoluteUsedCapacity=0.125 used=<memory:2048, vCores:1> cluster=<memory:16384, vCores:16>
2017-11-01 12:19:19,552 INFO org.apache.hadoop.yarn.server.resourcemanager.rmcontainer.RMContainerImpl: container_1509560227945_0001_01_000002 Container Transitioned from NEW to ALLOCATED
2017-11-01 12:19:19,552 INFO org.apache.hadoop.yarn.server.resourcemanager.scheduler.common.fica.FiCaSchedulerNode: Assigned container container_1509560227945_0001_01_000002 of capacity <memory:1024, vCores:1> on host c220g1-030803.wisc.cloudlab.us:43522, which has 1 containers, <memory:1024, vCores:1> used and <memory:7168, vCores:7> available after allocation
2017-11-01 12:19:19,552 INFO org.apache.hadoop.yarn.server.resourcemanager.RMAuditLogger: USER=wentingt	OPERATION=AM Allocated Container	TARGET=SchedulerApp	RESULT=SUCCESS	APPID=application_1509560227945_0001	CONTAINERID=container_1509560227945_0001_01_000002	RESOURCE=<memory:1024, vCores:1>
2017-11-01 12:19:19,552 INFO org.apache.hadoop.yarn.server.resourcemanager.scheduler.capacity.ParentQueue: assignedContainer queue=root usedCapacity=0.1875 absoluteUsedCapacity=0.1875 used=<memory:3072, vCores:2> cluster=<memory:16384, vCores:16>
2017-11-01 12:19:19,552 INFO org.apache.hadoop.yarn.server.resourcemanager.scheduler.capacity.CapacityScheduler: Allocation proposal accepted
2017-11-01 12:19:19,553 INFO org.apache.hadoop.yarn.server.resourcemanager.scheduler.capacity.allocator.AbstractContainerAllocator: assignedContainer application attempt=appattempt_1509560227945_0001_000001 container=null queue=org.apache.hadoop.yarn.server.resourcemanager.scheduler.capacity.allocator.RegularContainerAllocator@28abdf93 clusterResource=<memory:16384, vCores:16> type=NODE_LOCAL requestedPartition=
2017-11-01 12:19:19,553 INFO org.apache.hadoop.yarn.server.resourcemanager.scheduler.capacity.ParentQueue: assignedContainer queue=root usedCapacity=0.1875 absoluteUsedCapacity=0.1875 used=<memory:3072, vCores:2> cluster=<memory:16384, vCores:16>
2017-11-01 12:19:19,554 INFO org.apache.hadoop.yarn.server.resourcemanager.rmcontainer.RMContainerImpl: container_1509560227945_0001_01_000003 Container Transitioned from NEW to ALLOCATED
2017-11-01 12:19:19,554 INFO org.apache.hadoop.yarn.server.resourcemanager.scheduler.common.fica.FiCaSchedulerNode: Assigned container container_1509560227945_0001_01_000003 of capacity <memory:1024, vCores:1> on host c220g1-030803.wisc.cloudlab.us:43522, which has 2 containers, <memory:2048, vCores:2> used and <memory:6144, vCores:6> available after allocation
2017-11-01 12:19:19,554 INFO org.apache.hadoop.yarn.server.resourcemanager.RMAuditLogger: USER=wentingt	OPERATION=AM Allocated Container	TARGET=SchedulerApp	RESULT=SUCCESS	APPID=application_1509560227945_0001	CONTAINERID=container_1509560227945_0001_01_000003	RESOURCE=<memory:1024, vCores:1>
2017-11-01 12:19:19,554 INFO org.apache.hadoop.yarn.server.resourcemanager.scheduler.capacity.ParentQueue: assignedContainer queue=root usedCapacity=0.25 absoluteUsedCapacity=0.25 used=<memory:4096, vCores:3> cluster=<memory:16384, vCores:16>
2017-11-01 12:19:19,554 INFO org.apache.hadoop.yarn.server.resourcemanager.scheduler.capacity.CapacityScheduler: Allocation proposal accepted
2017-11-01 12:19:19,882 INFO org.apache.hadoop.yarn.server.resourcemanager.security.NMTokenSecretManagerInRM: Sending NMToken for nodeId : c220g1-030803.wisc.cloudlab.us:43522 for container : container_1509560227945_0001_01_000002
2017-11-01 12:19:19,884 INFO org.apache.hadoop.yarn.server.resourcemanager.rmcontainer.RMContainerImpl: container_1509560227945_0001_01_000002 Container Transitioned from ALLOCATED to ACQUIRED
2017-11-01 12:19:19,885 INFO org.apache.hadoop.yarn.server.resourcemanager.rmcontainer.RMContainerImpl: container_1509560227945_0001_01_000003 Container Transitioned from ALLOCATED to ACQUIRED
2017-11-01 12:19:20,909 INFO org.apache.hadoop.yarn.server.resourcemanager.scheduler.AppSchedulingInfo: checking for deactivate of application :application_1509560227945_0001
2017-11-01 12:19:21,572 INFO org.apache.hadoop.yarn.server.resourcemanager.rmcontainer.RMContainerImpl: container_1509560227945_0001_01_000002 Container Transitioned from ACQUIRED to RUNNING
2017-11-01 12:19:21,572 INFO org.apache.hadoop.yarn.server.resourcemanager.rmcontainer.RMContainerImpl: container_1509560227945_0001_01_000003 Container Transitioned from ACQUIRED to RUNNING
2017-11-01 12:19:25,256 INFO org.apache.hadoop.yarn.server.resourcemanager.rmcontainer.RMContainerImpl: container_1509560227945_0001_01_000003 Container Transitioned from RUNNING to COMPLETED
2017-11-01 12:19:25,256 INFO org.apache.hadoop.yarn.server.resourcemanager.RMAuditLogger: USER=wentingt	OPERATION=AM Released Container	TARGET=SchedulerApp	RESULT=SUCCESS	APPID=application_1509560227945_0001	CONTAINERID=container_1509560227945_0001_01_000003	RESOURCE=<memory:1024, vCores:1>
2017-11-01 12:19:25,258 INFO org.apache.hadoop.yarn.server.resourcemanager.rmcontainer.RMContainerImpl: container_1509560227945_0001_01_000002 Container Transitioned from RUNNING to COMPLETED
2017-11-01 12:19:25,258 INFO org.apache.hadoop.yarn.server.resourcemanager.RMAuditLogger: USER=wentingt	OPERATION=AM Released Container	TARGET=SchedulerApp	RESULT=SUCCESS	APPID=application_1509560227945_0001	CONTAINERID=container_1509560227945_0001_01_000002	RESOURCE=<memory:1024, vCores:1>
2017-11-01 12:19:26,257 INFO org.apache.hadoop.yarn.server.resourcemanager.scheduler.capacity.allocator.AbstractContainerAllocator: assignedContainer application attempt=appattempt_1509560227945_0001_000001 container=null queue=org.apache.hadoop.yarn.server.resourcemanager.scheduler.capacity.allocator.RegularContainerAllocator@28abdf93 clusterResource=<memory:16384, vCores:16> type=OFF_SWITCH requestedPartition=
2017-11-01 12:19:26,257 INFO org.apache.hadoop.yarn.server.resourcemanager.scheduler.capacity.ParentQueue: assignedContainer queue=root usedCapacity=0.125 absoluteUsedCapacity=0.125 used=<memory:2048, vCores:1> cluster=<memory:16384, vCores:16>
2017-11-01 12:19:26,258 INFO org.apache.hadoop.yarn.server.resourcemanager.rmcontainer.RMContainerImpl: container_1509560227945_0001_01_000004 Container Transitioned from NEW to ALLOCATED
2017-11-01 12:19:26,258 INFO org.apache.hadoop.yarn.server.resourcemanager.scheduler.common.fica.FiCaSchedulerNode: Assigned container container_1509560227945_0001_01_000004 of capacity <memory:1024, vCores:1> on host c220g1-030803.wisc.cloudlab.us:43522, which has 1 containers, <memory:1024, vCores:1> used and <memory:7168, vCores:7> available after allocation
2017-11-01 12:19:26,258 INFO org.apache.hadoop.yarn.server.resourcemanager.RMAuditLogger: USER=wentingt	OPERATION=AM Allocated Container	TARGET=SchedulerApp	RESULT=SUCCESS	APPID=application_1509560227945_0001	CONTAINERID=container_1509560227945_0001_01_000004	RESOURCE=<memory:1024, vCores:1>
2017-11-01 12:19:26,258 INFO org.apache.hadoop.yarn.server.resourcemanager.scheduler.capacity.ParentQueue: assignedContainer queue=root usedCapacity=0.1875 absoluteUsedCapacity=0.1875 used=<memory:3072, vCores:2> cluster=<memory:16384, vCores:16>
2017-11-01 12:19:26,258 INFO org.apache.hadoop.yarn.server.resourcemanager.scheduler.capacity.CapacityScheduler: Allocation proposal accepted
2017-11-01 12:19:26,947 INFO org.apache.hadoop.yarn.server.resourcemanager.rmcontainer.RMContainerImpl: container_1509560227945_0001_01_000004 Container Transitioned from ALLOCATED to ACQUIRED
2017-11-01 12:19:27,260 INFO org.apache.hadoop.yarn.server.resourcemanager.rmcontainer.RMContainerImpl: container_1509560227945_0001_01_000004 Container Transitioned from ACQUIRED to RUNNING
2017-11-01 12:19:27,953 INFO org.apache.hadoop.yarn.server.resourcemanager.scheduler.AppSchedulingInfo: checking for deactivate of application :application_1509560227945_0001
2017-11-01 12:19:56,462 INFO org.apache.hadoop.yarn.server.resourcemanager.rmcontainer.RMContainerImpl: container_1509560227945_0001_01_000004 Container Transitioned from RUNNING to COMPLETED
2017-11-01 12:19:56,462 INFO org.apache.hadoop.yarn.server.resourcemanager.RMAuditLogger: USER=wentingt	OPERATION=AM Released Container	TARGET=SchedulerApp	RESULT=SUCCESS	APPID=application_1509560227945_0001	CONTAINERID=container_1509560227945_0001_01_000004	RESOURCE=<memory:1024, vCores:1>
2017-11-01 12:19:58,468 INFO org.apache.hadoop.yarn.server.resourcemanager.scheduler.capacity.allocator.AbstractContainerAllocator: assignedContainer application attempt=appattempt_1509560227945_0001_000001 container=null queue=org.apache.hadoop.yarn.server.resourcemanager.scheduler.capacity.allocator.RegularContainerAllocator@28abdf93 clusterResource=<memory:16384, vCores:16> type=OFF_SWITCH requestedPartition=
2017-11-01 12:19:58,468 INFO org.apache.hadoop.yarn.server.resourcemanager.scheduler.capacity.ParentQueue: assignedContainer queue=root usedCapacity=0.125 absoluteUsedCapacity=0.125 used=<memory:2048, vCores:1> cluster=<memory:16384, vCores:16>
2017-11-01 12:19:58,469 INFO org.apache.hadoop.yarn.server.resourcemanager.rmcontainer.RMContainerImpl: container_1509560227945_0001_01_000005 Container Transitioned from NEW to ALLOCATED
2017-11-01 12:19:58,469 INFO org.apache.hadoop.yarn.server.resourcemanager.scheduler.common.fica.FiCaSchedulerNode: Assigned container container_1509560227945_0001_01_000005 of capacity <memory:1024, vCores:1> on host c220g1-030803.wisc.cloudlab.us:43522, which has 1 containers, <memory:1024, vCores:1> used and <memory:7168, vCores:7> available after allocation
2017-11-01 12:19:58,469 INFO org.apache.hadoop.yarn.server.resourcemanager.RMAuditLogger: USER=wentingt	OPERATION=AM Allocated Container	TARGET=SchedulerApp	RESULT=SUCCESS	APPID=application_1509560227945_0001	CONTAINERID=container_1509560227945_0001_01_000005	RESOURCE=<memory:1024, vCores:1>
2017-11-01 12:19:58,469 INFO org.apache.hadoop.yarn.server.resourcemanager.scheduler.capacity.ParentQueue: assignedContainer queue=root usedCapacity=0.1875 absoluteUsedCapacity=0.1875 used=<memory:3072, vCores:2> cluster=<memory:16384, vCores:16>
2017-11-01 12:19:58,469 INFO org.apache.hadoop.yarn.server.resourcemanager.scheduler.capacity.CapacityScheduler: Allocation proposal accepted
2017-11-01 12:19:59,053 INFO org.apache.hadoop.yarn.server.resourcemanager.rmcontainer.RMContainerImpl: container_1509560227945_0001_01_000005 Container Transitioned from ALLOCATED to ACQUIRED
2017-11-01 12:19:59,468 INFO org.apache.hadoop.yarn.server.resourcemanager.rmcontainer.RMContainerImpl: container_1509560227945_0001_01_000005 Container Transitioned from ACQUIRED to RUNNING
2017-11-01 12:20:00,057 INFO org.apache.hadoop.yarn.server.resourcemanager.scheduler.AppSchedulingInfo: checking for deactivate of application :application_1509560227945_0001
2017-11-01 12:20:02,319 INFO org.apache.hadoop.yarn.server.resourcemanager.rmcontainer.RMContainerImpl: container_1509560227945_0001_01_000005 Container Transitioned from RUNNING to COMPLETED
2017-11-01 12:20:02,319 INFO org.apache.hadoop.yarn.server.resourcemanager.RMAuditLogger: USER=wentingt	OPERATION=AM Released Container	TARGET=SchedulerApp	RESULT=SUCCESS	APPID=application_1509560227945_0001	CONTAINERID=container_1509560227945_0001_01_000005	RESOURCE=<memory:1024, vCores:1>
2017-11-01 12:20:02,320 INFO org.apache.hadoop.yarn.server.resourcemanager.scheduler.capacity.allocator.AbstractContainerAllocator: assignedContainer application attempt=appattempt_1509560227945_0001_000001 container=null queue=org.apache.hadoop.yarn.server.resourcemanager.scheduler.capacity.allocator.RegularContainerAllocator@28abdf93 clusterResource=<memory:16384, vCores:16> type=OFF_SWITCH requestedPartition=
2017-11-01 12:20:02,320 INFO org.apache.hadoop.yarn.server.resourcemanager.scheduler.capacity.ParentQueue: assignedContainer queue=root usedCapacity=0.125 absoluteUsedCapacity=0.125 used=<memory:2048, vCores:1> cluster=<memory:16384, vCores:16>
2017-11-01 12:20:02,321 INFO org.apache.hadoop.yarn.server.resourcemanager.rmcontainer.RMContainerImpl: container_1509560227945_0001_01_000006 Container Transitioned from NEW to ALLOCATED
2017-11-01 12:20:02,321 INFO org.apache.hadoop.yarn.server.resourcemanager.scheduler.common.fica.FiCaSchedulerNode: Assigned container container_1509560227945_0001_01_000006 of capacity <memory:1024, vCores:1> on host c220g1-030803.wisc.cloudlab.us:43522, which has 1 containers, <memory:1024, vCores:1> used and <memory:7168, vCores:7> available after allocation
2017-11-01 12:20:02,321 INFO org.apache.hadoop.yarn.server.resourcemanager.RMAuditLogger: USER=wentingt	OPERATION=AM Allocated Container	TARGET=SchedulerApp	RESULT=SUCCESS	APPID=application_1509560227945_0001	CONTAINERID=container_1509560227945_0001_01_000006	RESOURCE=<memory:1024, vCores:1>
2017-11-01 12:20:02,322 INFO org.apache.hadoop.yarn.server.resourcemanager.scheduler.capacity.ParentQueue: assignedContainer queue=root usedCapacity=0.1875 absoluteUsedCapacity=0.1875 used=<memory:3072, vCores:2> cluster=<memory:16384, vCores:16>
2017-11-01 12:20:02,322 INFO org.apache.hadoop.yarn.server.resourcemanager.scheduler.capacity.CapacityScheduler: Allocation proposal accepted
2017-11-01 12:20:03,069 INFO org.apache.hadoop.yarn.server.resourcemanager.rmcontainer.RMContainerImpl: container_1509560227945_0001_01_000006 Container Transitioned from ALLOCATED to ACQUIRED
2017-11-01 12:20:03,070 INFO org.apache.hadoop.yarn.server.resourcemanager.DefaultAMSProcessor: blacklist are updated in Scheduler.blacklistAdditions: [c220g1-030803.wisc.cloudlab.us], blacklistRemovals: []
2017-11-01 12:20:03,321 INFO org.apache.hadoop.yarn.server.resourcemanager.rmcontainer.RMContainerImpl: container_1509560227945_0001_01_000006 Container Transitioned from ACQUIRED to RUNNING
2017-11-01 12:20:04,090 INFO org.apache.hadoop.yarn.server.resourcemanager.scheduler.AppSchedulingInfo: checking for deactivate of application :application_1509560227945_0001
2017-11-01 12:20:04,091 INFO org.apache.hadoop.yarn.server.resourcemanager.DefaultAMSProcessor: blacklist are updated in Scheduler.blacklistAdditions: [], blacklistRemovals: [c220g1-030803.wisc.cloudlab.us]
2017-11-01 12:20:04,324 INFO org.apache.hadoop.yarn.server.resourcemanager.scheduler.capacity.allocator.AbstractContainerAllocator: assignedContainer application attempt=appattempt_1509560227945_0001_000001 container=null queue=org.apache.hadoop.yarn.server.resourcemanager.scheduler.capacity.allocator.RegularContainerAllocator@28abdf93 clusterResource=<memory:16384, vCores:16> type=OFF_SWITCH requestedPartition=
2017-11-01 12:20:04,324 INFO org.apache.hadoop.yarn.server.resourcemanager.scheduler.capacity.ParentQueue: assignedContainer queue=root usedCapacity=0.1875 absoluteUsedCapacity=0.1875 used=<memory:3072, vCores:2> cluster=<memory:16384, vCores:16>
2017-11-01 12:20:04,324 INFO org.apache.hadoop.yarn.server.resourcemanager.rmcontainer.RMContainerImpl: container_1509560227945_0001_01_000007 Container Transitioned from NEW to ALLOCATED
2017-11-01 12:20:04,324 INFO org.apache.hadoop.yarn.server.resourcemanager.scheduler.common.fica.FiCaSchedulerNode: Assigned container container_1509560227945_0001_01_000007 of capacity <memory:1024, vCores:1> on host c220g1-030803.wisc.cloudlab.us:43522, which has 2 containers, <memory:2048, vCores:2> used and <memory:6144, vCores:6> available after allocation
2017-11-01 12:20:04,325 INFO org.apache.hadoop.yarn.server.resourcemanager.RMAuditLogger: USER=wentingt	OPERATION=AM Allocated Container	TARGET=SchedulerApp	RESULT=SUCCESS	APPID=application_1509560227945_0001	CONTAINERID=container_1509560227945_0001_01_000007	RESOURCE=<memory:1024, vCores:1>
2017-11-01 12:20:04,325 INFO org.apache.hadoop.yarn.server.resourcemanager.scheduler.capacity.ParentQueue: assignedContainer queue=root usedCapacity=0.25 absoluteUsedCapacity=0.25 used=<memory:4096, vCores:3> cluster=<memory:16384, vCores:16>
2017-11-01 12:20:04,326 INFO org.apache.hadoop.yarn.server.resourcemanager.scheduler.capacity.CapacityScheduler: Allocation proposal accepted
2017-11-01 12:20:05,095 INFO org.apache.hadoop.yarn.server.resourcemanager.rmcontainer.RMContainerImpl: container_1509560227945_0001_01_000007 Container Transitioned from ALLOCATED to ACQUIRED
2017-11-01 12:20:05,326 INFO org.apache.hadoop.yarn.server.resourcemanager.rmcontainer.RMContainerImpl: container_1509560227945_0001_01_000007 Container Transitioned from ACQUIRED to RUNNING
2017-11-01 12:20:06,098 INFO org.apache.hadoop.yarn.server.resourcemanager.scheduler.AppSchedulingInfo: checking for deactivate of application :application_1509560227945_0001
2017-11-01 12:20:06,577 INFO org.apache.hadoop.yarn.server.resourcemanager.rmcontainer.RMContainerImpl: container_1509560227945_0001_01_000006 Container Transitioned from RUNNING to COMPLETED
2017-11-01 12:20:06,577 INFO org.apache.hadoop.yarn.server.resourcemanager.RMAuditLogger: USER=wentingt	OPERATION=AM Released Container	TARGET=SchedulerApp	RESULT=SUCCESS	APPID=application_1509560227945_0001	CONTAINERID=container_1509560227945_0001_01_000006	RESOURCE=<memory:1024, vCores:1>
2017-11-01 12:20:20,604 INFO org.apache.hadoop.yarn.server.resourcemanager.scheduler.capacity.allocator.AbstractContainerAllocator: assignedContainer application attempt=appattempt_1509560227945_0001_000001 container=null queue=org.apache.hadoop.yarn.server.resourcemanager.scheduler.capacity.allocator.RegularContainerAllocator@28abdf93 clusterResource=<memory:16384, vCores:16> type=OFF_SWITCH requestedPartition=
2017-11-01 12:20:20,604 INFO org.apache.hadoop.yarn.server.resourcemanager.scheduler.capacity.ParentQueue: assignedContainer queue=root usedCapacity=0.1875 absoluteUsedCapacity=0.1875 used=<memory:3072, vCores:2> cluster=<memory:16384, vCores:16>
2017-11-01 12:20:20,605 INFO org.apache.hadoop.yarn.server.resourcemanager.rmcontainer.RMContainerImpl: container_1509560227945_0001_01_000008 Container Transitioned from NEW to ALLOCATED
2017-11-01 12:20:20,605 INFO org.apache.hadoop.yarn.server.resourcemanager.scheduler.common.fica.FiCaSchedulerNode: Assigned container container_1509560227945_0001_01_000008 of capacity <memory:1024, vCores:1> on host c220g1-030803.wisc.cloudlab.us:43522, which has 2 containers, <memory:2048, vCores:2> used and <memory:6144, vCores:6> available after allocation
2017-11-01 12:20:20,605 INFO org.apache.hadoop.yarn.server.resourcemanager.RMAuditLogger: USER=wentingt	OPERATION=AM Allocated Container	TARGET=SchedulerApp	RESULT=SUCCESS	APPID=application_1509560227945_0001	CONTAINERID=container_1509560227945_0001_01_000008	RESOURCE=<memory:1024, vCores:1>
2017-11-01 12:20:20,605 INFO org.apache.hadoop.yarn.server.resourcemanager.scheduler.capacity.ParentQueue: assignedContainer queue=root usedCapacity=0.25 absoluteUsedCapacity=0.25 used=<memory:4096, vCores:3> cluster=<memory:16384, vCores:16>
2017-11-01 12:20:20,605 INFO org.apache.hadoop.yarn.server.resourcemanager.scheduler.capacity.CapacityScheduler: Allocation proposal accepted
2017-11-01 12:20:21,154 INFO org.apache.hadoop.yarn.server.resourcemanager.rmcontainer.RMContainerImpl: container_1509560227945_0001_01_000008 Container Transitioned from ALLOCATED to ACQUIRED
2017-11-01 12:20:21,227 INFO org.apache.hadoop.yarn.server.resourcemanager.rmcontainer.RMContainerImpl: container_1509560227945_0001_01_000008 Container Transitioned from ACQUIRED to RUNNING
2017-11-01 12:20:21,227 INFO org.apache.hadoop.yarn.server.resourcemanager.rmcontainer.RMContainerImpl: container_1509560227945_0001_01_000007 Container Transitioned from RUNNING to COMPLETED
2017-11-01 12:20:21,227 INFO org.apache.hadoop.yarn.server.resourcemanager.RMAuditLogger: USER=wentingt	OPERATION=AM Released Container	TARGET=SchedulerApp	RESULT=SUCCESS	APPID=application_1509560227945_0001	CONTAINERID=container_1509560227945_0001_01_000007	RESOURCE=<memory:1024, vCores:1>
2017-11-01 12:20:22,158 INFO org.apache.hadoop.yarn.server.resourcemanager.scheduler.AppSchedulingInfo: checking for deactivate of application :application_1509560227945_0001
2017-11-01 12:20:22,229 INFO org.apache.hadoop.yarn.server.resourcemanager.scheduler.capacity.allocator.AbstractContainerAllocator: assignedContainer application attempt=appattempt_1509560227945_0001_000001 container=null queue=org.apache.hadoop.yarn.server.resourcemanager.scheduler.capacity.allocator.RegularContainerAllocator@28abdf93 clusterResource=<memory:16384, vCores:16> type=OFF_SWITCH requestedPartition=
2017-11-01 12:20:22,229 INFO org.apache.hadoop.yarn.server.resourcemanager.scheduler.capacity.ParentQueue: assignedContainer queue=root usedCapacity=0.1875 absoluteUsedCapacity=0.1875 used=<memory:3072, vCores:2> cluster=<memory:16384, vCores:16>
2017-11-01 12:20:22,229 INFO org.apache.hadoop.yarn.server.resourcemanager.rmcontainer.RMContainerImpl: container_1509560227945_0001_01_000009 Container Transitioned from NEW to ALLOCATED
2017-11-01 12:20:22,230 INFO org.apache.hadoop.yarn.server.resourcemanager.scheduler.common.fica.FiCaSchedulerNode: Assigned container container_1509560227945_0001_01_000009 of capacity <memory:1024, vCores:1> on host c220g1-030803.wisc.cloudlab.us:43522, which has 2 containers, <memory:2048, vCores:2> used and <memory:6144, vCores:6> available after allocation
2017-11-01 12:20:22,230 INFO org.apache.hadoop.yarn.server.resourcemanager.RMAuditLogger: USER=wentingt	OPERATION=AM Allocated Container	TARGET=SchedulerApp	RESULT=SUCCESS	APPID=application_1509560227945_0001	CONTAINERID=container_1509560227945_0001_01_000009	RESOURCE=<memory:1024, vCores:1>
2017-11-01 12:20:22,230 INFO org.apache.hadoop.yarn.server.resourcemanager.scheduler.capacity.ParentQueue: assignedContainer queue=root usedCapacity=0.25 absoluteUsedCapacity=0.25 used=<memory:4096, vCores:3> cluster=<memory:16384, vCores:16>
2017-11-01 12:20:22,230 INFO org.apache.hadoop.yarn.server.resourcemanager.scheduler.capacity.CapacityScheduler: Allocation proposal accepted
2017-11-01 12:20:23,163 INFO org.apache.hadoop.yarn.server.resourcemanager.rmcontainer.RMContainerImpl: container_1509560227945_0001_01_000009 Container Transitioned from ALLOCATED to ACQUIRED
2017-11-01 12:20:23,231 INFO org.apache.hadoop.yarn.server.resourcemanager.rmcontainer.RMContainerImpl: container_1509560227945_0001_01_000009 Container Transitioned from ACQUIRED to RUNNING
2017-11-01 12:20:24,166 INFO org.apache.hadoop.yarn.server.resourcemanager.scheduler.AppSchedulingInfo: checking for deactivate of application :application_1509560227945_0001
2017-11-01 12:20:24,585 INFO org.apache.hadoop.yarn.server.resourcemanager.rmcontainer.RMContainerImpl: container_1509560227945_0001_01_000008 Container Transitioned from RUNNING to COMPLETED
2017-11-01 12:20:24,586 INFO org.apache.hadoop.yarn.server.resourcemanager.RMAuditLogger: USER=wentingt	OPERATION=AM Released Container	TARGET=SchedulerApp	RESULT=SUCCESS	APPID=application_1509560227945_0001	CONTAINERID=container_1509560227945_0001_01_000008	RESOURCE=<memory:1024, vCores:1>
2017-11-01 12:20:39,195 INFO org.apache.hadoop.yarn.server.resourcemanager.scheduler.AppSchedulingInfo: checking for deactivate of application :application_1509560227945_0001
2017-11-01 12:20:39,286 INFO org.apache.hadoop.yarn.server.resourcemanager.rmcontainer.RMContainerImpl: container_1509560227945_0001_01_000009 Container Transitioned from RUNNING to COMPLETED
2017-11-01 12:20:39,286 INFO org.apache.hadoop.yarn.server.resourcemanager.RMAuditLogger: USER=wentingt	OPERATION=AM Released Container	TARGET=SchedulerApp	RESULT=SUCCESS	APPID=application_1509560227945_0001	CONTAINERID=container_1509560227945_0001_01_000009	RESOURCE=<memory:1024, vCores:1>
2017-11-01 12:20:39,346 INFO org.apache.hadoop.yarn.server.resourcemanager.rmapp.attempt.RMAppAttemptImpl: Updating application attempt appattempt_1509560227945_0001_000001 with final state: FINISHING, and exit status: -1000
2017-11-01 12:20:39,347 INFO org.apache.hadoop.yarn.server.resourcemanager.rmapp.attempt.RMAppAttemptImpl: appattempt_1509560227945_0001_000001 State change from RUNNING to FINAL_SAVING on event = UNREGISTERED
2017-11-01 12:20:39,347 INFO org.apache.hadoop.yarn.server.resourcemanager.rmapp.RMAppImpl: Updating application application_1509560227945_0001 with final state: FINISHING
2017-11-01 12:20:39,348 INFO org.apache.hadoop.yarn.server.resourcemanager.rmapp.RMAppImpl: application_1509560227945_0001 State change from RUNNING to FINAL_SAVING on event = ATTEMPT_UNREGISTERED
2017-11-01 12:20:39,348 INFO org.apache.hadoop.yarn.server.resourcemanager.recovery.RMStateStore: Updating info for app: application_1509560227945_0001
2017-11-01 12:20:39,348 INFO org.apache.hadoop.yarn.server.resourcemanager.rmapp.attempt.RMAppAttemptImpl: appattempt_1509560227945_0001_000001 State change from FINAL_SAVING to FINISHING on event = ATTEMPT_UPDATE_SAVED
2017-11-01 12:20:39,348 INFO org.apache.hadoop.yarn.server.resourcemanager.rmapp.RMAppImpl: application_1509560227945_0001 State change from FINAL_SAVING to FINISHING on event = APP_UPDATE_SAVED
2017-11-01 12:20:40,345 INFO org.apache.hadoop.yarn.server.resourcemanager.ApplicationMasterService: application_1509560227945_0001 unregistered successfully. 
2017-11-01 12:20:45,782 INFO org.apache.hadoop.yarn.server.resourcemanager.rmcontainer.RMContainerImpl: container_1509560227945_0001_01_000001 Container Transitioned from RUNNING to COMPLETED
2017-11-01 12:20:45,782 INFO org.apache.hadoop.yarn.server.resourcemanager.ApplicationMasterService: Unregistering app attempt : appattempt_1509560227945_0001_000001
2017-11-01 12:20:45,782 INFO org.apache.hadoop.yarn.server.resourcemanager.RMAuditLogger: USER=wentingt	OPERATION=AM Released Container	TARGET=SchedulerApp	RESULT=SUCCESS	APPID=application_1509560227945_0001	CONTAINERID=container_1509560227945_0001_01_000001	RESOURCE=<memory:2048, vCores:1>
2017-11-01 12:20:45,783 INFO org.apache.hadoop.yarn.server.resourcemanager.security.AMRMTokenSecretManager: Application finished, removing password for appattempt_1509560227945_0001_000001
2017-11-01 12:20:45,784 INFO org.apache.hadoop.yarn.server.resourcemanager.rmapp.attempt.RMAppAttemptImpl: appattempt_1509560227945_0001_000001 State change from FINISHING to FINISHED on event = CONTAINER_FINISHED
2017-11-01 12:20:45,787 INFO org.apache.hadoop.yarn.server.resourcemanager.rmapp.RMAppImpl: application_1509560227945_0001 State change from FINISHING to FINISHED on event = ATTEMPT_FINISHED
2017-11-01 12:20:45,787 INFO org.apache.hadoop.yarn.server.resourcemanager.scheduler.capacity.CapacityScheduler: Application Attempt appattempt_1509560227945_0001_000001 is done. finalState=FINISHED
2017-11-01 12:20:45,787 INFO org.apache.hadoop.yarn.server.resourcemanager.scheduler.AppSchedulingInfo: Application application_1509560227945_0001 requests cleared
2017-11-01 12:20:45,787 INFO org.apache.hadoop.yarn.server.resourcemanager.amlauncher.AMLauncher: Cleaning master appattempt_1509560227945_0001_000001
2017-11-01 12:20:45,788 INFO org.apache.hadoop.yarn.server.resourcemanager.scheduler.capacity.LeafQueue: Application removed - appId: application_1509560227945_0001 user: wentingt queue: default #user-pending-applications: 0 #user-active-applications: 0 #queue-pending-applications: 0 #queue-active-applications: 0
2017-11-01 12:20:45,789 INFO org.apache.hadoop.yarn.server.resourcemanager.scheduler.capacity.ParentQueue: Application removed - appId: application_1509560227945_0001 user: wentingt leaf-queue of parent: root #applications: 0
2017-11-01 12:20:45,789 INFO org.apache.hadoop.yarn.server.resourcemanager.RMAuditLogger: USER=wentingt	OPERATION=Application Finished - Succeeded	TARGET=RMAppManager	RESULT=SUCCESS	APPID=application_1509560227945_0001
2017-11-01 12:20:45,793 INFO org.apache.hadoop.yarn.server.resourcemanager.RMAppManager$ApplicationSummary: appId=application_1509560227945_0001,name=QuasiMonteCarlo,user=wentingt,queue=default,state=FINISHED,trackingUrl=http://c220g1-030817.wisc.cloudlab.us:8088/proxy/application_1509560227945_0001/,appMasterHost=c220g1-030814.wisc.cloudlab.us,submitTime=1509560350270,startTime=1509560350363,finishTime=1509560439347,finalStatus=FAILED,memorySeconds=284775,vcoreSeconds=178,preemptedMemorySeconds=0,preemptedVcoreSeconds=0,preemptedAMContainers=0,preemptedNonAMContainers=0,preemptedResources=<memory:0\, vCores:0>,applicationType=MAPREDUCE
2017-11-01 12:25:49,168 INFO org.apache.hadoop.yarn.server.resourcemanager.ClientRMService: Allocated new applicationId: 2
2017-11-01 12:25:49,990 INFO org.apache.hadoop.yarn.server.resourcemanager.scheduler.capacity.CapacityScheduler: Application 'application_1509560227945_0002' is submitted without priority hence considering default queue/cluster priority: 0
2017-11-01 12:25:49,991 INFO org.apache.hadoop.yarn.server.resourcemanager.scheduler.capacity.CapacityScheduler: Priority '0' is acceptable in queue : default for application: application_1509560227945_0002
2017-11-01 12:25:49,991 INFO org.apache.hadoop.yarn.server.resourcemanager.ClientRMService: Application with id 2 submitted by user wentingt
2017-11-01 12:25:49,991 INFO org.apache.hadoop.yarn.server.resourcemanager.RMAuditLogger: USER=wentingt	IP=10.0.0.3	OPERATION=Submit Application Request	TARGET=ClientRMService	RESULT=SUCCESS	APPID=application_1509560227945_0002	CALLERCONTEXT=CLI
2017-11-01 12:25:49,991 INFO org.apache.hadoop.yarn.server.resourcemanager.rmapp.RMAppImpl: Storing application with id application_1509560227945_0002
2017-11-01 12:25:49,992 INFO org.apache.hadoop.yarn.server.resourcemanager.recovery.RMStateStore: Storing info for app: application_1509560227945_0002
2017-11-01 12:25:49,992 INFO org.apache.hadoop.yarn.server.resourcemanager.rmapp.RMAppImpl: application_1509560227945_0002 State change from NEW to NEW_SAVING on event = START
2017-11-01 12:25:49,992 INFO org.apache.hadoop.yarn.server.resourcemanager.rmapp.RMAppImpl: application_1509560227945_0002 State change from NEW_SAVING to SUBMITTED on event = APP_NEW_SAVED
2017-11-01 12:25:49,992 INFO org.apache.hadoop.yarn.server.resourcemanager.scheduler.capacity.ParentQueue: Application added - appId: application_1509560227945_0002 user: wentingt leaf-queue of parent: root #applications: 1
2017-11-01 12:25:49,992 INFO org.apache.hadoop.yarn.server.resourcemanager.scheduler.capacity.CapacityScheduler: Accepted application application_1509560227945_0002 from user: wentingt, in queue: default
2017-11-01 12:25:50,094 INFO org.apache.hadoop.yarn.server.resourcemanager.rmapp.RMAppImpl: application_1509560227945_0002 State change from SUBMITTED to ACCEPTED on event = APP_ACCEPTED
2017-11-01 12:25:50,094 INFO org.apache.hadoop.yarn.server.resourcemanager.ApplicationMasterService: Registering app attempt : appattempt_1509560227945_0002_000001
2017-11-01 12:25:50,094 INFO org.apache.hadoop.yarn.server.resourcemanager.rmapp.attempt.RMAppAttemptImpl: appattempt_1509560227945_0002_000001 State change from NEW to SUBMITTED on event = START
2017-11-01 12:25:50,096 INFO org.apache.hadoop.yarn.server.resourcemanager.scheduler.capacity.LeafQueue: Application application_1509560227945_0002 from user: wentingt activated in queue: default
2017-11-01 12:25:50,096 INFO org.apache.hadoop.yarn.server.resourcemanager.scheduler.capacity.LeafQueue: Application added - appId: application_1509560227945_0002 user: wentingt, leaf-queue: default #user-pending-applications: 0 #user-active-applications: 1 #queue-pending-applications: 0 #queue-active-applications: 1
2017-11-01 12:25:50,096 INFO org.apache.hadoop.yarn.server.resourcemanager.scheduler.capacity.CapacityScheduler: Added Application Attempt appattempt_1509560227945_0002_000001 to scheduler from user wentingt in queue default
2017-11-01 12:25:50,097 INFO org.apache.hadoop.yarn.server.resourcemanager.rmapp.attempt.RMAppAttemptImpl: appattempt_1509560227945_0002_000001 State change from SUBMITTED to SCHEDULED on event = ATTEMPT_ADDED
2017-11-01 12:25:50,168 INFO org.apache.hadoop.yarn.server.resourcemanager.scheduler.capacity.allocator.AbstractContainerAllocator: assignedContainer application attempt=appattempt_1509560227945_0002_000001 container=null queue=org.apache.hadoop.yarn.server.resourcemanager.scheduler.capacity.allocator.RegularContainerAllocator@2c302190 clusterResource=<memory:16384, vCores:16> type=OFF_SWITCH requestedPartition=
2017-11-01 12:25:50,169 INFO org.apache.hadoop.yarn.server.resourcemanager.scheduler.capacity.ParentQueue: assignedContainer queue=root usedCapacity=0.0 absoluteUsedCapacity=0.0 used=<memory:0, vCores:0> cluster=<memory:16384, vCores:16>
2017-11-01 12:25:50,169 INFO org.apache.hadoop.yarn.server.resourcemanager.rmcontainer.RMContainerImpl: container_1509560227945_0002_01_000001 Container Transitioned from NEW to ALLOCATED
2017-11-01 12:25:50,169 INFO org.apache.hadoop.yarn.server.resourcemanager.scheduler.common.fica.FiCaSchedulerNode: Assigned container container_1509560227945_0002_01_000001 of capacity <memory:2048, vCores:1> on host c220g1-030814.wisc.cloudlab.us:45451, which has 1 containers, <memory:2048, vCores:1> used and <memory:6144, vCores:7> available after allocation
2017-11-01 12:25:50,169 INFO org.apache.hadoop.yarn.server.resourcemanager.RMAuditLogger: USER=wentingt	OPERATION=AM Allocated Container	TARGET=SchedulerApp	RESULT=SUCCESS	APPID=application_1509560227945_0002	CONTAINERID=container_1509560227945_0002_01_000001	RESOURCE=<memory:2048, vCores:1>
2017-11-01 12:25:50,171 INFO org.apache.hadoop.yarn.server.resourcemanager.security.NMTokenSecretManagerInRM: Sending NMToken for nodeId : c220g1-030814.wisc.cloudlab.us:45451 for container : container_1509560227945_0002_01_000001
2017-11-01 12:25:50,172 INFO org.apache.hadoop.yarn.server.resourcemanager.rmcontainer.RMContainerImpl: container_1509560227945_0002_01_000001 Container Transitioned from ALLOCATED to ACQUIRED
2017-11-01 12:25:50,172 INFO org.apache.hadoop.yarn.server.resourcemanager.security.NMTokenSecretManagerInRM: Clear node set for appattempt_1509560227945_0002_000001
2017-11-01 12:25:50,172 INFO org.apache.hadoop.yarn.server.resourcemanager.rmapp.attempt.RMAppAttemptImpl: Storing attempt: AppId: application_1509560227945_0002 AttemptId: appattempt_1509560227945_0002_000001 MasterContainer: Container: [ContainerId: container_1509560227945_0002_01_000001, AllocationRequestId: 0, Version: 0, NodeId: c220g1-030814.wisc.cloudlab.us:45451, NodeHttpAddress: c220g1-030814.wisc.cloudlab.us:8042, Resource: <memory:2048, vCores:1>, Priority: 0, Token: Token { kind: ContainerToken, service: 128.104.222.44:45451 }, ExecutionType: GUARANTEED, ]
2017-11-01 12:25:50,172 INFO org.apache.hadoop.yarn.server.resourcemanager.scheduler.capacity.ParentQueue: assignedContainer queue=root usedCapacity=0.125 absoluteUsedCapacity=0.125 used=<memory:2048, vCores:1> cluster=<memory:16384, vCores:16>
2017-11-01 12:25:50,172 INFO org.apache.hadoop.yarn.server.resourcemanager.scheduler.capacity.CapacityScheduler: Allocation proposal accepted
2017-11-01 12:25:50,173 INFO org.apache.hadoop.yarn.server.resourcemanager.rmapp.attempt.RMAppAttemptImpl: appattempt_1509560227945_0002_000001 State change from SCHEDULED to ALLOCATED_SAVING on event = CONTAINER_ALLOCATED
2017-11-01 12:25:50,173 INFO org.apache.hadoop.yarn.server.resourcemanager.rmapp.attempt.RMAppAttemptImpl: appattempt_1509560227945_0002_000001 State change from ALLOCATED_SAVING to ALLOCATED on event = ATTEMPT_NEW_SAVED
2017-11-01 12:25:50,174 INFO org.apache.hadoop.yarn.server.resourcemanager.amlauncher.AMLauncher: Launching masterappattempt_1509560227945_0002_000001
2017-11-01 12:25:50,178 INFO org.apache.hadoop.yarn.server.resourcemanager.amlauncher.AMLauncher: Setting up container Container: [ContainerId: container_1509560227945_0002_01_000001, AllocationRequestId: 0, Version: 0, NodeId: c220g1-030814.wisc.cloudlab.us:45451, NodeHttpAddress: c220g1-030814.wisc.cloudlab.us:8042, Resource: <memory:2048, vCores:1>, Priority: 0, Token: Token { kind: ContainerToken, service: 128.104.222.44:45451 }, ExecutionType: GUARANTEED, ] for AM appattempt_1509560227945_0002_000001
2017-11-01 12:25:50,179 INFO org.apache.hadoop.yarn.server.resourcemanager.security.AMRMTokenSecretManager: Create AMRMToken for ApplicationAttempt: appattempt_1509560227945_0002_000001
2017-11-01 12:25:50,179 INFO org.apache.hadoop.yarn.server.resourcemanager.security.AMRMTokenSecretManager: Creating password for appattempt_1509560227945_0002_000001
2017-11-01 12:25:50,204 INFO org.apache.hadoop.yarn.server.resourcemanager.amlauncher.AMLauncher: Done launching container Container: [ContainerId: container_1509560227945_0002_01_000001, AllocationRequestId: 0, Version: 0, NodeId: c220g1-030814.wisc.cloudlab.us:45451, NodeHttpAddress: c220g1-030814.wisc.cloudlab.us:8042, Resource: <memory:2048, vCores:1>, Priority: 0, Token: Token { kind: ContainerToken, service: 128.104.222.44:45451 }, ExecutionType: GUARANTEED, ] for AM appattempt_1509560227945_0002_000001
2017-11-01 12:25:50,204 INFO org.apache.hadoop.yarn.server.resourcemanager.rmapp.attempt.RMAppAttemptImpl: appattempt_1509560227945_0002_000001 State change from ALLOCATED to LAUNCHED on event = LAUNCHED
2017-11-01 12:25:51,170 INFO org.apache.hadoop.yarn.server.resourcemanager.rmcontainer.RMContainerImpl: container_1509560227945_0002_01_000001 Container Transitioned from ACQUIRED to RUNNING
2017-11-01 12:25:55,628 INFO SecurityLogger.org.apache.hadoop.ipc.Server: Auth successful for appattempt_1509560227945_0002_000001 (auth:SIMPLE)
2017-11-01 12:25:55,633 INFO org.apache.hadoop.yarn.server.resourcemanager.DefaultAMSProcessor: AM registration appattempt_1509560227945_0002_000001
2017-11-01 12:25:55,633 INFO org.apache.hadoop.yarn.server.resourcemanager.RMAuditLogger: USER=wentingt	IP=10.0.0.2	OPERATION=Register App Master	TARGET=ApplicationMasterService	RESULT=SUCCESS	APPID=application_1509560227945_0002	APPATTEMPTID=appattempt_1509560227945_0002_000001
2017-11-01 12:25:55,633 INFO org.apache.hadoop.yarn.server.resourcemanager.rmapp.attempt.RMAppAttemptImpl: appattempt_1509560227945_0002_000001 State change from LAUNCHED to RUNNING on event = REGISTERED
2017-11-01 12:25:55,634 INFO org.apache.hadoop.yarn.server.resourcemanager.rmapp.RMAppImpl: application_1509560227945_0002 State change from ACCEPTED to RUNNING on event = ATTEMPT_REGISTERED
2017-11-01 12:25:57,180 INFO org.apache.hadoop.yarn.server.resourcemanager.scheduler.capacity.allocator.AbstractContainerAllocator: assignedContainer application attempt=appattempt_1509560227945_0002_000001 container=null queue=org.apache.hadoop.yarn.server.resourcemanager.scheduler.capacity.allocator.RegularContainerAllocator@2c302190 clusterResource=<memory:16384, vCores:16> type=NODE_LOCAL requestedPartition=
2017-11-01 12:25:57,180 INFO org.apache.hadoop.yarn.server.resourcemanager.scheduler.capacity.ParentQueue: assignedContainer queue=root usedCapacity=0.125 absoluteUsedCapacity=0.125 used=<memory:2048, vCores:1> cluster=<memory:16384, vCores:16>
2017-11-01 12:25:57,180 INFO org.apache.hadoop.yarn.server.resourcemanager.rmcontainer.RMContainerImpl: container_1509560227945_0002_01_000002 Container Transitioned from NEW to ALLOCATED
2017-11-01 12:25:57,180 INFO org.apache.hadoop.yarn.server.resourcemanager.scheduler.common.fica.FiCaSchedulerNode: Assigned container container_1509560227945_0002_01_000002 of capacity <memory:1024, vCores:1> on host c220g1-030814.wisc.cloudlab.us:45451, which has 2 containers, <memory:3072, vCores:2> used and <memory:5120, vCores:6> available after allocation
2017-11-01 12:25:57,180 INFO org.apache.hadoop.yarn.server.resourcemanager.RMAuditLogger: USER=wentingt	OPERATION=AM Allocated Container	TARGET=SchedulerApp	RESULT=SUCCESS	APPID=application_1509560227945_0002	CONTAINERID=container_1509560227945_0002_01_000002	RESOURCE=<memory:1024, vCores:1>
2017-11-01 12:25:57,181 INFO org.apache.hadoop.yarn.server.resourcemanager.scheduler.capacity.ParentQueue: assignedContainer queue=root usedCapacity=0.1875 absoluteUsedCapacity=0.1875 used=<memory:3072, vCores:2> cluster=<memory:16384, vCores:16>
2017-11-01 12:25:57,181 INFO org.apache.hadoop.yarn.server.resourcemanager.scheduler.capacity.CapacityScheduler: Allocation proposal accepted
2017-11-01 12:25:57,181 INFO org.apache.hadoop.yarn.server.resourcemanager.scheduler.capacity.allocator.AbstractContainerAllocator: assignedContainer application attempt=appattempt_1509560227945_0002_000001 container=null queue=org.apache.hadoop.yarn.server.resourcemanager.scheduler.capacity.allocator.RegularContainerAllocator@2c302190 clusterResource=<memory:16384, vCores:16> type=NODE_LOCAL requestedPartition=
2017-11-01 12:25:57,181 INFO org.apache.hadoop.yarn.server.resourcemanager.scheduler.capacity.ParentQueue: assignedContainer queue=root usedCapacity=0.1875 absoluteUsedCapacity=0.1875 used=<memory:3072, vCores:2> cluster=<memory:16384, vCores:16>
2017-11-01 12:25:57,182 INFO org.apache.hadoop.yarn.server.resourcemanager.rmcontainer.RMContainerImpl: container_1509560227945_0002_01_000003 Container Transitioned from NEW to ALLOCATED
2017-11-01 12:25:57,182 INFO org.apache.hadoop.yarn.server.resourcemanager.scheduler.common.fica.FiCaSchedulerNode: Assigned container container_1509560227945_0002_01_000003 of capacity <memory:1024, vCores:1> on host c220g1-030814.wisc.cloudlab.us:45451, which has 3 containers, <memory:4096, vCores:3> used and <memory:4096, vCores:5> available after allocation
2017-11-01 12:25:57,182 INFO org.apache.hadoop.yarn.server.resourcemanager.RMAuditLogger: USER=wentingt	OPERATION=AM Allocated Container	TARGET=SchedulerApp	RESULT=SUCCESS	APPID=application_1509560227945_0002	CONTAINERID=container_1509560227945_0002_01_000003	RESOURCE=<memory:1024, vCores:1>
2017-11-01 12:25:57,182 INFO org.apache.hadoop.yarn.server.resourcemanager.scheduler.capacity.ParentQueue: assignedContainer queue=root usedCapacity=0.25 absoluteUsedCapacity=0.25 used=<memory:4096, vCores:3> cluster=<memory:16384, vCores:16>
2017-11-01 12:25:57,182 INFO org.apache.hadoop.yarn.server.resourcemanager.scheduler.capacity.CapacityScheduler: Allocation proposal accepted
2017-11-01 12:25:57,715 INFO org.apache.hadoop.yarn.server.resourcemanager.security.NMTokenSecretManagerInRM: Sending NMToken for nodeId : c220g1-030814.wisc.cloudlab.us:45451 for container : container_1509560227945_0002_01_000002
2017-11-01 12:25:57,716 INFO org.apache.hadoop.yarn.server.resourcemanager.rmcontainer.RMContainerImpl: container_1509560227945_0002_01_000002 Container Transitioned from ALLOCATED to ACQUIRED
2017-11-01 12:25:57,717 INFO org.apache.hadoop.yarn.server.resourcemanager.rmcontainer.RMContainerImpl: container_1509560227945_0002_01_000003 Container Transitioned from ALLOCATED to ACQUIRED
2017-11-01 12:25:58,182 INFO org.apache.hadoop.yarn.server.resourcemanager.rmcontainer.RMContainerImpl: container_1509560227945_0002_01_000002 Container Transitioned from ACQUIRED to RUNNING
2017-11-01 12:25:58,182 INFO org.apache.hadoop.yarn.server.resourcemanager.rmcontainer.RMContainerImpl: container_1509560227945_0002_01_000003 Container Transitioned from ACQUIRED to RUNNING
2017-11-01 12:25:58,739 INFO org.apache.hadoop.yarn.server.resourcemanager.scheduler.AppSchedulingInfo: checking for deactivate of application :application_1509560227945_0002
2017-11-01 12:26:01,333 INFO org.apache.hadoop.yarn.server.resourcemanager.rmcontainer.RMContainerImpl: container_1509560227945_0002_01_000003 Container Transitioned from RUNNING to COMPLETED
2017-11-01 12:26:01,333 INFO org.apache.hadoop.yarn.server.resourcemanager.RMAuditLogger: USER=wentingt	OPERATION=AM Released Container	TARGET=SchedulerApp	RESULT=SUCCESS	APPID=application_1509560227945_0002	CONTAINERID=container_1509560227945_0002_01_000003	RESOURCE=<memory:1024, vCores:1>
2017-11-01 12:26:01,346 INFO org.apache.hadoop.yarn.server.resourcemanager.rmcontainer.RMContainerImpl: container_1509560227945_0002_01_000002 Container Transitioned from RUNNING to COMPLETED
2017-11-01 12:26:01,346 INFO org.apache.hadoop.yarn.server.resourcemanager.RMAuditLogger: USER=wentingt	OPERATION=AM Released Container	TARGET=SchedulerApp	RESULT=SUCCESS	APPID=application_1509560227945_0002	CONTAINERID=container_1509560227945_0002_01_000002	RESOURCE=<memory:1024, vCores:1>
2017-11-01 12:26:03,349 INFO org.apache.hadoop.yarn.server.resourcemanager.scheduler.capacity.allocator.AbstractContainerAllocator: assignedContainer application attempt=appattempt_1509560227945_0002_000001 container=null queue=org.apache.hadoop.yarn.server.resourcemanager.scheduler.capacity.allocator.RegularContainerAllocator@2c302190 clusterResource=<memory:16384, vCores:16> type=OFF_SWITCH requestedPartition=
2017-11-01 12:26:03,350 INFO org.apache.hadoop.yarn.server.resourcemanager.scheduler.capacity.ParentQueue: assignedContainer queue=root usedCapacity=0.125 absoluteUsedCapacity=0.125 used=<memory:2048, vCores:1> cluster=<memory:16384, vCores:16>
2017-11-01 12:26:03,350 INFO org.apache.hadoop.yarn.server.resourcemanager.rmcontainer.RMContainerImpl: container_1509560227945_0002_01_000004 Container Transitioned from NEW to ALLOCATED
2017-11-01 12:26:03,350 INFO org.apache.hadoop.yarn.server.resourcemanager.scheduler.common.fica.FiCaSchedulerNode: Assigned container container_1509560227945_0002_01_000004 of capacity <memory:1024, vCores:1> on host c220g1-030814.wisc.cloudlab.us:45451, which has 2 containers, <memory:3072, vCores:2> used and <memory:5120, vCores:6> available after allocation
2017-11-01 12:26:03,350 INFO org.apache.hadoop.yarn.server.resourcemanager.RMAuditLogger: USER=wentingt	OPERATION=AM Allocated Container	TARGET=SchedulerApp	RESULT=SUCCESS	APPID=application_1509560227945_0002	CONTAINERID=container_1509560227945_0002_01_000004	RESOURCE=<memory:1024, vCores:1>
2017-11-01 12:26:03,350 INFO org.apache.hadoop.yarn.server.resourcemanager.scheduler.capacity.ParentQueue: assignedContainer queue=root usedCapacity=0.1875 absoluteUsedCapacity=0.1875 used=<memory:3072, vCores:2> cluster=<memory:16384, vCores:16>
2017-11-01 12:26:03,350 INFO org.apache.hadoop.yarn.server.resourcemanager.scheduler.capacity.CapacityScheduler: Allocation proposal accepted
2017-11-01 12:26:03,766 INFO org.apache.hadoop.yarn.server.resourcemanager.rmcontainer.RMContainerImpl: container_1509560227945_0002_01_000004 Container Transitioned from ALLOCATED to ACQUIRED
2017-11-01 12:26:04,352 INFO org.apache.hadoop.yarn.server.resourcemanager.rmcontainer.RMContainerImpl: container_1509560227945_0002_01_000004 Container Transitioned from ACQUIRED to RUNNING
2017-11-01 12:26:04,770 INFO org.apache.hadoop.yarn.server.resourcemanager.scheduler.AppSchedulingInfo: checking for deactivate of application :application_1509560227945_0002
2017-11-01 12:27:07,817 INFO org.apache.hadoop.yarn.server.resourcemanager.scheduler.AbstractYarnScheduler: Release request cache is cleaned up
2017-11-01 12:28:51,335 INFO org.apache.hadoop.yarn.server.resourcemanager.rmcontainer.RMContainerImpl: container_1509560227945_0002_01_000004 Container Transitioned from RUNNING to COMPLETED
2017-11-01 12:28:51,336 INFO org.apache.hadoop.yarn.server.resourcemanager.RMAuditLogger: USER=wentingt	OPERATION=AM Released Container	TARGET=SchedulerApp	RESULT=SUCCESS	APPID=application_1509560227945_0002	CONTAINERID=container_1509560227945_0002_01_000004	RESOURCE=<memory:1024, vCores:1>
2017-11-01 12:28:52,336 INFO org.apache.hadoop.yarn.server.resourcemanager.scheduler.capacity.allocator.AbstractContainerAllocator: assignedContainer application attempt=appattempt_1509560227945_0002_000001 container=null queue=org.apache.hadoop.yarn.server.resourcemanager.scheduler.capacity.allocator.RegularContainerAllocator@2c302190 clusterResource=<memory:16384, vCores:16> type=OFF_SWITCH requestedPartition=
2017-11-01 12:28:52,336 INFO org.apache.hadoop.yarn.server.resourcemanager.scheduler.capacity.ParentQueue: assignedContainer queue=root usedCapacity=0.125 absoluteUsedCapacity=0.125 used=<memory:2048, vCores:1> cluster=<memory:16384, vCores:16>
2017-11-01 12:28:52,337 INFO org.apache.hadoop.yarn.server.resourcemanager.rmcontainer.RMContainerImpl: container_1509560227945_0002_01_000005 Container Transitioned from NEW to ALLOCATED
2017-11-01 12:28:52,337 INFO org.apache.hadoop.yarn.server.resourcemanager.scheduler.common.fica.FiCaSchedulerNode: Assigned container container_1509560227945_0002_01_000005 of capacity <memory:1024, vCores:1> on host c220g1-030814.wisc.cloudlab.us:45451, which has 2 containers, <memory:3072, vCores:2> used and <memory:5120, vCores:6> available after allocation
2017-11-01 12:28:52,337 INFO org.apache.hadoop.yarn.server.resourcemanager.RMAuditLogger: USER=wentingt	OPERATION=AM Allocated Container	TARGET=SchedulerApp	RESULT=SUCCESS	APPID=application_1509560227945_0002	CONTAINERID=container_1509560227945_0002_01_000005	RESOURCE=<memory:1024, vCores:1>
2017-11-01 12:28:52,337 INFO org.apache.hadoop.yarn.server.resourcemanager.scheduler.capacity.ParentQueue: assignedContainer queue=root usedCapacity=0.1875 absoluteUsedCapacity=0.1875 used=<memory:3072, vCores:2> cluster=<memory:16384, vCores:16>
2017-11-01 12:28:52,337 INFO org.apache.hadoop.yarn.server.resourcemanager.scheduler.capacity.CapacityScheduler: Allocation proposal accepted
2017-11-01 12:28:53,108 INFO org.apache.hadoop.yarn.server.resourcemanager.rmcontainer.RMContainerImpl: container_1509560227945_0002_01_000005 Container Transitioned from ALLOCATED to ACQUIRED
2017-11-01 12:28:53,338 INFO org.apache.hadoop.yarn.server.resourcemanager.rmcontainer.RMContainerImpl: container_1509560227945_0002_01_000005 Container Transitioned from ACQUIRED to RUNNING
2017-11-01 12:28:54,126 INFO org.apache.hadoop.yarn.server.resourcemanager.scheduler.AppSchedulingInfo: checking for deactivate of application :application_1509560227945_0002
2017-11-01 12:28:56,132 INFO org.apache.hadoop.yarn.server.resourcemanager.DefaultAMSProcessor: blacklist are updated in Scheduler.blacklistAdditions: [c220g1-030814.wisc.cloudlab.us], blacklistRemovals: []
2017-11-01 12:28:56,354 INFO org.apache.hadoop.yarn.server.resourcemanager.rmcontainer.RMContainerImpl: container_1509560227945_0002_01_000005 Container Transitioned from RUNNING to COMPLETED
2017-11-01 12:28:56,354 INFO org.apache.hadoop.yarn.server.resourcemanager.RMAuditLogger: USER=wentingt	OPERATION=AM Released Container	TARGET=SchedulerApp	RESULT=SUCCESS	APPID=application_1509560227945_0002	CONTAINERID=container_1509560227945_0002_01_000005	RESOURCE=<memory:1024, vCores:1>
2017-11-01 12:28:56,873 INFO org.apache.hadoop.yarn.server.resourcemanager.scheduler.capacity.allocator.AbstractContainerAllocator: assignedContainer application attempt=appattempt_1509560227945_0002_000001 container=null queue=org.apache.hadoop.yarn.server.resourcemanager.scheduler.capacity.allocator.RegularContainerAllocator@2c302190 clusterResource=<memory:16384, vCores:16> type=OFF_SWITCH requestedPartition=
2017-11-01 12:28:56,873 INFO org.apache.hadoop.yarn.server.resourcemanager.scheduler.capacity.ParentQueue: assignedContainer queue=root usedCapacity=0.125 absoluteUsedCapacity=0.125 used=<memory:2048, vCores:1> cluster=<memory:16384, vCores:16>
2017-11-01 12:28:56,874 INFO org.apache.hadoop.yarn.server.resourcemanager.rmcontainer.RMContainerImpl: container_1509560227945_0002_01_000006 Container Transitioned from NEW to ALLOCATED
2017-11-01 12:28:56,874 INFO org.apache.hadoop.yarn.server.resourcemanager.scheduler.common.fica.FiCaSchedulerNode: Assigned container container_1509560227945_0002_01_000006 of capacity <memory:1024, vCores:1> on host c220g1-030803.wisc.cloudlab.us:43522, which has 1 containers, <memory:1024, vCores:1> used and <memory:7168, vCores:7> available after allocation
2017-11-01 12:28:56,874 INFO org.apache.hadoop.yarn.server.resourcemanager.RMAuditLogger: USER=wentingt	OPERATION=AM Allocated Container	TARGET=SchedulerApp	RESULT=SUCCESS	APPID=application_1509560227945_0002	CONTAINERID=container_1509560227945_0002_01_000006	RESOURCE=<memory:1024, vCores:1>
2017-11-01 12:28:56,875 INFO org.apache.hadoop.yarn.server.resourcemanager.scheduler.capacity.ParentQueue: assignedContainer queue=root usedCapacity=0.1875 absoluteUsedCapacity=0.1875 used=<memory:3072, vCores:2> cluster=<memory:16384, vCores:16>
2017-11-01 12:28:56,875 INFO org.apache.hadoop.yarn.server.resourcemanager.scheduler.capacity.CapacityScheduler: Allocation proposal accepted
2017-11-01 12:28:57,136 INFO org.apache.hadoop.yarn.server.resourcemanager.security.NMTokenSecretManagerInRM: Sending NMToken for nodeId : c220g1-030803.wisc.cloudlab.us:43522 for container : container_1509560227945_0002_01_000006
2017-11-01 12:28:57,141 INFO org.apache.hadoop.yarn.server.resourcemanager.rmcontainer.RMContainerImpl: container_1509560227945_0002_01_000006 Container Transitioned from ALLOCATED to ACQUIRED
2017-11-01 12:28:57,141 INFO org.apache.hadoop.yarn.server.resourcemanager.DefaultAMSProcessor: blacklist are updated in Scheduler.blacklistAdditions: [], blacklistRemovals: [c220g1-030814.wisc.cloudlab.us]
2017-11-01 12:28:57,356 INFO org.apache.hadoop.yarn.server.resourcemanager.scheduler.capacity.allocator.AbstractContainerAllocator: assignedContainer application attempt=appattempt_1509560227945_0002_000001 container=null queue=org.apache.hadoop.yarn.server.resourcemanager.scheduler.capacity.allocator.RegularContainerAllocator@2c302190 clusterResource=<memory:16384, vCores:16> type=OFF_SWITCH requestedPartition=
2017-11-01 12:28:57,356 INFO org.apache.hadoop.yarn.server.resourcemanager.scheduler.capacity.ParentQueue: assignedContainer queue=root usedCapacity=0.1875 absoluteUsedCapacity=0.1875 used=<memory:3072, vCores:2> cluster=<memory:16384, vCores:16>
2017-11-01 12:28:57,356 INFO org.apache.hadoop.yarn.server.resourcemanager.rmcontainer.RMContainerImpl: container_1509560227945_0002_01_000007 Container Transitioned from NEW to ALLOCATED
2017-11-01 12:28:57,357 INFO org.apache.hadoop.yarn.server.resourcemanager.scheduler.common.fica.FiCaSchedulerNode: Assigned container container_1509560227945_0002_01_000007 of capacity <memory:1024, vCores:1> on host c220g1-030814.wisc.cloudlab.us:45451, which has 2 containers, <memory:3072, vCores:2> used and <memory:5120, vCores:6> available after allocation
2017-11-01 12:28:57,357 INFO org.apache.hadoop.yarn.server.resourcemanager.RMAuditLogger: USER=wentingt	OPERATION=AM Allocated Container	TARGET=SchedulerApp	RESULT=SUCCESS	APPID=application_1509560227945_0002	CONTAINERID=container_1509560227945_0002_01_000007	RESOURCE=<memory:1024, vCores:1>
2017-11-01 12:28:57,357 INFO org.apache.hadoop.yarn.server.resourcemanager.scheduler.capacity.ParentQueue: assignedContainer queue=root usedCapacity=0.25 absoluteUsedCapacity=0.25 used=<memory:4096, vCores:3> cluster=<memory:16384, vCores:16>
2017-11-01 12:28:57,357 INFO org.apache.hadoop.yarn.server.resourcemanager.scheduler.capacity.CapacityScheduler: Allocation proposal accepted
2017-11-01 12:28:57,875 INFO org.apache.hadoop.yarn.server.resourcemanager.rmcontainer.RMContainerImpl: container_1509560227945_0002_01_000006 Container Transitioned from ACQUIRED to RUNNING
2017-11-01 12:28:58,147 INFO org.apache.hadoop.yarn.server.resourcemanager.scheduler.AppSchedulingInfo: checking for deactivate of application :application_1509560227945_0002
2017-11-01 12:28:58,149 INFO org.apache.hadoop.yarn.server.resourcemanager.rmcontainer.RMContainerImpl: container_1509560227945_0002_01_000007 Container Transitioned from ALLOCATED to ACQUIRED
2017-11-01 12:28:58,358 INFO org.apache.hadoop.yarn.server.resourcemanager.rmcontainer.RMContainerImpl: container_1509560227945_0002_01_000007 Container Transitioned from ACQUIRED to RUNNING
2017-11-01 12:28:59,154 INFO org.apache.hadoop.yarn.server.resourcemanager.scheduler.AppSchedulingInfo: checking for deactivate of application :application_1509560227945_0002
2017-11-01 12:29:00,911 INFO org.apache.hadoop.yarn.server.resourcemanager.rmcontainer.RMContainerImpl: container_1509560227945_0002_01_000006 Container Transitioned from RUNNING to COMPLETED
2017-11-01 12:29:00,911 INFO org.apache.hadoop.yarn.server.resourcemanager.RMAuditLogger: USER=wentingt	OPERATION=AM Released Container	TARGET=SchedulerApp	RESULT=SUCCESS	APPID=application_1509560227945_0002	CONTAINERID=container_1509560227945_0002_01_000006	RESOURCE=<memory:1024, vCores:1>
2017-11-01 12:29:01,430 INFO org.apache.hadoop.yarn.server.resourcemanager.rmcontainer.RMContainerImpl: container_1509560227945_0002_01_000007 Container Transitioned from RUNNING to COMPLETED
2017-11-01 12:29:01,430 INFO org.apache.hadoop.yarn.server.resourcemanager.RMAuditLogger: USER=wentingt	OPERATION=AM Released Container	TARGET=SchedulerApp	RESULT=SUCCESS	APPID=application_1509560227945_0002	CONTAINERID=container_1509560227945_0002_01_000007	RESOURCE=<memory:1024, vCores:1>
2017-11-01 12:29:02,432 INFO org.apache.hadoop.yarn.server.resourcemanager.scheduler.capacity.allocator.AbstractContainerAllocator: assignedContainer application attempt=appattempt_1509560227945_0002_000001 container=null queue=org.apache.hadoop.yarn.server.resourcemanager.scheduler.capacity.allocator.RegularContainerAllocator@2c302190 clusterResource=<memory:16384, vCores:16> type=OFF_SWITCH requestedPartition=
2017-11-01 12:29:02,432 INFO org.apache.hadoop.yarn.server.resourcemanager.scheduler.capacity.ParentQueue: assignedContainer queue=root usedCapacity=0.125 absoluteUsedCapacity=0.125 used=<memory:2048, vCores:1> cluster=<memory:16384, vCores:16>
2017-11-01 12:29:02,432 INFO org.apache.hadoop.yarn.server.resourcemanager.rmcontainer.RMContainerImpl: container_1509560227945_0002_01_000008 Container Transitioned from NEW to ALLOCATED
2017-11-01 12:29:02,432 INFO org.apache.hadoop.yarn.server.resourcemanager.scheduler.common.fica.FiCaSchedulerNode: Assigned container container_1509560227945_0002_01_000008 of capacity <memory:1024, vCores:1> on host c220g1-030814.wisc.cloudlab.us:45451, which has 2 containers, <memory:3072, vCores:2> used and <memory:5120, vCores:6> available after allocation
2017-11-01 12:29:02,432 INFO org.apache.hadoop.yarn.server.resourcemanager.RMAuditLogger: USER=wentingt	OPERATION=AM Allocated Container	TARGET=SchedulerApp	RESULT=SUCCESS	APPID=application_1509560227945_0002	CONTAINERID=container_1509560227945_0002_01_000008	RESOURCE=<memory:1024, vCores:1>
2017-11-01 12:29:02,433 INFO org.apache.hadoop.yarn.server.resourcemanager.scheduler.capacity.ParentQueue: assignedContainer queue=root usedCapacity=0.1875 absoluteUsedCapacity=0.1875 used=<memory:3072, vCores:2> cluster=<memory:16384, vCores:16>
2017-11-01 12:29:02,433 INFO org.apache.hadoop.yarn.server.resourcemanager.scheduler.capacity.CapacityScheduler: Allocation proposal accepted
2017-11-01 12:29:03,171 INFO org.apache.hadoop.yarn.server.resourcemanager.rmcontainer.RMContainerImpl: container_1509560227945_0002_01_000008 Container Transitioned from ALLOCATED to ACQUIRED
2017-11-01 12:29:03,432 INFO org.apache.hadoop.yarn.server.resourcemanager.rmcontainer.RMContainerImpl: container_1509560227945_0002_01_000008 Container Transitioned from ACQUIRED to RUNNING
2017-11-01 12:29:03,433 INFO org.apache.hadoop.yarn.server.resourcemanager.scheduler.capacity.allocator.AbstractContainerAllocator: assignedContainer application attempt=appattempt_1509560227945_0002_000001 container=null queue=org.apache.hadoop.yarn.server.resourcemanager.scheduler.capacity.allocator.RegularContainerAllocator@2c302190 clusterResource=<memory:16384, vCores:16> type=OFF_SWITCH requestedPartition=
2017-11-01 12:29:03,433 INFO org.apache.hadoop.yarn.server.resourcemanager.scheduler.capacity.ParentQueue: assignedContainer queue=root usedCapacity=0.1875 absoluteUsedCapacity=0.1875 used=<memory:3072, vCores:2> cluster=<memory:16384, vCores:16>
2017-11-01 12:29:03,434 INFO org.apache.hadoop.yarn.server.resourcemanager.rmcontainer.RMContainerImpl: container_1509560227945_0002_01_000009 Container Transitioned from NEW to ALLOCATED
2017-11-01 12:29:03,434 INFO org.apache.hadoop.yarn.server.resourcemanager.scheduler.common.fica.FiCaSchedulerNode: Assigned container container_1509560227945_0002_01_000009 of capacity <memory:1024, vCores:1> on host c220g1-030814.wisc.cloudlab.us:45451, which has 3 containers, <memory:4096, vCores:3> used and <memory:4096, vCores:5> available after allocation
2017-11-01 12:29:03,434 INFO org.apache.hadoop.yarn.server.resourcemanager.RMAuditLogger: USER=wentingt	OPERATION=AM Allocated Container	TARGET=SchedulerApp	RESULT=SUCCESS	APPID=application_1509560227945_0002	CONTAINERID=container_1509560227945_0002_01_000009	RESOURCE=<memory:1024, vCores:1>
2017-11-01 12:29:03,434 INFO org.apache.hadoop.yarn.server.resourcemanager.scheduler.capacity.ParentQueue: assignedContainer queue=root usedCapacity=0.25 absoluteUsedCapacity=0.25 used=<memory:4096, vCores:3> cluster=<memory:16384, vCores:16>
2017-11-01 12:29:03,434 INFO org.apache.hadoop.yarn.server.resourcemanager.scheduler.capacity.CapacityScheduler: Allocation proposal accepted
2017-11-01 12:29:04,174 INFO org.apache.hadoop.yarn.server.resourcemanager.scheduler.AppSchedulingInfo: checking for deactivate of application :application_1509560227945_0002
2017-11-01 12:29:04,176 INFO org.apache.hadoop.yarn.server.resourcemanager.rmcontainer.RMContainerImpl: container_1509560227945_0002_01_000009 Container Transitioned from ALLOCATED to ACQUIRED
2017-11-01 12:29:04,435 INFO org.apache.hadoop.yarn.server.resourcemanager.rmcontainer.RMContainerImpl: container_1509560227945_0002_01_000009 Container Transitioned from ACQUIRED to RUNNING
2017-11-01 12:29:05,187 INFO org.apache.hadoop.yarn.server.resourcemanager.scheduler.AppSchedulingInfo: checking for deactivate of application :application_1509560227945_0002
2017-11-01 12:29:06,388 INFO org.apache.hadoop.yarn.server.resourcemanager.rmcontainer.RMContainerImpl: container_1509560227945_0002_01_000008 Container Transitioned from RUNNING to COMPLETED
2017-11-01 12:29:06,388 INFO org.apache.hadoop.yarn.server.resourcemanager.RMAuditLogger: USER=wentingt	OPERATION=AM Released Container	TARGET=SchedulerApp	RESULT=SUCCESS	APPID=application_1509560227945_0002	CONTAINERID=container_1509560227945_0002_01_000008	RESOURCE=<memory:1024, vCores:1>
2017-11-01 12:29:06,931 INFO org.apache.hadoop.yarn.server.resourcemanager.rmcontainer.RMContainerImpl: container_1509560227945_0002_01_000009 Container Transitioned from RUNNING to COMPLETED
2017-11-01 12:29:06,932 INFO org.apache.hadoop.yarn.server.resourcemanager.RMAuditLogger: USER=wentingt	OPERATION=AM Released Container	TARGET=SchedulerApp	RESULT=SUCCESS	APPID=application_1509560227945_0002	CONTAINERID=container_1509560227945_0002_01_000009	RESOURCE=<memory:1024, vCores:1>
2017-11-01 12:29:06,950 INFO org.apache.hadoop.yarn.server.resourcemanager.rmapp.attempt.RMAppAttemptImpl: Updating application attempt appattempt_1509560227945_0002_000001 with final state: FINISHING, and exit status: -1000
2017-11-01 12:29:06,951 INFO org.apache.hadoop.yarn.server.resourcemanager.rmapp.attempt.RMAppAttemptImpl: appattempt_1509560227945_0002_000001 State change from RUNNING to FINAL_SAVING on event = UNREGISTERED
2017-11-01 12:29:06,951 INFO org.apache.hadoop.yarn.server.resourcemanager.rmapp.RMAppImpl: Updating application application_1509560227945_0002 with final state: FINISHING
2017-11-01 12:29:06,951 INFO org.apache.hadoop.yarn.server.resourcemanager.rmapp.RMAppImpl: application_1509560227945_0002 State change from RUNNING to FINAL_SAVING on event = ATTEMPT_UNREGISTERED
2017-11-01 12:29:06,951 INFO org.apache.hadoop.yarn.server.resourcemanager.recovery.RMStateStore: Updating info for app: application_1509560227945_0002
2017-11-01 12:29:06,952 INFO org.apache.hadoop.yarn.server.resourcemanager.rmapp.attempt.RMAppAttemptImpl: appattempt_1509560227945_0002_000001 State change from FINAL_SAVING to FINISHING on event = ATTEMPT_UPDATE_SAVED
2017-11-01 12:29:06,952 INFO org.apache.hadoop.yarn.server.resourcemanager.rmapp.RMAppImpl: application_1509560227945_0002 State change from FINAL_SAVING to FINISHING on event = APP_UPDATE_SAVED
2017-11-01 12:29:07,952 INFO org.apache.hadoop.yarn.server.resourcemanager.ApplicationMasterService: application_1509560227945_0002 unregistered successfully. 
2017-11-01 12:29:13,366 INFO org.apache.hadoop.yarn.server.resourcemanager.rmcontainer.RMContainerImpl: container_1509560227945_0002_01_000001 Container Transitioned from RUNNING to COMPLETED
2017-11-01 12:29:13,366 INFO org.apache.hadoop.yarn.server.resourcemanager.ApplicationMasterService: Unregistering app attempt : appattempt_1509560227945_0002_000001
2017-11-01 12:29:13,366 INFO org.apache.hadoop.yarn.server.resourcemanager.RMAuditLogger: USER=wentingt	OPERATION=AM Released Container	TARGET=SchedulerApp	RESULT=SUCCESS	APPID=application_1509560227945_0002	CONTAINERID=container_1509560227945_0002_01_000001	RESOURCE=<memory:2048, vCores:1>
2017-11-01 12:29:13,366 INFO org.apache.hadoop.yarn.server.resourcemanager.security.AMRMTokenSecretManager: Application finished, removing password for appattempt_1509560227945_0002_000001
2017-11-01 12:29:13,366 INFO org.apache.hadoop.yarn.server.resourcemanager.rmapp.attempt.RMAppAttemptImpl: appattempt_1509560227945_0002_000001 State change from FINISHING to FINISHED on event = CONTAINER_FINISHED
2017-11-01 12:29:13,366 INFO org.apache.hadoop.yarn.server.resourcemanager.rmapp.RMAppImpl: application_1509560227945_0002 State change from FINISHING to FINISHED on event = ATTEMPT_FINISHED
2017-11-01 12:29:13,366 INFO org.apache.hadoop.yarn.server.resourcemanager.scheduler.capacity.CapacityScheduler: Application Attempt appattempt_1509560227945_0002_000001 is done. finalState=FINISHED
2017-11-01 12:29:13,366 INFO org.apache.hadoop.yarn.server.resourcemanager.RMAuditLogger: USER=wentingt	OPERATION=Application Finished - Succeeded	TARGET=RMAppManager	RESULT=SUCCESS	APPID=application_1509560227945_0002
2017-11-01 12:29:13,366 INFO org.apache.hadoop.yarn.server.resourcemanager.scheduler.AppSchedulingInfo: Application application_1509560227945_0002 requests cleared
2017-11-01 12:29:13,367 INFO org.apache.hadoop.yarn.server.resourcemanager.scheduler.capacity.LeafQueue: Application removed - appId: application_1509560227945_0002 user: wentingt queue: default #user-pending-applications: 0 #user-active-applications: 0 #queue-pending-applications: 0 #queue-active-applications: 0
2017-11-01 12:29:13,367 INFO org.apache.hadoop.yarn.server.resourcemanager.scheduler.capacity.ParentQueue: Application removed - appId: application_1509560227945_0002 user: wentingt leaf-queue of parent: root #applications: 0
2017-11-01 12:29:13,367 INFO org.apache.hadoop.yarn.server.resourcemanager.RMAppManager$ApplicationSummary: appId=application_1509560227945_0002,name=QuasiMonteCarlo,user=wentingt,queue=default,state=FINISHED,trackingUrl=http://c220g1-030817.wisc.cloudlab.us:8088/proxy/application_1509560227945_0002/,appMasterHost=c220g1-030814.wisc.cloudlab.us,submitTime=1509560749990,startTime=1509560749991,finishTime=1509560946951,finalStatus=FAILED,memorySeconds=616730,vcoreSeconds=396,preemptedMemorySeconds=0,preemptedVcoreSeconds=0,preemptedAMContainers=0,preemptedNonAMContainers=0,preemptedResources=<memory:0\, vCores:0>,applicationType=MAPREDUCE
2017-11-01 12:29:13,367 INFO org.apache.hadoop.yarn.server.resourcemanager.amlauncher.AMLauncher: Cleaning master appattempt_1509560227945_0002_000001
